Workbook

Sheet README
A1: AUTOMETRIC — KOL DISCOVERY BRAND MATCH ENGINE
A2: Specification and calculation workbook. Twelve sheets: two of inputs, one engine, seven views, one lookup sheet and this page. Generated by scripts/build-brand-match-workbook.mjs and verified by scripts/verify-brand-match-workbook.mjs.
A4: 1. PURPOSE
B5: This workbook is the source of truth for the Autometric KOL Discovery Brand Match calculation. It is not a mock-up: every score on every sheet is an Excel formula over the values in Brand_Profile and KOL_Database, weighted by the constants on Lookup_Lists. Change an input and the workbook re-answers. Hand it to a backend developer and the formulas are the specification — there is no second document that says what the code should do.
B6: It exists because the product needs a Brand Match today and the KOL database cannot supply one: feature.brand_fit_analysis holds 0 rows, which is why four of the eight Smart Preset chips in the running prototype are disabled. The logic has to be agreed and written down before the pipeline is built, not after.
A7: 2. BRAND_PROFILE — the brand half of the inputs
B8: Four sections, matching the Brand Profile & Matching UI: A. Company Profile, B. Target Audience, C. Brand Identification, D. Ideal Creator Profile. A fifth block, E. Matching Configuration, holds the switches that decide which rules act as hard filters.
B9: Columns D, E and F are the three brands. Column G is whichever brand cell B4 names, and that is the column the active-brand views (Match_Explanation, Discovery_Ranking) read. Two calculated blocks sit under the fields: a token helper that splits the comma-separated list fields into five addressable slots, and the audience sub-weights, which move weight onto whichever dimension Audience Demographics Priority names.
A10: 3. KOL_DATABASE — the creator half of the inputs
B11: Thirty creators on Instagram and TikTok, in six blocks: identity, performance, audience, content, commercial, safety — plus the exclusion state and the freshness columns Discovery needs. Tier, CPV, CPE, CPM, Estimated Reach, Estimated ROI, View-to-Follower Ratio, Cost Efficiency, Data Completeness and Data Status are calculated from the columns beside them.
B12: Several creators are missing a field on purpose — a blank Median Views, a blank rate card, a blank audience city. The real roster is full of holes, the Confidence column exists to report them, and every formula here is written to survive one without printing #DIV/0!.
A13: 4. THE SIX COMPONENTS
A14: Brand & Business Relevance | B14: Brand Industry, Product / Service Category, Main Business Keywords, Brand Keywords and Brand Niche against the creator Category, Sub Category, Content Topics and Audience Interests. Industry Match 40%, Category Match 30%, Keyword Match 30% — the last being the two keyword lists scored separately and averaged.
A15: Target Audience Relevance | B15: Age 25%, Gender 15%, Location 30%, Interest 30% — before Audience Demographics Priority moves 12 points onto one of them and takes a third of that off each of the others.
A16: Content & Category Relevance | B16: Preferred Category 30%, Preferred Sub Category 20%, Preferred Content Topics 30%, Preferred Content Style 20%.
A17: Brand Personality Fit | B17: Personality 35%, Tone against Content Style 25%, Values overlap 25%, Communication Style 15%. Related matches count: Innovative is answered by a Tech-savvy or Creative creator, not only by one who calls themselves Innovative.
A18: Performance Quality | B18: Engagement Rate 35%, Audience Quality 20%, Consistency 20%, Community 10%, Average Views 10%, Recent Growth 5%, each normalised to 0–100 against a calibration target on Lookup_Lists.
A19: Brand Safety | B19: Brand Safety Score 80%, head-room from Competitor Saturation 20%, multiplied by the Risk Flag discount (High 0.6, Medium 0.85, Low 0.95). Saturation lowers the score; it never excludes on its own.
A20: 5. WEIGHTING — the master formula
A21: FINAL MATCH = 20% Brand & Business + 30% Target Audience + 20% Content & Category + 10% Brand Personality + 10% Performance + 10% Brand Safety
B23: The six weights live in the COMPONENT WEIGHTS block on Lookup_Lists and nowhere else. The engine divides by their sum rather than by a literal 100, so a workbook whose weights have been edited still produces a 0–100 score; the CHECK_WEIGHT_TOTAL cell beside them says out loud whether they still total 100.
A24: 6. FORMULA LOGIC — how a comparison becomes a number
A25: Category-style comparisons | B25: A matrix lookup on Lookup_Lists, on the 100 / 80 / 60 / 40 / 20 ladder: exact, strongly related, partially related, weakly related, unrelated. Five matrices — Industry × Category, Category × Category, Brand Personality × Creator Personality, Brand Tone × Content Style, Communication Style × Content Style, Content Style × Content Style. Every cell is editable, which is what makes a disputed score a conversation about one number rather than about a model.
A26: List comparisons | B26: Overlap counting. The brand list is split into five slots by the token helper; each slot is looked for in the creator text with SEARCH; the score is matches ÷ slots filled × 100. A brand that names three keywords is judged out of three.
A27: Numeric comparisons | B27: Normalisation against a target on Lookup_Lists: MIN(100, value ÷ target × 100). Engagement Rate scores 100 at 6%; views per follower at 0.5; 30-day growth at 8%, and 0 at −2%.
A28: Missing data | B28: A blank input scores the neutral 50 where the brand left a preference blank, and 0 where the creator is missing a measurement — those are different situations and the formulas keep them apart. Nothing ever divides by an unguarded cell.
A29: Two inputs that carry no weight | B29: Company Description is free text for the brief. Brand Positioning is carried and printed in the Personality Match Reason, but it is deliberately not weighted: the honest thing to weigh a Premium or Luxury positioning against is production quality, and there is no measured production-quality signal on the roster to weigh it against. Inventing one would be the same mistake as the four Smart Preset chips that used to rank by a hash of the creator id. Give it a weight the day a real signal exists.
A30: 7. HARD FILTERS — remove the creator
B31: Platform, Minimum and Maximum Followers, Minimum Engagement Rate, Tier, Minimum Audience Quality, Minimum Brand Safety, Audience Country and Category (both switchable), Max Competitor Saturation, the four exclusion toggles, and Minimum Brand Match. The engine computes the reason first and the verdict from it, so an excluded creator always carries the sentence that explains why. See Filter_Logic.
A32: 8. SOFT MATCHING — reorder the list
B33: Brand Match, Audience Match, Content Relevance, Personality Fit, Performance, Opportunity, Estimated ROI and Competitor Saturation. A low soft score never removes a creator. Competitor Saturation in particular is a warning, not a rejection: it can only exclude through the explicit Max Competitor Saturation setting.
A34: 9. DISCOVERY RANKING
B35: Default order is Brand Match, then Audience Match, then Content Relevance, then Performance, then Brand Safety, encoded as one Default Sort Key so the tie-break order is inspectable. Thirty presets are defined on Lookup_Lists; the picker on Discovery_Ranking reads the metric column each one names. The "Available today" column tells you which of them the KOL database can actually answer — the prototype ships four of its eight chips disabled for exactly this reason.
A36: 10. MATCH EXPLANATION
B37: Generated, not written. The three strengths are the three highest components and the three considerations the three lowest, read with LARGE and SMALL over the same cells the score came from, so an explanation cannot drift away from the number it explains. Each component also carries its own reason line naming its sub-scores.
A38: 11. SAMPLE BRANDS AND SAMPLE OUTPUT
B39: Three briefs — Technology / SaaS, Beauty & Skincare, Food & Beverage — run against one roster of thirty. Sample_Output puts the three scores for each creator side by side and reports the spread. If the engine were ranking creators globally rather than matching brand to creator, that spread would be zero on every row; the verdict cell says whether it is.
A40: 12. TAXONOMY — the tree everything classifies against
B41: One sheet, because the whole point is that the four things are one object: a creator sub category, a brand niche, a raw kol_categories row and a matching keyword are four views of a single tree. Lookup_Lists derives its Category, Sub Category, Industry and Niche dropdowns from it, so no list in this workbook can drift from another.
A42: Three axes | B42: A label answers one question — what the creator makes, who watches, or how it is shot. public.kol_categories mixes all three: "Moms" is an audience and "Gen Z" is an age band, both sitting in a content column. Only the content axis may feed the Category and Sub Category ladders; the audience axis already has its own 30% of the score.
...

Sheet Brand_Profile
A1: BRAND PROFILE · Company Profile · Target Audience · Brand Identification · Ideal Creator Profile
A2: The inputs. Columns D–F are the three brands, each cell typed by hand or picked from a dropdown; column G is whichever brand cell B4 names, and that is the column the engine reads for every active-brand view. Nothing on this sheet is calculated from a creator — it is what the brand says about itself before it has seen the roster.
A4: Active Brand → | B4: BRAND-A | G4: active column → | H4: =MATCH($B$4,$D$6:$F$6,0)
A6: Section | B6: Field | C6: Field Key | D6: BRAND-A | E6: BRAND-B | F6: BRAND-C | G6: Active Value | H6: Input type / allowed values
A7: A. COMPANY PROFILE
A8: COMPANY PROFILE | B8: Brand ID | C8: brand_id | D8: BRAND-A | E8: BRAND-B | F8: BRAND-C | G8: =INDEX($D8:$F8,1,$H$4) | H8: Free text
A9: COMPANY PROFILE | B9: Brand Name | C9: brand_name | D9: Nusatech Cloud | E9: Lumaya Skin | F9: Rasa Nusantara | G9: =INDEX($D9:$F9,1,$H$4) | H9: Free text
A10: COMPANY PROFILE | B10: Industry | C10: industry | D10: Technology / SaaS | E10: Beauty & Skincare | F10: Food & Beverage | G10: =INDEX($D10:$F10,1,$H$4) | H10: Dropdown — Lookup_Lists.Industry
A11: COMPANY PROFILE | B11: Company Description | C11: company_description | D11: Workflow automation and team collaboration for Indonesian SMEs. | E11: Dermatologist-tested skincare for humid-climate skin barriers. | F11: Ready-to-drink archipelago flavours for everyday family tables. | G11: =INDEX($D11:$F11,1,$H$4) | H11: Free text
A12: COMPANY PROFILE | B12: Product / Service Category | C12: product_category | D12: Software & SaaS | E12: Skincare | F12: Coffee & Beverage | G12: =INDEX($D12:$F12,1,$H$4) | H12: Dropdown — Lookup_Lists.SubCategory
A13: COMPANY PROFILE | B13: Main Business Keywords | C13: business_keywords | D13: Technology, Productivity, Business, Education, Finance | E13: Skincare, Beauty, Makeup, Health, Shopping | F13: Food, Cooking, Coffee, Shopping, Entertainment | G13: =INDEX($D13:$F13,1,$H$4) | H13: Up to 5 items, comma-separated
A14: COMPANY PROFILE | B14: Brand Niche | C14: brand_niche | D14: B2B SaaS | E14: Derma Skincare | F14: Ready-to-Drink | G14: =INDEX($D14:$F14,1,$H$4) | H14: Dropdown — Lookup_Lists.Niche
A15: B. TARGET AUDIENCE
A16: TARGET AUDIENCE | B16: Primary Age Range | C16: primary_age_range | D16: 25-34 | E16: 18-24 | F16: 25-34 | G16: =INDEX($D16:$F16,1,$H$4) | H16: Dropdown — Lookup_Lists.AgeBand
A17: TARGET AUDIENCE | B17: Secondary Age Range | C17: secondary_age_range | D17: 18-24 | E17: 25-34 | F17: 35-44 | G17: =INDEX($D17:$F17,1,$H$4) | H17: Dropdown — Lookup_Lists.AgeBand
A18: TARGET AUDIENCE | B18: Gender Majority | C18: gender_majority | D18: Any | E18: Female | F18: Balanced | G18: =INDEX($D18:$F18,1,$H$4) | H18: Dropdown — Lookup_Lists.GenderMajority
A19: TARGET AUDIENCE | B19: Target Country | C19: target_country | D19: Indonesia | E19: Indonesia | F19: Indonesia | G19: =INDEX($D19:$F19,1,$H$4) | H19: Dropdown — Lookup_Lists.Country
A20: TARGET AUDIENCE | B20: Target Region / Province | C20: target_region | D20: DKI Jakarta | E20: Nasional | F20: Nasional | G20: =INDEX($D20:$F20,1,$H$4) | H20: Dropdown — Lookup_Lists.Region
A21: TARGET AUDIENCE | B21: Target City | C21: target_city | D21: Jakarta | E21: Jakarta | F21: Nasional | G21: =INDEX($D21:$F21,1,$H$4) | H21: Dropdown — Lookup_Lists.City
A22: TARGET AUDIENCE | B22: Audience Interests | C22: audience_interests | D22: Technology, Business, Productivity, Education, Finance | E22: Skincare, Beauty, Makeup, Fashion, Shopping | F22: Food, Cooking, Coffee, Travel, Entertainment | G22: =INDEX($D22:$F22,1,$H$4) | H22: Up to 5 items, comma-separated
A23: TARGET AUDIENCE | B23: Audience Demographics Priority | C23: audience_priority | D23: Interest | E23: Gender | F23: Age | G23: =INDEX($D23:$F23,1,$H$4) | H23: Dropdown — Lookup_Lists.AudiencePriority
A24: C. BRAND IDENTIFICATION
A25: BRAND IDENTIFICATION | B25: Brand Personality | C25: brand_personality | D25: Innovative | E25: Premium | F25: Friendly | G25: =INDEX($D25:$F25,1,$H$4) | H25: Dropdown — Lookup_Lists.BrandPersonality
A26: BRAND IDENTIFICATION | B26: Brand Values | C26: brand_values | D26: Innovation, Trust, Transparency, Quality, Empowerment | E26: Quality, Authenticity, Trust, Craftsmanship, Health | F26: Fun, Community, Affordability, Authenticity, Family | G26: =INDEX($D26:$F26,1,$H$4) | H26: Up to 5 items, comma-separated
A27: BRAND IDENTIFICATION | B27: Brand Tone | C27: brand_tone | D27: Informative | E27: Aspirational | F27: Warm | G27: =INDEX($D27:$F27,1,$H$4) | H27: Dropdown — Lookup_Lists.BrandTone
A28: BRAND IDENTIFICATION | B28: Brand Positioning | C28: brand_positioning | D28: Mid-market | E28: Premium | F28: Mass | G28: =INDEX($D28:$F28,1,$H$4) | H28: Dropdown — Lookup_Lists.Positioning
A29: BRAND IDENTIFICATION | B29: Brand Keywords | C29: brand_keywords | D29: Technology, Productivity, Business, Education, Finance | E29: Skincare, Beauty, Health, Makeup, Shopping | F29: Food, Cooking, Coffee, Entertainment, Shopping | G29: =INDEX($D29:$F29,1,$H$4) | H29: Up to 5 items, comma-separated
A30: BRAND IDENTIFICATION | B30: Communication Style | C30: communication_style | D30: Educational | E30: Visual-first | F30: Storytelling | G30: =INDEX($D30:$F30,1,$H$4) | H30: Dropdown — Lookup_Lists.CommStyle
A31: D. IDEAL CREATOR PROFILE
A32: IDEAL CREATOR PROFILE | B32: Preferred Platform | C32: preferred_platform | D32: Instagram, TikTok | E32: Instagram, TikTok | F32: Instagram, TikTok | G32: =INDEX($D32:$F32,1,$H$4) | H32: One or more of the Platform list, comma-separated
A33: IDEAL CREATOR PROFILE | B33: Preferred Category | C33: preferred_category | D33: Tech | E33: Beauty | F33: Food | G33: =INDEX($D33:$F33,1,$H$4) | H33: Dropdown — Lookup_Lists.Category
A34: IDEAL CREATOR PROFILE | B34: Preferred Sub Category | C34: preferred_subcategory | D34: Software & SaaS | E34: Skincare | F34: Culinary Review | G34: =INDEX($D34:$F34,1,$H$4) | H34: Dropdown — Lookup_Lists.SubCategory
A35: IDEAL CREATOR PROFILE | B35: Preferred Tier | C35: preferred_tier | D35: Micro, Mid-tier, Macro | E35: Micro, Mid-tier | F35: Nano, Micro, Mid-tier | G35: =INDEX($D35:$F35,1,$H$4) | H35: One or more of the Tier list, comma-separated
A36: IDEAL CREATOR PROFILE | B36: Preferred Follower Range — Min | C36: preferred_followers_min | D36: 10000 | E36: 10000 | F36: 5000 | G36: =INDEX($D36:$F36,1,$H$4) | H36: Whole number
A37: IDEAL CREATOR PROFILE | B37: Preferred Follower Range — Max | C37: preferred_followers_max | D37: 1000000 | E37: 500000 | F37: 400000 | G37: =INDEX($D37:$F37,1,$H$4) | H37: Whole number
A38: IDEAL CREATOR PROFILE | B38: Minimum Engagement Rate (%) | C38: min_engagement_rate | D38: 2.5 | E38: 3 | F38: 3.5 | G38: =INDEX($D38:$F38,1,$H$4) | H38: Percent, e.g. 3.5 means 3,5%
A39: IDEAL CREATOR PROFILE | B39: Preferred Content Style | C39: preferred_content_style | D39: Educational | E39: Review | F39: Storytelling | G39: =INDEX($D39:$F39,1,$H$4) | H39: Dropdown — Lookup_Lists.ContentStyle
A40: IDEAL CREATOR PROFILE | B40: Preferred Content Topics | C40: preferred_content_topics | D40: Technology, Business, Education, Productivity, Finance | E40: Skincare, Beauty, Makeup, Health, Shopping | F40: Food, Cooking, Coffee, Entertainment, Travel | G40: =INDEX($D40:$F40,1,$H$4) | H40: Up to 5 items, comma-separated
A41: IDEAL CREATOR PROFILE | B41: Preferred Creator Personality | C41: preferred_creator_personality | D41: Educational | E41: Reviewer | F41: Relatable | G41: =INDEX($D41:$F41,1,$H$4) | H41: Dropdown — Lookup_Lists.CreatorPersonality
A42: IDEAL CREATOR PROFILE | B42: Preferred Creator Values | C42: preferred_creator_values | D42: Innovation, Trust, Quality, Transparency, Empowerment | E42: Authenticity, Quality, Trust, Health, Craftsmanship | F42: Fun, Community, Authenticity, Family, Affordability | G42: =INDEX($D42:$F42,1,$H$4) | H42: Up to 5 items, comma-separated
...

Sheet KOL_Database
A1: KOL DATABASE · 30 creators, Instagram and TikTok
A2: The other half of the inputs. Identity, performance, audience, content, commercial and safety — the same six blocks the creator workspace shows. Tier, CPV, CPE, CPM, Estimated Reach, Estimated ROI, View-to-Follower Ratio, Cost Efficiency, Data Completeness and Data Status are calculated from the columns beside them, so they cannot disagree with their own inputs. Several creators are deliberately missing a field: the real roster is full of holes and every formula here has to survive one.
A3: IDENTITY | J3: PERFORMANCE | W3: AUDIENCE | AI3: CONTENT | AN3: COMMERCIAL | AT3: SAFETY | AW3: EXCLUSION STATE | BA3: FRESHNESS | BC3: DERIVED
A4: KOL ID | B4: Creator Name | C4: Handle | D4: Platform | E4: Category | F4: Sub Category | G4: Tier | H4: Verified | I4: Creator City | J4: Followers | K4: Engagement Rate (%) | L4: Average Views | M4: Median Views | N4: 30D Growth (%) | O4: 90D Growth (%) | P4: Consistency Score | Q4: Community Score | R4: Audience Quality | S4: Audience Authenticity | T4: Share Rate (%) | U4: Save Rate (%) | V4: Recent Performance | W4: Audience Age 13–17 % | X4: Audience Age 18–24 % | Y4: Audience Age 25–34 % | Z4: Audience Age 35–44 % | AA4: Audience Age 45+ % | AB4: Female % | AC4: Male % | AD4: Audience Country | AE4: Audience Region | AF4: Audience City | AG4: Audience Interests | AH4: Purchase Intent | AI4: Content Topics | AJ4: Content Style | AK4: Creator Personality | AL4: Creator Values | AM4: Content Quality | AN4: Rate Card (IDR) | AO4: CPV | AP4: CPE | AQ4: CPM | AR4: Estimated Reach | AS4: Estimated ROI | AT4: Brand Safety Score | AU4: Competitor Saturation | AV4: Risk Flag | AW4: Already Selected | AX4: In Cart | AY4: Existing Partner | AZ4: Excluded Creator | BA4: Added Date | BB4: Last Updated | BC4: View-to-Follower Ratio | BD4: Cost Efficiency | BE4: Data Completeness % | BF4: Data Status
A5: KOL-01 | B5: Ardi Nugraha | C5: @ardidigital | D5: Instagram | E5: Tech | F5: Gadget Review | G5: =IFERROR(INDEX(Lookup_Lists!$A$96:$A$100,MATCH(KOL_Database!$J$5,Lookup_Lists!$B$96:$B$100,1)),"") | H5: Yes | I5: Jakarta | J5: 128000 | K5: 3.8 | L5: 46223 | M5: 37645 | N5: 2.7 | O5: 6.7 | P5: 73 | Q5: 66 | R5: 83 | S5: 75 | T5: 1.65 | U5: 3.46 | V5: 84 | W5: 5 | X5: 23 | Y5: 42 | Z5: 20 | AA5: 10 | AB5: 20 | AC5: 80 | AD5: Indonesia | AE5: DKI Jakarta | AF5: Jakarta | AG5: Technology, Productivity, Business, Gaming, Shopping | AH5: High | AI5: Technology, Productivity, Business | AJ5: Review | AK5: Reviewer | AL5: Quality, Trust, Innovation, Transparency | AM5: 86 | AN5: 3677000 | AO5: =IF(OR(KOL_Database!$AN$5="",KOL_Database!$AN$5=0,KOL_Database!$L$5="",KOL_Database!$L$5=0),"",ROUND(KOL_Database!$AN$5/KOL_Database!$L$5,2)) | AP5: =IF(OR(KOL_Database!$AN$5="",KOL_Database!$AN$5=0,KOL_Database!$L$5="",KOL_Database!$L$5=0,KOL_Database!$K$5="",KOL_Database!$K$5=0),"",ROUND(KOL_Database!$AN$5/(KOL_Database!$L$5*KOL_Database!$K$5/100),0)) | AQ5: =IF(OR(KOL_Database!$AN$5="",KOL_Database!$AN$5=0,KOL_Database!$J$5="",KOL_Database!$J$5=0),"",ROUND(KOL_Database!$AN$5/KOL_Database!$J$5*1000,0)) | AR5: =IF(OR(KOL_Database!$L$5="",KOL_Database!$J$5=""),"",ROUND(KOL_Database!$L$5*Lookup_Lists!$D$147+KOL_Database!$J$5*Lookup_Lists!$D$148,0)) | AS5: =IF(OR(KOL_Database!$AN$5="",KOL_Database!$AN$5=0,KOL_Database!$AR$5=""),"",ROUND(KOL_Database!$AR$5*KOL_Database!$K$5/100*Lookup_Lists!$D$146/KOL_Database!$AN$5,2)) | AT5: 90 | AU5: 56 | AV5: None | AW5: No | AX5: No | AY5: No | AZ5: No | BA5: 46171.708 | BB5: 46234.708 | BC5: =IF(OR(KOL_Database!$J$5="",KOL_Database!$J$5=0,KOL_Database!$L$5=""),"",ROUND(KOL_Database!$L$5/KOL_Database!$J$5,3)) | BD5: =IF(OR(KOL_Database!$AP$5="",KOL_Database!$AP$5=0,Lookup_Lists!$D$149=0),"",MIN(100,ROUND(Lookup_Lists!$D$149/KOL_Database!$AP$5*100,0))) | BE5: =ROUND((IF(KOL_Database!$J$5="",0,1)+IF(KOL_Database!$K$5="",0,1)+IF(KOL_Database!$L$5="",0,1)+IF(KOL_Database!$M$5="",0,1)+IF(KOL_Database!$N$5="",0,1)+IF(KOL_Database!$O$5="",0,1)+IF(KOL_Database!$P$5="",0,1)+IF(KOL_Database!$R$5="",0,1)+IF(KOL_Database!$S$5="",0,1)+IF(KOL_Database!$AE$5="",0,1)+IF(KOL_Database!$AF$5="",0,1)+IF(KOL_Database!$AN$5="",0,1))/12*100,0) | BF5: =IF(KOL_Database!$BE$5>=Lookup_Lists!$D$159,"Live",IF(KOL_Database!$BE$5>=Lookup_Lists!$D$160,"Calculated","Estimated"))
A6: KOL-02 | B6: Rifqi Pratama | C6: @rifqi.codes | D6: TikTok | E6: Tech | F6: Software & SaaS | G6: =IFERROR(INDEX(Lookup_Lists!$A$96:$A$100,MATCH(KOL_Database!$J$6,Lookup_Lists!$B$96:$B$100,1)),"") | H6: No | I6: Bandung | J6: 86000 | K6: 6.2 | L6: 87604 | M6: 64637 | N6: 4.9 | O6: 10.8 | P6: 56 | Q6: 92 | R6: 75 | S6: 89 | T6: 1.15 | U6: 2.52 | V6: 69 | W6: 10 | X6: 35 | Y6: 32 | Z6: 15 | AA6: 8 | AB6: 26 | AC6: 74 | AD6: Indonesia | AE6: Jawa Barat | AF6: Bandung | AG6: Technology, Productivity, Education, Business, Finance | AH6: Medium | AI6: Technology, Productivity, Education, Business | AJ6: Educational | AK6: Educational | AL6: Innovation, Empowerment, Transparency, Quality | AM6: 77 | AN6: 4738000 | AO6: =IF(OR(KOL_Database!$AN$6="",KOL_Database!$AN$6=0,KOL_Database!$L$6="",KOL_Database!$L$6=0),"",ROUND(KOL_Database!$AN$6/KOL_Database!$L$6,2)) | AP6: =IF(OR(KOL_Database!$AN$6="",KOL_Database!$AN$6=0,KOL_Database!$L$6="",KOL_Database!$L$6=0,KOL_Database!$K$6="",KOL_Database!$K$6=0),"",ROUND(KOL_Database!$AN$6/(KOL_Database!$L$6*KOL_Database!$K$6/100),0)) | AQ6: =IF(OR(KOL_Database!$AN$6="",KOL_Database!$AN$6=0,KOL_Database!$J$6="",KOL_Database!$J$6=0),"",ROUND(KOL_Database!$AN$6/KOL_Database!$J$6*1000,0)) | AR6: =IF(OR(KOL_Database!$L$6="",KOL_Database!$J$6=""),"",ROUND(KOL_Database!$L$6*Lookup_Lists!$D$147+KOL_Database!$J$6*Lookup_Lists!$D$148,0)) | AS6: =IF(OR(KOL_Database!$AN$6="",KOL_Database!$AN$6=0,KOL_Database!$AR$6=""),"",ROUND(KOL_Database!$AR$6*KOL_Database!$K$6/100*Lookup_Lists!$D$146/KOL_Database!$AN$6,2)) | AT6: 82 | AU6: 40 | AV6: None | AW6: No | AX6: No | AY6: No | AZ6: No | BA6: 46069.708 | BB6: 46248.708 | BC6: =IF(OR(KOL_Database!$J$6="",KOL_Database!$J$6=0,KOL_Database!$L$6=""),"",ROUND(KOL_Database!$L$6/KOL_Database!$J$6,3)) | BD6: =IF(OR(KOL_Database!$AP$6="",KOL_Database!$AP$6=0,Lookup_Lists!$D$149=0),"",MIN(100,ROUND(Lookup_Lists!$D$149/KOL_Database!$AP$6*100,0))) | BE6: =ROUND((IF(KOL_Database!$J$6="",0,1)+IF(KOL_Database!$K$6="",0,1)+IF(KOL_Database!$L$6="",0,1)+IF(KOL_Database!$M$6="",0,1)+IF(KOL_Database!$N$6="",0,1)+IF(KOL_Database!$O$6="",0,1)+IF(KOL_Database!$P$6="",0,1)+IF(KOL_Database!$R$6="",0,1)+IF(KOL_Database!$S$6="",0,1)+IF(KOL_Database!$AE$6="",0,1)+IF(KOL_Database!$AF$6="",0,1)+IF(KOL_Database!$AN$6="",0,1))/12*100,0) | BF6: =IF(KOL_Database!$BE$6>=Lookup_Lists!$D$159,"Live",IF(KOL_Database!$BE$6>=Lookup_Lists!$D$160,"Calculated","Estimated"))
A7: KOL-03 | B7: Salsa Aulia | C7: @salsabeautydiary | D7: Instagram | E7: Beauty | F7: Skincare | G7: =IFERROR(INDEX(Lookup_Lists!$A$96:$A$100,MATCH(KOL_Database!$J$7,Lookup_Lists!$B$96:$B$100,1)),"") | H7: Yes | I7: Jakarta | J7: 240000 | K7: 4.4 | L7: 71261 | M7: 54519 | N7: 2.7 | O7: 8.5 | P7: 74 | Q7: 68 | R7: 77 | S7: 84 | T7: 1.34 | U7: 2.94 | V7: 74 | W7: 7 | X7: 39 | Y7: 35 | Z7: 14 | AA7: 5 | AB7: 86 | AC7: 14 | AD7: Indonesia | AE7: DKI Jakarta | AF7: Jakarta | AG7: Skincare, Beauty, Makeup, Shopping, Health | AH7: High | AI7: Skincare, Beauty, Health | AJ7: Review | AK7: Reviewer | AL7: Authenticity, Quality, Trust, Health | AM7: 81 | AN7: 6906000 | AO7: =IF(OR(KOL_Database!$AN$7="",KOL_Database!$AN$7=0,KOL_Database!$L$7="",KOL_Database!$L$7=0),"",ROUND(KOL_Database!$AN$7/KOL_Database!$L$7,2)) | AP7: =IF(OR(KOL_Database!$AN$7="",KOL_Database!$AN$7=0,KOL_Database!$L$7="",KOL_Database!$L$7=0,KOL_Database!$K$7="",KOL_Database!$K$7=0),"",ROUND(KOL_Database!$AN$7/(KOL_Database!$L$7*KOL_Database!$K$7/100),0)) | AQ7: =IF(OR(KOL_Database!$AN$7="",KOL_Database!$AN$7=0,KOL_Database!$J$7="",KOL_Database!$J$7=0),"",ROUND(KOL_Database!$AN$7/KOL_Database!$J$7*1000,0)) | AR7: =IF(OR(KOL_Database!$L$7="",KOL_Database!$J$7=""),"",ROUND(KOL_Database!$L$7*Lookup_Lists!$D$147+KOL_Database!$J$7*Lookup_Lists!$D$148,0)) | AS7: =IF(OR(KOL_Database!$AN$7="",KOL_Database!$AN$7=0,KOL_Database!$AR$7=""),"",ROUND(KOL_Database!$AR$7*KOL_Database!$K$7/100*Lookup_Lists!$D$146/KOL_Database!$AN$7,2)) | AT7: 85 | AU7: 45 | AV7: None | AW7: Yes | AX7: No | AY7: No | AZ7: No | BA7: 46088.708 | BB7: 46238.708 | BC7: =IF(OR(KOL_Database!$J$7="",KOL_Database!$J$7=0,KOL_Database!$L$7=""),"",ROUND(KOL_Database!$L$7/KOL_Database!$J$7,3)) | BD7: =IF(OR(KOL_Database!$AP$7="",KOL_Database!$AP$7=0,Lookup_Lists!$D$149=0),"",MIN(100,ROUND(Lookup_Lists!$D$149/KOL_Database!$AP$7*100,0))) | BE7: =ROUND((IF(KOL_Database!$J$7="",0,1)+IF(KOL_Database!$K$7="",0,1)+IF(KOL_Database!$L$7="",0,1)+IF(KOL_Database!$M$7="",0,1)+IF(KOL_Database!$N$7="",0,1)+IF(KOL_Database!$O$7="",0,1)+IF(KOL_Database!$P$7="",0,1)+IF(KOL_Database!$R$7="",0,1)+IF(KOL_Database!$S$7="",0,1)+IF(KOL_Database!$AE$7="",0,1)+IF(KOL_Database!$AF$7="",0,1)+IF(KOL_Database!$AN$7="",0,1))/12*100,0) | BF7: =IF(KOL_Database!$BE$7>=Lookup_Lists!$D$159,"Live",IF(KOL_Database!$BE$7>=Lookup_Lists!$D$160,"Calculated","Estimated"))
A8: KOL-04 | B8: Nadia Puspa | C8: @nadiaglowup | D8: TikTok | E8: Beauty | F8: Makeup | G8: =IFERROR(INDEX(Lookup_Lists!$A$96:$A$100,MATCH(KOL_Database!$J$8,Lookup_Lists!$B$96:$B$100,1)),"") | H8: Yes | I8: Surabaya | J8: 512000 | K8: 7.1 | L8: 663796 | M8: 524778 | N8: 7 | O8: 19.3 | P8: 85 | Q8: 78 | R8: 82 | S8: 85 | T8: 1.63 | U8: 3.35 | V8: 81 | W8: 12 | X8: 44 | Y8: 30 | Z8: 10 | AA8: 4 | AB8: 81 | AC8: 19 | AD8: Indonesia | AE8: Jawa Timur | AF8: Surabaya | AG8: Makeup, Beauty, Fashion, Shopping, Entertainment | AH8: High | AI8: Makeup, Beauty, Fashion | AJ8: Tutorial | AK8: Creative | AL8: Fun, Authenticity, Quality, Empowerment | AM8: 85 | AN8: 14504000 | AO8: =IF(OR(KOL_Database!$AN$8="",KOL_Database!$AN$8=0,KOL_Database!$L$8="",KOL_Database!$L$8=0),"",ROUND(KOL_Database!$AN$8/KOL_Database!$L$8,2)) | AP8: =IF(OR(KOL_Database!$AN$8="",KOL_Database!$AN$8=0,KOL_Database!$L$8="",KOL_Database!$L$8=0,KOL_Database!$K$8="",KOL_Database!$K$8=0),"",ROUND(KOL_Database!$AN$8/(KOL_Database!$L$8*KOL_Database!$K$8/100),0)) | AQ8: =IF(OR(KOL_Database!$AN$8="",KOL_Database!$AN$8=0,KOL_Database!$J$8="",KOL_Database!$J$8=0),"",ROUND(KOL_Database!$AN$8/KOL_Database!$J$8*1000,0)) | AR8: =IF(OR(KOL_Database!$L$8="",KOL_Database!$J$8=""),"",ROUND(KOL_Database!$L$8*Lookup_Lists!$D$147+KOL_Database!$J$8*Lookup_Lists!$D$148,0)) | AS8: =IF(OR(KOL_Database!$AN$8="",KOL_Database!$AN$8=0,KOL_Database!$AR$8=""),"",ROUND(KOL_Database!$AR$8*KOL_Database!$K$8/100*Lookup_Lists!$D$146/KOL_Database!$AN$8,2)) | AT8: 89 | AU8: 78 | AV8: Medium | AW8: No | AX8: No | AY8: Yes | AZ8: No | BA8: 46098.708 | BB8: 46253.708 | BC8: =IF(OR(KOL_Database!$J$8="",KOL_Database!$J$8=0,KOL_Database!$L$8=""),"",ROUND(KOL_Database!$L$8/KOL_Database!$J$8,3)) | BD8: =IF(OR(KOL_Database!$AP$8="",KOL_Database!$AP$8=0,Lookup_Lists!$D$149=0),"",MIN(100,ROUND(Lookup_Lists!$D$149/KOL_Database!$AP$8*100,0))) | BE8: =ROUND((IF(KOL_Database!$J$8="",0,1)+IF(KOL_Database!$K$8="",0,1)+IF(KOL_Database!$L$8="",0,1)+IF(KOL_Database!$M$8="",0,1)+IF(KOL_Database!$N$8="",0,1)+IF(KOL_Database!$O$8="",0,1)+IF(KOL_Database!$P$8="",0,1)+IF(KOL_Database!$R$8="",0,1)+IF(KOL_Database!$S$8="",0,1)+IF(KOL_Database!$AE$8="",0,1)+IF(KOL_Database!$AF$8="",0,1)+IF(KOL_Database!$AN$8="",0,1))/12*100,0) | BF8: =IF(KOL_Database!$BE$8>=Lookup_Lists!$D$159,"Live",IF(KOL_Database!$BE$8>=Lookup_Lists!$D$160,"Calculated","Estimated"))
A9: KOL-05 | B9: Bimo Saputra | C9: @bimomakan | D9: TikTok | E9: Food | F9: Culinary Review | G9: =IFERROR(INDEX(Lookup_Lists!$A$96:$A$100,MATCH(KOL_Database!$J$9,Lookup_Lists!$B$96:$B$100,1)),"") | H9: Yes | I9: Jakarta | J9: 375000 | K9: 8.4 | L9: 360494 | M9: 255180 | N9: 3.6 | O9: 9.5 | P9: 75 | Q9: 67 | R9: 70 | S9: 83 | T9: 1.1 | U9: 2.04 | V9: 61 | W9: 7 | X9: 40 | Y9: 35 | Z9: 13 | AA9: 5 | AB9: 48 | AC9: 52 | AD9: Indonesia | AE9: Nasional | AF9: Jakarta | AG9: Food, Cooking, Travel, Shopping, Entertainment | AH9: High | AI9: Food, Cooking, Travel | AJ9: Review | AK9: Relatable | AL9: Fun, Authenticity, Community, Affordability | AM9: 72 | AN9: 11482000 | AO9: =IF(OR(KOL_Database!$AN$9="",KOL_Database!$AN$9=0,KOL_Database!$L$9="",KOL_Database!$L$9=0),"",ROUND(KOL_Database!$AN$9/KOL_Database!$L$9,2)) | AP9: =IF(OR(KOL_Database!$AN$9="",KOL_Database!$AN$9=0,KOL_Database!$L$9="",KOL_Database!$L$9=0,KOL_Database!$K$9="",KOL_Database!$K$9=0),"",ROUND(KOL_Database!$AN$9/(KOL_Database!$L$9*KOL_Database!$K$9/100),0)) | AQ9: =IF(OR(KOL_Database!$AN$9="",KOL_Database!$AN$9=0,KOL_Database!$J$9="",KOL_Database!$J$9=0),"",ROUND(KOL_Database!$AN$9/KOL_Database!$J$9*1000,0)) | AR9: =IF(OR(KOL_Database!$L$9="",KOL_Database!$J$9=""),"",ROUND(KOL_Database!$L$9*Lookup_Lists!$D$147+KOL_Database!$J$9*Lookup_Lists!$D$148,0)) | AS9: =IF(OR(KOL_Database!$AN$9="",KOL_Database!$AN$9=0,KOL_Database!$AR$9=""),"",ROUND(KOL_Database!$AR$9*KOL_Database!$K$9/100*Lookup_Lists!$D$146/KOL_Database!$AN$9,2)) | AT9: 78 | AU9: 30 | AV9: Low | AW9: No | AX9: No | AY9: No | AZ9: No | BA9: 46157.708 | BB9: 46260.708 | BC9: =IF(OR(KOL_Database!$J$9="",KOL_Database!$J$9=0,KOL_Database!$L$9=""),"",ROUND(KOL_Database!$L$9/KOL_Database!$J$9,3)) | BD9: =IF(OR(KOL_Database!$AP$9="",KOL_Database!$AP$9=0,Lookup_Lists!$D$149=0),"",MIN(100,ROUND(Lookup_Lists!$D$149/KOL_Database!$AP$9*100,0))) | BE9: =ROUND((IF(KOL_Database!$J$9="",0,1)+IF(KOL_Database!$K$9="",0,1)+IF(KOL_Database!$L$9="",0,1)+IF(KOL_Database!$M$9="",0,1)+IF(KOL_Database!$N$9="",0,1)+IF(KOL_Database!$O$9="",0,1)+IF(KOL_Database!$P$9="",0,1)+IF(KOL_Database!$R$9="",0,1)+IF(KOL_Database!$S$9="",0,1)+IF(KOL_Database!$AE$9="",0,1)+IF(KOL_Database!$AF$9="",0,1)+IF(KOL_Database!$AN$9="",0,1))/12*100,0) | BF9: =IF(KOL_Database!$BE$9>=Lookup_Lists!$D$159,"Live",IF(KOL_Database!$BE$9>=Lookup_Lists!$D$160,"Calculated","Estimated"))
A10: KOL-06 | B10: Ayu Lestari | C10: @dapurayu | D10: Instagram | E10: Food | F10: Home Cooking | G10: =IFERROR(INDEX(Lookup_Lists!$A$96:$A$100,MATCH(KOL_Database!$J$10,Lookup_Lists!$B$96:$B$100,1)),"") | H10: No | I10: Yogyakarta | J10: 64000 | K10: 5.2 | L10: 19195 | M10: 14121 | N10: 6 | O10: 18.5 | P10: 63 | Q10: 58 | R10: 73 | S10: 67 | T10: 0.96 | U10: 1.97 | V10: 61 | W10: 1 | X10: 22 | Y10: 46 | Z10: 18 | AA10: 13 | AB10: 86 | AC10: 14 | AD10: Indonesia | AF10: Yogyakarta | AG10: Cooking, Food, Parenting, Home Decor, Health | AH10: Medium | AI10: Cooking, Food, Parenting | AJ10: Tutorial | AK10: Relatable | AL10: Family, Community, Quality, Affordability | AM10: 72 | AN10: 2638000 | AO10: =IF(OR(KOL_Database!$AN$10="",KOL_Database!$AN$10=0,KOL_Database!$L$10="",KOL_Database!$L$10=0),"",ROUND(KOL_Database!$AN$10/KOL_Database!$L$10,2)) | AP10: =IF(OR(KOL_Database!$AN$10="",KOL_Database!$AN$10=0,KOL_Database!$L$10="",KOL_Database!$L$10=0,KOL_Database!$K$10="",KOL_Database!$K$10=0),"",ROUND(KOL_Database!$AN$10/(KOL_Database!$L$10*KOL_Database!$K$10/100),0)) | AQ10: =IF(OR(KOL_Database!$AN$10="",KOL_Database!$AN$10=0,KOL_Database!$J$10="",KOL_Database!$J$10=0),"",ROUND(KOL_Database!$AN$10/KOL_Database!$J$10*1000,0)) | AR10: =IF(OR(KOL_Database!$L$10="",KOL_Database!$J$10=""),"",ROUND(KOL_Database!$L$10*Lookup_Lists!$D$147+KOL_Database!$J$10*Lookup_Lists!$D$148,0)) | AS10: =IF(OR(KOL_Database!$AN$10="",KOL_Database!$AN$10=0,KOL_Database!$AR$10=""),"",ROUND(KOL_Database!$AR$10*KOL_Database!$K$10/100*Lookup_Lists!$D$146/KOL_Database!$AN$10,2)) | AT10: 79 | AU10: 29 | AV10: Low | AW10: No | AX10: No | AY10: No | AZ10: No | BA10: 46053.708 | BB10: 46266.708 | BC10: =IF(OR(KOL_Database!$J$10="",KOL_Database!$J$10=0,KOL_Database!$L$10=""),"",ROUND(KOL_Database!$L$10/KOL_Database!$J$10,3)) | BD10: =IF(OR(KOL_Database!$AP$10="",KOL_Database!$AP$10=0,Lookup_Lists!$D$149=0),"",MIN(100,ROUND(Lookup_Lists!$D$149/KOL_Database!$AP$10*100,0))) | BE10: =ROUND((IF(KOL_Database!$J$10="",0,1)+IF(KOL_Database!$K$10="",0,1)+IF(KOL_Database!$L$10="",0,1)+IF(KOL_Database!$M$10="",0,1)+IF(KOL_Database!$N$10="",0,1)+IF(KOL_Database!$O$10="",0,1)+IF(KOL_Database!$P$10="",0,1)+IF(KOL_Database!$R$10="",0,1)+IF(KOL_Database!$S$10="",0,1)+IF(KOL_Database!$AE$10="",0,1)+IF(KOL_Database!$AF$10="",0,1)+IF(KOL_Database!$AN$10="",0,1))/12*100,0) | BF10: =IF(KOL_Database!$BE$10>=Lookup_Lists!$D$159,"Live",IF(KOL_Database!$BE$10>=Lookup_Lists!$D$160,"Calculated","Estimated"))
A11: KOL-07 | B11: Fajar Ramadhan | C11: @fajarfinance | D11: Instagram | E11: Finance | F11: Personal Finance | G11: =IFERROR(INDEX(Lookup_Lists!$A$96:$A$100,MATCH(KOL_Database!$J$11,Lookup_Lists!$B$96:$B$100,1)),"") | H11: Yes | I11: Jakarta | J11: 152000 | K11: 3.2 | L11: 53466 | M11: 43843 | N11: 3.2 | O11: 8.1 | P11: 83 | Q11: 85 | R11: 86 | S11: 73 | T11: 2.08 | U11: 3.82 | V11: 88 | W11: 6 | X11: 23 | Y11: 41 | Z11: 20 | AA11: 10 | AB11: 21 | AC11: 79 | AD11: Indonesia | AE11: DKI Jakarta | AF11: Jakarta | AG11: Finance, Business, Education, Technology, Productivity | AH11: Medium | AI11: Finance, Business, Education | AJ11: Educational | AK11: Professional | AL11: Trust, Transparency, Empowerment, Quality | AM11: 89 | AN11: 5065000 | AO11: =IF(OR(KOL_Database!$AN$11="",KOL_Database!$AN$11=0,KOL_Database!$L$11="",KOL_Database!$L$11=0),"",ROUND(KOL_Database!$AN$11/KOL_Database!$L$11,2)) | AP11: =IF(OR(KOL_Database!$AN$11="",KOL_Database!$AN$11=0,KOL_Database!$L$11="",KOL_Database!$L$11=0,KOL_Database!$K$11="",KOL_Database!$K$11=0),"",ROUND(KOL_Database!$AN$11/(KOL_Database!$L$11*KOL_Database!$K$11/100),0)) | AQ11: =IF(OR(KOL_Database!$AN$11="",KOL_Database!$AN$11=0,KOL_Database!$J$11="",KOL_Database!$J$11=0),"",ROUND(KOL_Database!$AN$11/KOL_Database!$J$11*1000,0)) | AR11: =IF(OR(KOL_Database!$L$11="",KOL_Database!$J$11=""),"",ROUND(KOL_Database!$L$11*Lookup_Lists!$D$147+KOL_Database!$J$11*Lookup_Lists!$D$148,0)) | AS11: =IF(OR(KOL_Database!$AN$11="",KOL_Database!$AN$11=0,KOL_Database!$AR$11=""),"",ROUND(KOL_Database!$AR$11*KOL_Database!$K$11/100*Lookup_Lists!$D$146/KOL_Database!$AN$11,2)) | AT11: 93 | AU11: 60 | AV11: None | AW11: No | AX11: No | AY11: No | AZ11: No | BA11: 46225.708 | BB11: 46236.708 | BC11: =IF(OR(KOL_Database!$J$11="",KOL_Database!$J$11=0,KOL_Database!$L$11=""),"",ROUND(KOL_Database!$L$11/KOL_Database!$J$11,3)) | BD11: =IF(OR(KOL_Database!$AP$11="",KOL_Database!$AP$11=0,Lookup_Lists!$D$149=0),"",MIN(100,ROUND(Lookup_Lists!$D$149/KOL_Database!$AP$11*100,0))) | BE11: =ROUND((IF(KOL_Database!$J$11="",0,1)+IF(KOL_Database!$K$11="",0,1)+IF(KOL_Database!$L$11="",0,1)+IF(KOL_Database!$M$11="",0,1)+IF(KOL_Database!$N$11="",0,1)+IF(KOL_Database!$O$11="",0,1)+IF(KOL_Database!$P$11="",0,1)+IF(KOL_Database!$R$11="",0,1)+IF(KOL_Database!$S$11="",0,1)+IF(KOL_Database!$AE$11="",0,1)+IF(KOL_Database!$AF$11="",0,1)+IF(KOL_Database!$AN$11="",0,1))/12*100,0) | BF11: =IF(KOL_Database!$BE$11>=Lookup_Lists!$D$159,"Live",IF(KOL_Database!$BE$11>=Lookup_Lists!$D$160,"Calculated","Estimated"))
A12: KOL-08 | B12: Tania Wijaya | C12: @taniainvest | D12: TikTok | E12: Finance | F12: Investing | G12: =IFERROR(INDEX(Lookup_Lists!$A$96:$A$100,MATCH(KOL_Database!$J$12,Lookup_Lists!$B$96:$B$100,1)),"") | H12: No | I12: Jakarta | J12: 98000 | K12: 5.6 | L12: 66537 | M12: 43248 | N12: 3.8 | O12: 12.9 | P12: 77 | Q12: 67 | R12: 64 | S12: 94 | T12: 0.4 | U12: 0.87 | V12: 50 | W12: 9 | X12: 37 | Y12: 33 | Z12: 14 | AA12: 7 | AB12: 68 | AC12: 32 | AD12: Indonesia | AE12: DKI Jakarta | AF12: Jakarta | AG12: Finance, Business, Education, Productivity, Shopping | AH12: Medium | AI12: Finance, Business, Productivity | AJ12: Educational | AK12: Educational | AL12: Empowerment, Transparency, Trust, Innovation | AM12: 63 | AN12: 3492000 | AO12: =IF(OR(KOL_Database!$AN$12="",KOL_Database!$AN$12=0,KOL_Database!$L$12="",KOL_Database!$L$12=0),"",ROUND(KOL_Database!$AN$12/KOL_Database!$L$12,2)) | AP12: =IF(OR(KOL_Database!$AN$12="",KOL_Database!$AN$12=0,KOL_Database!$L$12="",KOL_Database!$L$12=0,KOL_Database!$K$12="",KOL_Database!$K$12=0),"",ROUND(KOL_Database!$AN$12/(KOL_Database!$L$12*KOL_Database!$K$12/100),0)) | AQ12: =IF(OR(KOL_Database!$AN$12="",KOL_Database!$AN$12=0,KOL_Database!$J$12="",KOL_Database!$J$12=0),"",ROUND(KOL_Database!$AN$12/KOL_Database!$J$12*1000,0)) | AR12: =IF(OR(KOL_Database!$L$12="",KOL_Database!$J$12=""),"",ROUND(KOL_Database!$L$12*Lookup_Lists!$D$147+KOL_Database!$J$12*Lookup_Lists!$D$148,0)) | AS12: =IF(OR(KOL_Database!$AN$12="",KOL_Database!$AN$12=0,KOL_Database!$AR$12=""),"",ROUND(KOL_Database!$AR$12*KOL_Database!$K$12/100*Lookup_Lists!$D$146/KOL_Database!$AN$12,2)) | AT12: 72 | AU12: 14 | AV12: Low | AW12: No | AX12: No | AY12: No | AZ12: No | BA12: 46121.708 | BB12: 46265.708 | BC12: =IF(OR(KOL_Database!$J$12="",KOL_Database!$J$12=0,KOL_Database!$L$12=""),"",ROUND(KOL_Database!$L$12/KOL_Database!$J$12,3)) | BD12: =IF(OR(KOL_Database!$AP$12="",KOL_Database!$AP$12=0,Lookup_Lists!$D$149=0),"",MIN(100,ROUND(Lookup_Lists!$D$149/KOL_Database!$AP$12*100,0))) | BE12: =ROUND((IF(KOL_Database!$J$12="",0,1)+IF(KOL_Database!$K$12="",0,1)+IF(KOL_Database!$L$12="",0,1)+IF(KOL_Database!$M$12="",0,1)+IF(KOL_Database!$N$12="",0,1)+IF(KOL_Database!$O$12="",0,1)+IF(KOL_Database!$P$12="",0,1)+IF(KOL_Database!$R$12="",0,1)+IF(KOL_Database!$S$12="",0,1)+IF(KOL_Database!$AE$12="",0,1)+IF(KOL_Database!$AF$12="",0,1)+IF(KOL_Database!$AN$12="",0,1))/12*100,0) | BF12: =IF(KOL_Database!$BE$12>=Lookup_Lists!$D$159,"Live",IF(KOL_Database!$BE$12>=Lookup_Lists!$D$160,"Calculated","Estimated"))
A13: KOL-09 | B13: Gilang Prakoso | C13: @gilangbelajar | D13: TikTok | E13: Education | F13: Study Tips | G13: =IFERROR(INDEX(Lookup_Lists!$A$96:$A$100,MATCH(KOL_Database!$J$13,Lookup_Lists!$B$96:$B$100,1)),"") | H13: Yes | I13: Semarang | J13: 210000 | K13: 6.8 | L13: 310647 | M13: 254639 | N13: 7.3 | O13: 24.7 | P13: 85 | Q13: 83 | R13: 86 | S13: 91 | T13: 2.11 | U13: 3.81 | V13: 86 | W13: 12 | X13: 44 | Y13: 30 | Z13: 10 | AA13: 4 | AB13: 52 | AC13: 48 | AD13: Indonesia | AE13: Jawa Tengah | AF13: Semarang | AG13: Education, Productivity, Technology, Entertainment, Business | AH13: Low | AI13: Education, Productivity, Technology | AJ13: Educational | AK13: Educational | AL13: Empowerment, Community, Trust, Innovation | AM13: 89 | AN13: 4653000 | AO13: =IF(OR(KOL_Database!$AN$13="",KOL_Database!$AN$13=0,KOL_Database!$L$13="",KOL_Database!$L$13=0),"",ROUND(KOL_Database!$AN$13/KOL_Database!$L$13,2)) | AP13: =IF(OR(KOL_Database!$AN$13="",KOL_Database!$AN$13=0,KOL_Database!$L$13="",KOL_Database!$L$13=0,KOL_Database!$K$13="",KOL_Database!$K$13=0),"",ROUND(KOL_Database!$AN$13/(KOL_Database!$L$13*KOL_Database!$K$13/100),0)) | AQ13: =IF(OR(KOL_Database!$AN$13="",KOL_Database!$AN$13=0,KOL_Database!$J$13="",KOL_Database!$J$13=0),"",ROUND(KOL_Database!$AN$13/KOL_Database!$J$13*1000,0)) | AR13: =IF(OR(KOL_Database!$L$13="",KOL_Database!$J$13=""),"",ROUND(KOL_Database!$L$13*Lookup_Lists!$D$147+KOL_Database!$J$13*Lookup_Lists!$D$148,0)) | AS13: =IF(OR(KOL_Database!$AN$13="",KOL_Database!$AN$13=0,KOL_Database!$AR$13=""),"",ROUND(KOL_Database!$AR$13*KOL_Database!$K$13/100*Lookup_Lists!$D$146/KOL_Database!$AN$13,2)) | AT13: 92 | AU13: 61 | AV13: None | AW13: No | AX13: No | AY13: No | AZ13: No | BA13: 46177.708 | BB13: 46272.708 | BC13: =IF(OR(KOL_Database!$J$13="",KOL_Database!$J$13=0,KOL_Database!$L$13=""),"",ROUND(KOL_Database!$L$13/KOL_Database!$J$13,3)) | BD13: =IF(OR(KOL_Database!$AP$13="",KOL_Database!$AP$13=0,Lookup_Lists!$D$149=0),"",MIN(100,ROUND(Lookup_Lists!$D$149/KOL_Database!$AP$13*100,0))) | BE13: =ROUND((IF(KOL_Database!$J$13="",0,1)+IF(KOL_Database!$K$13="",0,1)+IF(KOL_Database!$L$13="",0,1)+IF(KOL_Database!$M$13="",0,1)+IF(KOL_Database!$N$13="",0,1)+IF(KOL_Database!$O$13="",0,1)+IF(KOL_Database!$P$13="",0,1)+IF(KOL_Database!$R$13="",0,1)+IF(KOL_Database!$S$13="",0,1)+IF(KOL_Database!$AE$13="",0,1)+IF(KOL_Database!$AF$13="",0,1)+IF(KOL_Database!$AN$13="",0,1))/12*100,0) | BF13: =IF(KOL_Database!$BE$13>=Lookup_Lists!$D$159,"Live",IF(KOL_Database!$BE$13>=Lookup_Lists!$D$160,"Calculated","Estimated"))
A14: KOL-10 | B14: Mira Handayani | C14: @mirabahasa | D14: Instagram | E14: Education | F14: Language | G14: =IFERROR(INDEX(Lookup_Lists!$A$96:$A$100,MATCH(KOL_Database!$J$14,Lookup_Lists!$B$96:$B$100,1)),"") | H14: No | I14: Bandung | J14: 42000 | K14: 4.9 | L14: 11783 | N14: 1.6 | O14: 4.7 | P14: 94 | Q14: 85 | R14: 75 | S14: 64 | T14: 1.29 | U14: 2.15 | V14: 69 | W14: 6 | X14: 41 | Y14: 36 | Z14: 13 | AA14: 4 | AB14: 70 | AC14: 30 | AD14: Indonesia | AE14: Jawa Barat | AF14: Bandung | AG14: Education, Travel, Productivity, Entertainment, Technology | AH14: Low | AI14: Education, Travel, Productivity | AJ14: Tutorial | AK14: Educational | AL14: Empowerment, Quality, Community, Trust | AM14: 73 | AN14: 1427000 | AO14: =IF(OR(KOL_Database!$AN$14="",KOL_Database!$AN$14=0,KOL_Database!$L$14="",KOL_Database!$L$14=0),"",ROUND(KOL_Database!$AN$14/KOL_Database!$L$14,2)) | AP14: =IF(OR(KOL_Database!$AN$14="",KOL_Database!$AN$14=0,KOL_Database!$L$14="",KOL_Database!$L$14=0,KOL_Database!$K$14="",KOL_Database!$K$14=0),"",ROUND(KOL_Database!$AN$14/(KOL_Database!$L$14*KOL_Database!$K$14/100),0)) | AQ14: =IF(OR(KOL_Database!$AN$14="",KOL_Database!$AN$14=0,KOL_Database!$J$14="",KOL_Database!$J$14=0),"",ROUND(KOL_Database!$AN$14/KOL_Database!$J$14*1000,0)) | AR14: =IF(OR(KOL_Database!$L$14="",KOL_Database!$J$14=""),"",ROUND(KOL_Database!$L$14*Lookup_Lists!$D$147+KOL_Database!$J$14*Lookup_Lists!$D$148,0)) | AS14: =IF(OR(KOL_Database!$AN$14="",KOL_Database!$AN$14=0,KOL_Database!$AR$14=""),"",ROUND(KOL_Database!$AR$14*KOL_Database!$K$14/100*Lookup_Lists!$D$146/KOL_Database!$AN$14,2)) | AT14: 83 | AU14: 32 | AV14: None | AW14: No | AX14: No | AY14: No | AZ14: No | BA14: 46093.708 | BB14: 46239.708 | BC14: =IF(OR(KOL_Database!$J$14="",KOL_Database!$J$14=0,KOL_Database!$L$14=""),"",ROUND(KOL_Database!$L$14/KOL_Database!$J$14,3)) | BD14: =IF(OR(KOL_Database!$AP$14="",KOL_Database!$AP$14=0,Lookup_Lists!$D$149=0),"",MIN(100,ROUND(Lookup_Lists!$D$149/KOL_Database!$AP$14*100,0))) | BE14: =ROUND((IF(KOL_Database!$J$14="",0,1)+IF(KOL_Database!$K$14="",0,1)+IF(KOL_Database!$L$14="",0,1)+IF(KOL_Database!$M$14="",0,1)+IF(KOL_Database!$N$14="",0,1)+IF(KOL_Database!$O$14="",0,1)+IF(KOL_Database!$P$14="",0,1)+IF(KOL_Database!$R$14="",0,1)+IF(KOL_Database!$S$14="",0,1)+IF(KOL_Database!$AE$14="",0,1)+IF(KOL_Database!$AF$14="",0,1)+IF(KOL_Database!$AN$14="",0,1))/12*100,0) | BF14: =IF(KOL_Database!$BE$14>=Lookup_Lists!$D$159,"Live",IF(KOL_Database!$BE$14>=Lookup_Lists!$D$160,"Calculated","Estimated"))
A15: KOL-11 | B15: Dimas Anggara | C15: @dimasfit | D15: Instagram | E15: Fitness | F15: Gym & Strength | G15: =IFERROR(INDEX(Lookup_Lists!$A$96:$A$100,MATCH(KOL_Database!$J$15,Lookup_Lists!$B$96:$B$100,1)),"") | H15: Yes | I15: Jakarta | J15: 178000 | K15: 3.9 | L15: 34767 | M15: 22194 | N15: 2 | O15: 6.1 | P15: 87 | Q15: 79 | R15: 61 | S15: 77 | T15: 0.31 | U15: 0.95 | V15: 48 | W15: 1 | X15: 24 | Y15: 50 | Z15: 20 | AA15: 5 | AB15: 28 | AC15: 72 | AD15: Indonesia | AE15: DKI Jakarta | AF15: Jakarta | AG15: Fitness, Health, Food, Fashion, Shopping | AH15: Medium | AI15: Fitness, Health, Food | AJ15: Demo | AK15: Professional | AL15: Performance, Health, Quality, Trust | AM15: 63 | AN15: 7793000 | AO15: =IF(OR(KOL_Database!$AN$15="",KOL_Database!$AN$15=0,KOL_Database!$L$15="",KOL_Database!$L$15=0),"",ROUND(KOL_Database!$AN$15/KOL_Database!$L$15,2)) | AP15: =IF(OR(KOL_Database!$AN$15="",KOL_Database!$AN$15=0,KOL_Database!$L$15="",KOL_Database!$L$15=0,KOL_Database!$K$15="",KOL_Database!$K$15=0),"",ROUND(KOL_Database!$AN$15/(KOL_Database!$L$15*KOL_Database!$K$15/100),0)) | AQ15: =IF(OR(KOL_Database!$AN$15="",KOL_Database!$AN$15=0,KOL_Database!$J$15="",KOL_Database!$J$15=0),"",ROUND(KOL_Database!$AN$15/KOL_Database!$J$15*1000,0)) | AR15: =IF(OR(KOL_Database!$L$15="",KOL_Database!$J$15=""),"",ROUND(KOL_Database!$L$15*Lookup_Lists!$D$147+KOL_Database!$J$15*Lookup_Lists!$D$148,0)) | AS15: =IF(OR(KOL_Database!$AN$15="",KOL_Database!$AN$15=0,KOL_Database!$AR$15=""),"",ROUND(KOL_Database!$AR$15*KOL_Database!$K$15/100*Lookup_Lists!$D$146/KOL_Database!$AN$15,2)) | AT15: 71 | AU15: 15 | AV15: Low | AW15: No | AX15: No | AY15: No | AZ15: No | BA15: 46092.708 | BB15: 46252.708 | BC15: =IF(OR(KOL_Database!$J$15="",KOL_Database!$J$15=0,KOL_Database!$L$15=""),"",ROUND(KOL_Database!$L$15/KOL_Database!$J$15,3)) | BD15: =IF(OR(KOL_Database!$AP$15="",KOL_Database!$AP$15=0,Lookup_Lists!$D$149=0),"",MIN(100,ROUND(Lookup_Lists!$D$149/KOL_Database!$AP$15*100,0))) | BE15: =ROUND((IF(KOL_Database!$J$15="",0,1)+IF(KOL_Database!$K$15="",0,1)+IF(KOL_Database!$L$15="",0,1)+IF(KOL_Database!$M$15="",0,1)+IF(KOL_Database!$N$15="",0,1)+IF(KOL_Database!$O$15="",0,1)+IF(KOL_Database!$P$15="",0,1)+IF(KOL_Database!$R$15="",0,1)+IF(KOL_Database!$S$15="",0,1)+IF(KOL_Database!$AE$15="",0,1)+IF(KOL_Database!$AF$15="",0,1)+IF(KOL_Database!$AN$15="",0,1))/12*100,0) | BF15: =IF(KOL_Database!$BE$15>=Lookup_Lists!$D$159,"Live",IF(KOL_Database!$BE$15>=Lookup_Lists!$D$160,"Calculated","Estimated"))
A16: KOL-12 | B16: Rani Kusuma | C16: @ranihomeworkout | D16: TikTok | E16: Fitness | F16: Home Workout | G16: =IFERROR(INDEX(Lookup_Lists!$A$96:$A$100,MATCH(KOL_Database!$J$16,Lookup_Lists!$B$96:$B$100,1)),"") | H16: No | I16: Tangerang | J16: 305000 | K16: 6.5 | L16: 343139 | M16: 266395 | N16: 2.7 | O16: 8.5 | P16: 86 | Q16: 88 | R16: 80 | S16: 75 | T16: 1.71 | U16: 3.13 | V16: 79 | W16: 5 | X16: 42 | Y16: 37 | Z16: 13 | AA16: 3 | AB16: 79 | AC16: 21 | AD16: Indonesia | AE16: Banten | AF16: Tangerang | AG16: Fitness, Health, Food, Beauty, Parenting | AH16: Medium | AI16: Fitness, Health, Food | AJ16: Tutorial | AK16: Inspirational | AL16: Health, Empowerment, Community, Performance | AM16: 82 | AN16: 11000000 | AO16: =IF(OR(KOL_Database!$AN$16="",KOL_Database!$AN$16=0,KOL_Database!$L$16="",KOL_Database!$L$16=0),"",ROUND(KOL_Database!$AN$16/KOL_Database!$L$16,2)) | AP16: =IF(OR(KOL_Database!$AN$16="",KOL_Database!$AN$16=0,KOL_Database!$L$16="",KOL_Database!$L$16=0,KOL_Database!$K$16="",KOL_Database!$K$16=0),"",ROUND(KOL_Database!$AN$16/(KOL_Database!$L$16*KOL_Database!$K$16/100),0)) | AQ16: =IF(OR(KOL_Database!$AN$16="",KOL_Database!$AN$16=0,KOL_Database!$J$16="",KOL_Database!$J$16=0),"",ROUND(KOL_Database!$AN$16/KOL_Database!$J$16*1000,0)) | AR16: =IF(OR(KOL_Database!$L$16="",KOL_Database!$J$16=""),"",ROUND(KOL_Database!$L$16*Lookup_Lists!$D$147+KOL_Database!$J$16*Lookup_Lists!$D$148,0)) | AS16: =IF(OR(KOL_Database!$AN$16="",KOL_Database!$AN$16=0,KOL_Database!$AR$16=""),"",ROUND(KOL_Database!$AR$16*KOL_Database!$K$16/100*Lookup_Lists!$D$146/KOL_Database!$AN$16,2)) | AT16: 88 | AU16: 49 | AV16: None | AW16: No | AX16: No | AY16: No | AZ16: No | BA16: 46096.708 | BB16: 46253.708 | BC16: =IF(OR(KOL_Database!$J$16="",KOL_Database!$J$16=0,KOL_Database!$L$16=""),"",ROUND(KOL_Database!$L$16/KOL_Database!$J$16,3)) | BD16: =IF(OR(KOL_Database!$AP$16="",KOL_Database!$AP$16=0,Lookup_Lists!$D$149=0),"",MIN(100,ROUND(Lookup_Lists!$D$149/KOL_Database!$AP$16*100,0))) | BE16: =ROUND((IF(KOL_Database!$J$16="",0,1)+IF(KOL_Database!$K$16="",0,1)+IF(KOL_Database!$L$16="",0,1)+IF(KOL_Database!$M$16="",0,1)+IF(KOL_Database!$N$16="",0,1)+IF(KOL_Database!$O$16="",0,1)+IF(KOL_Database!$P$16="",0,1)+IF(KOL_Database!$R$16="",0,1)+IF(KOL_Database!$S$16="",0,1)+IF(KOL_Database!$AE$16="",0,1)+IF(KOL_Database!$AF$16="",0,1)+IF(KOL_Database!$AN$16="",0,1))/12*100,0) | BF16: =IF(KOL_Database!$BE$16>=Lookup_Lists!$D$159,"Live",IF(KOL_Database!$BE$16>=Lookup_Lists!$D$160,"Calculated","Estimated"))
A17: KOL-13 | B17: Kevin Halim | C17: @kevinstyleid | D17: Instagram | E17: Fashion | F17: Streetwear | G17: =IFERROR(INDEX(Lookup_Lists!$A$96:$A$100,MATCH(KOL_Database!$J$17,Lookup_Lists!$B$96:$B$100,1)),"") | H17: No | I17: Jakarta | J17: 96000 | K17: 3.4 | L17: 33575 | M17: 27597 | N17: 5.5 | O17: 16.4 | P17: 64 | Q17: 64 | R17: 86 | S17: 69 | T17: 1.76 | U17: 3.33 | V17: 81 | W17: 12 | X17: 44 | Y17: 30 | Z17: 10 | AA17: 4 | AB17: 33 | AC17: 67 | AD17: Indonesia | AE17: DKI Jakarta | AF17: Jakarta | AG17: Fashion, Shopping, Music, Entertainment, Beauty | AH17: High | AI17: Fashion, Shopping, Music | AJ17: Aesthetic | AK17: Creative | AL17: Craftsmanship, Quality, Authenticity, Fun | AM17: 85 | AN17: 5595000 | AO17: =IF(OR(KOL_Database!$AN$17="",KOL_Database!$AN$17=0,KOL_Database!$L$17="",KOL_Database!$L$17=0),"",ROUND(KOL_Database!$AN$17/KOL_Database!$L$17,2)) | AP17: =IF(OR(KOL_Database!$AN$17="",KOL_Database!$AN$17=0,KOL_Database!$L$17="",KOL_Database!$L$17=0,KOL_Database!$K$17="",KOL_Database!$K$17=0),"",ROUND(KOL_Database!$AN$17/(KOL_Database!$L$17*KOL_Database!$K$17/100),0)) | AQ17: =IF(OR(KOL_Database!$AN$17="",KOL_Database!$AN$17=0,KOL_Database!$J$17="",KOL_Database!$J$17=0),"",ROUND(KOL_Database!$AN$17/KOL_Database!$J$17*1000,0)) | AR17: =IF(OR(KOL_Database!$L$17="",KOL_Database!$J$17=""),"",ROUND(KOL_Database!$L$17*Lookup_Lists!$D$147+KOL_Database!$J$17*Lookup_Lists!$D$148,0)) | AS17: =IF(OR(KOL_Database!$AN$17="",KOL_Database!$AN$17=0,KOL_Database!$AR$17=""),"",ROUND(KOL_Database!$AR$17*KOL_Database!$K$17/100*Lookup_Lists!$D$146/KOL_Database!$AN$17,2)) | AT17: 89 | AU17: 54 | AV17: None | AW17: No | AX17: No | AY17: No | AZ17: No | BA17: 46164.708 | BB17: 46255.708 | BC17: =IF(OR(KOL_Database!$J$17="",KOL_Database!$J$17=0,KOL_Database!$L$17=""),"",ROUND(KOL_Database!$L$17/KOL_Database!$J$17,3)) | BD17: =IF(OR(KOL_Database!$AP$17="",KOL_Database!$AP$17=0,Lookup_Lists!$D$149=0),"",MIN(100,ROUND(Lookup_Lists!$D$149/KOL_Database!$AP$17*100,0))) | BE17: =ROUND((IF(KOL_Database!$J$17="",0,1)+IF(KOL_Database!$K$17="",0,1)+IF(KOL_Database!$L$17="",0,1)+IF(KOL_Database!$M$17="",0,1)+IF(KOL_Database!$N$17="",0,1)+IF(KOL_Database!$O$17="",0,1)+IF(KOL_Database!$P$17="",0,1)+IF(KOL_Database!$R$17="",0,1)+IF(KOL_Database!$S$17="",0,1)+IF(KOL_Database!$AE$17="",0,1)+IF(KOL_Database!$AF$17="",0,1)+IF(KOL_Database!$AN$17="",0,1))/12*100,0) | BF17: =IF(KOL_Database!$BE$17>=Lookup_Lists!$D$159,"Live",IF(KOL_Database!$BE$17>=Lookup_Lists!$D$160,"Calculated","Estimated"))
A18: KOL-14 | B18: Zahra Amelia | C18: @zahrahijabstyle | D18: Instagram | E18: Fashion | F18: Hijab Fashion | G18: =IFERROR(INDEX(Lookup_Lists!$A$96:$A$100,MATCH(KOL_Database!$J$18,Lookup_Lists!$B$96:$B$100,1)),"") | H18: Yes | I18: Bandung | J18: 268000 | K18: 4.7 | L18: 60835 | M18: 38966 | N18: 4.7 | O18: 13.5 | P18: 93 | Q18: 92 | R18: 62 | S18: 68 | T18: 0.6 | U18: 0.98 | V18: 49 | W18: 9 | X18: 36 | Y18: 32 | Z18: 15 | AA18: 8 | AB18: 76 | AC18: 24 | AD18: Indonesia | AE18: Jawa Barat | AF18: Bandung | AG18: Fashion, Beauty, Shopping, Skincare, Travel | AH18: High | AI18: Fashion, Beauty, Shopping | AJ18: Aesthetic | AK18: Premium | AL18: Quality, Authenticity, Craftsmanship, Trust | AM18: 63 | AN18: 9178000 | AO18: =IF(OR(KOL_Database!$AN$18="",KOL_Database!$AN$18=0,KOL_Database!$L$18="",KOL_Database!$L$18=0),"",ROUND(KOL_Database!$AN$18/KOL_Database!$L$18,2)) | AP18: =IF(OR(KOL_Database!$AN$18="",KOL_Database!$AN$18=0,KOL_Database!$L$18="",KOL_Database!$L$18=0,KOL_Database!$K$18="",KOL_Database!$K$18=0),"",ROUND(KOL_Database!$AN$18/(KOL_Database!$L$18*KOL_Database!$K$18/100),0)) | AQ18: =IF(OR(KOL_Database!$AN$18="",KOL_Database!$AN$18=0,KOL_Database!$J$18="",KOL_Database!$J$18=0),"",ROUND(KOL_Database!$AN$18/KOL_Database!$J$18*1000,0)) | AR18: =IF(OR(KOL_Database!$L$18="",KOL_Database!$J$18=""),"",ROUND(KOL_Database!$L$18*Lookup_Lists!$D$147+KOL_Database!$J$18*Lookup_Lists!$D$148,0)) | AS18: =IF(OR(KOL_Database!$AN$18="",KOL_Database!$AN$18=0,KOL_Database!$AR$18=""),"",ROUND(KOL_Database!$AR$18*KOL_Database!$K$18/100*Lookup_Lists!$D$146/KOL_Database!$AN$18,2)) | AT18: 72 | AU18: 15 | AV18: Low | AW18: No | AX18: No | AY18: No | AZ18: No | BA18: 46091.708 | BB18: 46257.708 | BC18: =IF(OR(KOL_Database!$J$18="",KOL_Database!$J$18=0,KOL_Database!$L$18=""),"",ROUND(KOL_Database!$L$18/KOL_Database!$J$18,3)) | BD18: =IF(OR(KOL_Database!$AP$18="",KOL_Database!$AP$18=0,Lookup_Lists!$D$149=0),"",MIN(100,ROUND(Lookup_Lists!$D$149/KOL_Database!$AP$18*100,0))) | BE18: =ROUND((IF(KOL_Database!$J$18="",0,1)+IF(KOL_Database!$K$18="",0,1)+IF(KOL_Database!$L$18="",0,1)+IF(KOL_Database!$M$18="",0,1)+IF(KOL_Database!$N$18="",0,1)+IF(KOL_Database!$O$18="",0,1)+IF(KOL_Database!$P$18="",0,1)+IF(KOL_Database!$R$18="",0,1)+IF(KOL_Database!$S$18="",0,1)+IF(KOL_Database!$AE$18="",0,1)+IF(KOL_Database!$AF$18="",0,1)+IF(KOL_Database!$AN$18="",0,1))/12*100,0) | BF18: =IF(KOL_Database!$BE$18>=Lookup_Lists!$D$159,"Live",IF(KOL_Database!$BE$18>=Lookup_Lists!$D$160,"Calculated","Estimated"))
A19: KOL-15 | B19: Andini Rahma | C19: @andinidaily | D19: Instagram | E19: Lifestyle | F19: Daily Vlog | G19: =IFERROR(INDEX(Lookup_Lists!$A$96:$A$100,MATCH(KOL_Database!$J$19,Lookup_Lists!$B$96:$B$100,1)),"") | H19: No | I19: Jakarta | J19: 58000 | K19: 5.8 | L19: 19817 | N19: 0.8 | O19: 2.2 | P19: 54 | Q19: 49 | R19: 79 | S19: 75 | T19: 1.78 | U19: 2.87 | V19: 77 | W19: 6 | X19: 41 | Y19: 36 | Z19: 13 | AA19: 4 | AB19: 78 | AC19: 22 | AD19: Indonesia | AE19: DKI Jakarta | AF19: Jakarta | AG19: Shopping, Food, Beauty, Travel, Fashion | AH19: High | AI19: Shopping, Food, Beauty | AJ19: Vlog | AK19: Relatable | AL19: Authenticity, Fun, Community, Affordability | AM19: 81 | AO19: =IF(OR(KOL_Database!$AN$19="",KOL_Database!$AN$19=0,KOL_Database!$L$19="",KOL_Database!$L$19=0),"",ROUND(KOL_Database!$AN$19/KOL_Database!$L$19,2)) | AP19: =IF(OR(KOL_Database!$AN$19="",KOL_Database!$AN$19=0,KOL_Database!$L$19="",KOL_Database!$L$19=0,KOL_Database!$K$19="",KOL_Database!$K$19=0),"",ROUND(KOL_Database!$AN$19/(KOL_Database!$L$19*KOL_Database!$K$19/100),0)) | AQ19: =IF(OR(KOL_Database!$AN$19="",KOL_Database!$AN$19=0,KOL_Database!$J$19="",KOL_Database!$J$19=0),"",ROUND(KOL_Database!$AN$19/KOL_Database!$J$19*1000,0)) | AR19: =IF(OR(KOL_Database!$L$19="",KOL_Database!$J$19=""),"",ROUND(KOL_Database!$L$19*Lookup_Lists!$D$147+KOL_Database!$J$19*Lookup_Lists!$D$148,0)) | AS19: =IF(OR(KOL_Database!$AN$19="",KOL_Database!$AN$19=0,KOL_Database!$AR$19=""),"",ROUND(KOL_Database!$AR$19*KOL_Database!$K$19/100*Lookup_Lists!$D$146/KOL_Database!$AN$19,2)) | AT19: 87 | AU19: 47 | AV19: None | AW19: No | AX19: No | AY19: No | AZ19: No | BA19: 46192.708 | BB19: 46241.708 | BC19: =IF(OR(KOL_Database!$J$19="",KOL_Database!$J$19=0,KOL_Database!$L$19=""),"",ROUND(KOL_Database!$L$19/KOL_Database!$J$19,3)) | BD19: =IF(OR(KOL_Database!$AP$19="",KOL_Database!$AP$19=0,Lookup_Lists!$D$149=0),"",MIN(100,ROUND(Lookup_Lists!$D$149/KOL_Database!$AP$19*100,0))) | BE19: =ROUND((IF(KOL_Database!$J$19="",0,1)+IF(KOL_Database!$K$19="",0,1)+IF(KOL_Database!$L$19="",0,1)+IF(KOL_Database!$M$19="",0,1)+IF(KOL_Database!$N$19="",0,1)+IF(KOL_Database!$O$19="",0,1)+IF(KOL_Database!$P$19="",0,1)+IF(KOL_Database!$R$19="",0,1)+IF(KOL_Database!$S$19="",0,1)+IF(KOL_Database!$AE$19="",0,1)+IF(KOL_Database!$AF$19="",0,1)+IF(KOL_Database!$AN$19="",0,1))/12*100,0) | BF19: =IF(KOL_Database!$BE$19>=Lookup_Lists!$D$159,"Live",IF(KOL_Database!$BE$19>=Lookup_Lists!$D$160,"Calculated","Estimated"))
A20: KOL-16 | B20: Yoga Pratama | C20: @yogaminimal | D20: TikTok | E20: Lifestyle | F20: Self Improvement | G20: =IFERROR(INDEX(Lookup_Lists!$A$96:$A$100,MATCH(KOL_Database!$J$20,Lookup_Lists!$B$96:$B$100,1)),"") | H20: No | I20: Yogyakarta | J20: 143000 | K20: 7.3 | L20: 128922 | M20: 93520 | N20: 1.6 | O20: 4.7 | P20: 69 | Q20: 58 | R20: 72 | S20: 75 | T20: 1.11 | U20: 1.8 | V20: 65 | W20: 10 | X20: 35 | Y20: 32 | Z20: 15 | AA20: 8 | AB20: 50 | AC20: 50 | AD20: Indonesia | AE20: DI Yogyakarta | AF20: Yogyakarta | AG20: Productivity, Education, Finance, Technology, Health | AH20: Medium | AI20: Productivity, Education, Finance | AJ20: Storytelling | AK20: Inspirational | AL20: Empowerment, Authenticity, Trust, Health | AM20: 70 | AN20: 7434000 | AO20: =IF(OR(KOL_Database!$AN$20="",KOL_Database!$AN$20=0,KOL_Database!$L$20="",KOL_Database!$L$20=0),"",ROUND(KOL_Database!$AN$20/KOL_Database!$L$20,2)) | AP20: =IF(OR(KOL_Database!$AN$20="",KOL_Database!$AN$20=0,KOL_Database!$L$20="",KOL_Database!$L$20=0,KOL_Database!$K$20="",KOL_Database!$K$20=0),"",ROUND(KOL_Database!$AN$20/(KOL_Database!$L$20*KOL_Database!$K$20/100),0)) | AQ20: =IF(OR(KOL_Database!$AN$20="",KOL_Database!$AN$20=0,KOL_Database!$J$20="",KOL_Database!$J$20=0),"",ROUND(KOL_Database!$AN$20/KOL_Database!$J$20*1000,0)) | AR20: =IF(OR(KOL_Database!$L$20="",KOL_Database!$J$20=""),"",ROUND(KOL_Database!$L$20*Lookup_Lists!$D$147+KOL_Database!$J$20*Lookup_Lists!$D$148,0)) | AS20: =IF(OR(KOL_Database!$AN$20="",KOL_Database!$AN$20=0,KOL_Database!$AR$20=""),"",ROUND(KOL_Database!$AR$20*KOL_Database!$K$20/100*Lookup_Lists!$D$146/KOL_Database!$AN$20,2)) | AT20: 80 | AU20: 27 | AV20: Low | AW20: No | AX20: No | AY20: No | AZ20: No | BA20: 46208.708 | BB20: 46258.708 | BC20: =IF(OR(KOL_Database!$J$20="",KOL_Database!$J$20=0,KOL_Database!$L$20=""),"",ROUND(KOL_Database!$L$20/KOL_Database!$J$20,3)) | BD20: =IF(OR(KOL_Database!$AP$20="",KOL_Database!$AP$20=0,Lookup_Lists!$D$149=0),"",MIN(100,ROUND(Lookup_Lists!$D$149/KOL_Database!$AP$20*100,0))) | BE20: =ROUND((IF(KOL_Database!$J$20="",0,1)+IF(KOL_Database!$K$20="",0,1)+IF(KOL_Database!$L$20="",0,1)+IF(KOL_Database!$M$20="",0,1)+IF(KOL_Database!$N$20="",0,1)+IF(KOL_Database!$O$20="",0,1)+IF(KOL_Database!$P$20="",0,1)+IF(KOL_Database!$R$20="",0,1)+IF(KOL_Database!$S$20="",0,1)+IF(KOL_Database!$AE$20="",0,1)+IF(KOL_Database!$AF$20="",0,1)+IF(KOL_Database!$AN$20="",0,1))/12*100,0) | BF20: =IF(KOL_Database!$BE$20>=Lookup_Lists!$D$159,"Live",IF(KOL_Database!$BE$20>=Lookup_Lists!$D$160,"Calculated","Estimated"))
