Workbook

Sheet README
A1: AUTOMETRIC — BRAND MATCH DISTRIBUTION TEST
A2: 6991 creators read from the KOL server · three preference profiles · populations of 1243, 5115, 687 · Absolute and Normalized scores, six histograms.
A4: 1. WHAT THIS FILE IS FOR
A5: The question | B5: Not "who should this brand hire". It is: taking the Absolute Brand Match Score exactly as it stands, what shape does it take across a real population, and does dividing by the population maximum make it easier to read?
A6: What was NOT changed | B6: No weight, sub-weight, normalisation target, match-level band or relevance-matrix cell. The scores here are produced by scripts/brand-match/scoring.mjs, a JavaScript port of the workbook formulas that is gated by npm run brandmatch:port:verify — it recalculates the published 24x5 comparison workbook in Excel and asserts the port reproduces all 120 rows across 26 score columns exactly. 3.120 values, no tolerance.
A7: The one change that was made | B7: A bug, and the brief allows bug fixing. The emptiness guard on the keyword and topic haystacks tested LEN(TRIM(haystack))=0, but the haystack joins four fields with " | ", so a creator with none of them still produced " | | | " and the guard never fired — three creators with no bio and no captions were scoring 0 ("searched, found nothing") where the design says N/A ("nothing was searched"). The guard now strips the separators first. It affects 15 of the 120 rows in the comparison workbook and nothing else.
A8: 2. HOW TO READ THE TWO SCORES
A9: Absolute Score | B9: Answers "what value did the scoring formula produce". It is comparable across preferences and across time, and it is the number to look at when asking whether the model itself is working.
A10: Normalized Score | B10: Answers "how high does this creator sit compared with the others in the SAME comparison population". Normalized = Absolute ÷ MAX(Absolute in that population) × 100. The three divisors here are Preference A 80, Preference B 80, Preference C 67.
A11: What 100 does NOT mean | B11: A Normalized Score of 100 means "highest relative match within the current comparison population". It does not mean a 100% fit. In Preference A the top creator scores an Absolute 80 and a Normalized 100 — the same creator, the same evidence, two different questions. Both sheets ship for exactly this reason.
A12: 3. WHAT THE DATA SHOWS
A13: The distribution is compressed, and normalisation does not fix it | B13: Preference A (LumiSkin, N=1243) spans 25-80 but its middle half sits between 44 and 50 — 6 points of a 55-point range. Preference B (DailyBite, N=5115) spans 18-80 but its middle half sits between 41 and 50 — 9 points of a 62-point range. Preference C (NovaTech, N=687) spans 18-67 but its middle half sits between 36 and 48 — 12 points of a 49-point range. The absolute scores occupy a narrow band in the middle of the 0-100 scale, so almost every creator lands in Low Match against bands that assume a complete record.
A14: Normalisation is affine, so it cannot change shape | B14: Dividing every value by one constant is a linear rescale. It moves the maximum to 100 and stretches the axis, but skewness, the ordering, and the relative gaps are mathematically identical — which is why the Skewness column on Distribution_Summary reads the same for Absolute and Normalized in every one of the three preferences. Normalisation is a presentation layer. It makes a ranking easier to read; it cannot make a compressed score more discriminating.
A15: Why so many creators land on the same value | B15: Preference A: 33.7% of the population scores exactly 50 · Preference B: 45.0% of the population scores exactly 50 · Preference C: 10.0% of the population scores exactly 55. The reason is on the Population sheet: 55,8% of creators carry a category and almost nobody carries anything else, so for most of the population the model has only Category Match, verification and sometimes an engagement rate to work with. A discrete input produces a discrete score, and creators with no category at all take CAL_NEUTRAL = 50 on every category-driven sub-score at once.
A16: The ranking does change when the brand changes | B16: Across the 194 creators eligible under all three preferences, the median rank spread is 2409 places and the widest is 5082. 152 of them (78.4%) move by more than 10 percentiles between the best and worst preference for them. The score is behaving contextually: changing the brand reorders the population rather than only relabelling it.
A17: 4. SHEETS
A18: Sheet | B18: What it holds
A19: Population | B19: What was read, and the signal-coverage table that explains every distribution here.
A20: Preference_Profiles | B20: The three brands and their eligibility rules, with the database column behind each.
A21: Absolute_Scores | B21: The unchanged model, one block per preference.
A22: Normalized_Scores | B22: Absolute ÷ population max × 100, as live formulas, with the absolute beside it.
A23: Distribution_Summary | B23: N, Min, Max, Mean, Median, Std Dev, P25, P75, SKEW() and a tail reading per series.
A24: Histogram_Data | B24: Twenty five-point bins per series, as COUNTIFS. The six charts read from here.
A25: Histograms | B25: The six charts: Absolute and Normalized for each preference.
A26: Preference_Comparison | B26: Creators eligible under all three, with both scores and all three ranks.
A27: Validation | B27: The fifteen checks.
A28: 5. REGENERATING
A29: Commands | B29: npm run brandmatch:population (office VPN) · npm run brandmatch:port:verify (the gate) · npm run brandmatch:distribution

Sheet Population
A1: POPULATION · what was read off the KOL server, and how much of it can be scored
A2: 6991 active creators from public.kol_directory, measured 2026-09-10 06:25 UTC from 10.100.14.216/kol. No creator here was invented and no metric was filled in. The coverage table below is the single most important context for every distribution on the other sheets.
A4: A. SIGNAL COVERAGE · how many of the population carry each input the model reads
A5: Input | B5: Creators carrying it | C5: Share of population | D5: Which component it feeds | E5: Consequence when absent
A6: Followers | B6: 6991 | C6: =B6/6991 -> 1 | D6: Tier, and every eligibility rule | E6: —
A7: Canonical category (kol_categories.taxonomy_key) | B7: 3888 | C7: =B7/6991 -> 0.55614361 | D7: Brand & Business Relevance (60% of it) | E7: Category Match falls back to CAL_NEUTRAL = 50
A8: of those, live from kol_categories | B8: 3847 | C8: =B8/6991 -> 0.55027893 | D8: as above | E8: —
A9: Engagement rate | B9: 1728 | C9: =B9/6991 -> 0.24717494 | D9: Performance Quality (35% of it) | E9: ER Score N/A; Performance renormalises or drops out
A10: View-to-follower ratio | B10: 20 | C10: =B10/6991 -> 0.0028608211 | D10: Performance Quality (10% of it) | E10: Average Views Score N/A
A11: Audience analysis (quality / authenticity) | B11: 24 | C11: =B11/6991 -> 0.0034329853 | D11: Performance and Brand Safety | E11: Safety falls back to verification alone
A12: Audience interests | B12: 24 | C12: =B12/6991 -> 0.0034329853 | D12: Target Audience Relevance (30% of it) | E12: Interest Score N/A; whole component often N/A
A13: Harvested captions | B13: 50 | C13: =B13/6991 -> 0.0071520526 | D13: Content Relevance and Keyword Match | E13: Topic Match N/A; category cannot be classified
A14: Bio text | B14: 897 | C14: =B14/6991 -> 0.12830782 | D14: Keyword Match | E14: Keyword Match N/A unless a category name is present
A15: Platform-verified | B15: 559 | C15: =B15/6991 -> 0.079959949 | D15: Brand Safety (15% of it) | E15: scores CAL_VERIFIED_NO = 50, not 0
A17: B. THE THREE COMPARISON POPULATIONS · each preference filters the same reading
A18: Preference | B18: Brand | C18: Brand category | D18: Population size (N) | E18: Eligibility
A19: Preference A | B19: LumiSkin | C19: Beauty | D19: 1243 | E19: Platform: Instagram only · Minimum followers: 10.000 (Micro and above) · Category requirement: must carry at least one kol_categories row · Brand category: Beauty · Gender target: Female
A20: Preference B | B20: DailyBite | C20: Food | D20: 5115 | E20: Platform: Instagram and TikTok · Minimum followers: 10.000 (Micro and above) · Category requirement: none · Brand category: Food · Gender target: Balanced
A21: Preference C | B21: NovaTech | C21: Tech | D21: 687 | E21: Platform: Instagram and TikTok · Minimum followers: 100.000 (Macro and above) · Minimum engagement rate: must be measured (kol_directory.engagement_rate not null) · Brand category: Tech · Gender target: Balanced

Sheet Preference_Profiles
A1: PREFERENCE PROFILES · the three brand profiles under test
A2: Each is an existing brand from the comparison workbook — same canonical category, same keywords, same interest keys — paired with an eligibility rule that decides its comparison population. Every filter used is one the Discovery catalogue marks DONE; none gates on a column that is 0% filled.
A4: Preference A · LumiSkin · category Beauty · N = 1243
A5: Why this profile | B5: A beauty brand buying on Instagram. Beauty is the second-largest category on the server (1.206 creators), so this preference has a deep pool of on-category creators and a female-audience target that most of the roster can be measured against.
A6: Criterion | B6: Value | C6: Source in the database | D6: Kind
A7: Platform | B7: Instagram only | C7: kol_directory.platform_id → platforms.key | D7: HARD FILTER
A8: Minimum followers | B8: 10.000 (Micro and above) | C8: kol_directory.followers_count | D8: HARD FILTER
A9: Category requirement | B9: must carry at least one kol_categories row | C9: kol_directory.category_ids → kol_categories | D9: HARD FILTER
A10: Brand category | B10: Beauty | C10: public.kol_categories.taxonomy_key | D10: SOFT MATCH — scored, never gated
A11: Gender target | B11: Female | C11: audience_demographics_daily / feature.*_audience_analysis.female_pct | D11: SOFT MATCH
A12: Brand keywords | B12: skincare, perawatan kulit, kecantikan, glowing, serum, sunscreen | C12: public.brand.brand_keywords
A13: Audience interests | B13: beauty, fashion, entertainment | C13: l2_gold.audience_interest_daily.interest_key
A16: Preference B · DailyBite · category Food · N = 5115
A17: Why this profile | B17: A mass-market F&B brand with the broadest possible reach: both platforms, no category requirement. This is the largest of the three populations and the one most exposed to creators the database knows almost nothing about, which is exactly what makes it worth measuring.
A18: Criterion | B18: Value | C18: Source in the database | D18: Kind
A19: Platform | B19: Instagram and TikTok | C19: kol_directory.platform_id → platforms.key | D19: HARD FILTER
A20: Minimum followers | B20: 10.000 (Micro and above) | C20: kol_directory.followers_count | D20: HARD FILTER
A21: Category requirement | B21: none | C21: kol_directory.category_ids → kol_categories | D21: HARD FILTER
A22: Brand category | B22: Food | C22: public.kol_categories.taxonomy_key | D22: SOFT MATCH — scored, never gated
A23: Gender target | B23: Balanced | C23: audience_demographics_daily / feature.*_audience_analysis.female_pct | D23: SOFT MATCH
A24: Brand keywords | B24: makanan, minuman, kuliner, resto, cafe, jajan | C24: public.brand.brand_keywords
A25: Audience interests | B25: food, entertainment, parenting, travel | C25: l2_gold.audience_interest_daily.interest_key
A28: Preference C · NovaTech · category Tech · N = 687
A29: Why this profile | B29: A B2B software brand buying large accounts with measured engagement. Tech is the SMALLEST canonical category on the server — 4 creators carry it — so this preference tests what the model does when almost nobody in the population is on-category, and the engagement-rate gate makes it the only one of the three where every creator has a Performance Score.
A30: Criterion | B30: Value | C30: Source in the database | D30: Kind
A31: Platform | B31: Instagram and TikTok | C31: kol_directory.platform_id → platforms.key | D31: HARD FILTER
A32: Minimum followers | B32: 100.000 (Macro and above) | C32: kol_directory.followers_count | D32: HARD FILTER
A33: Minimum engagement rate | B33: must be measured (kol_directory.engagement_rate not null) | C33: kol_directory.engagement_rate | D33: HARD FILTER
A34: Brand category | B34: Tech | C34: public.kol_categories.taxonomy_key | D34: SOFT MATCH — scored, never gated
A35: Gender target | B35: Balanced | C35: audience_demographics_daily / feature.*_audience_analysis.female_pct | D35: SOFT MATCH
A36: Brand keywords | B36: teknologi, software, aplikasi, produktivitas, bisnis, digital | C36: public.brand.brand_keywords
A37: Audience interests | B37: technology, business, education, gaming | C37: l2_gold.audience_interest_daily.interest_key

Sheet Absolute_Scores
A1: ABSOLUTE SCORES · the model exactly as it stands, one block per preference
A2: Every value is the Final Match Score produced by the unchanged model. Blocks are side by side rather than stacked so each preference keeps its own contiguous range — which is what lets Distribution_Summary and Histogram_Data be live formulas over a population instead of pasted numbers.
A4: Preference A · LumiSkin (Beauty) · N=1243 | F4: Preference B · DailyBite (Food) · N=5115 | K4: Preference C · NovaTech (Tech) · N=687
A5: KOL | B5: Platform | C5: Followers | D5: Absolute Score | F5: KOL | G5: Platform | H5: Followers | I5: Absolute Score | K5: KOL | L5: Platform | M5: Followers | N5: Absolute Score
A6: @almamestika | B6: Instagram | C6: 165218 | D6: 80 | F6: @nanakoot | G6: TikTok | H6: 9900000 | I6: 80 | K6: @alyaaputri | L6: Instagram | M6: 236164 | N6: 67
A7: @desylasterina | B7: Instagram | C7: 80404 | D7: 72 | F7: @inul.d | G7: Instagram | H7: 20046665 | I7: 69 | K7: @hipatrickreal | L7: Instagram | M7: 116769 | N7: 67
A8: @regina_nugroho | B8: Instagram | C8: 91319 | D8: 69 | F8: @cheekykiddo | G8: TikTok | H8: 5600000 | I8: 68 | K8: @nfahdan | L8: Instagram | M8: 143915 | N8: 67
A9: @__ditamal | B9: Instagram | C9: 122110 | D9: 67 | F9: @dairyqueen | G9: TikTok | H9: 307567 | I9: 68 | K9: @suryainsomnia | L9: Instagram | M9: 2137780 | N9: 62
A10: @angelaaudreyyy | B10: Instagram | C10: 102609 | D10: 67 | F10: @dimsthemeatguy | G10: TikTok | H10: 6600000 | I10: 68 | K10: @indahnadapuspita | L10: Instagram | M10: 1132901 | N10: 61
A11: @carlenedoraa | B11: Instagram | C11: 98222 | D11: 67 | F11: @mursid241 | G11: TikTok | H11: 6685227 | I11: 68 | K11: @anggikabolsterli | L11: Instagram | M11: 805581 | N11: 59
A12: @cindercella | B12: Instagram | C12: 740575 | D12: 67 | F12: @ainiraaul | G12: Instagram | H12: 193274 | I12: 67 | K12: @bobbykertanegara | L12: Instagram | M12: 948683 | N12: 59
A13: @lindakayhz | B13: Instagram | C13: 324971 | D13: 67 | F13: @alyaaputri | G13: Instagram | H13: 236164 | I13: 67 | K13: @kayleemiracle | L13: Instagram | M13: 343960 | N13: 59
A14: @raniaayamin | B14: Instagram | C14: 429570 | D14: 67 | F14: @hipatrickreal | G14: Instagram | H14: 116769 | I14: 67 | K14: @laura_theux | L14: Instagram | M14: 794018 | N14: 59
A15: @theliztagram | B15: Instagram | C15: 299227 | D15: 67 | F15: @kokikutv | G15: Instagram | H15: 729181 | I15: 67 | K15: @ia_nita_lohiya | L15: Instagram | M15: 209819 | N15: 56
A16: @vaniafebrianne | B16: Instagram | C16: 121140 | D16: 67 | F16: @nfahdan | G16: Instagram | H16: 143915 | I16: 67 | K16: @karmalogy | L16: TikTok | M16: 2100000 | N16: 56
A17: @yorikooangln_ | B17: Instagram | C17: 2011129 | D17: 67 | F17: @aira_mishel_aurellia | G17: Instagram | H17: 102895 | I17: 64 | K17: @__ehan | L17: TikTok | M17: 4900000 | N17: 55
... A692: @fenny_fennyyy | B692: Instagram | C692: 106722 | D692: 45 | F692: @bidarakirana | G692: TikTok | H692: 11100 | I692: 50 | K692: @rrghufrona | L692: Instagram | M692: 101429 | N692: 18
A693: @hairnerdsstudio | B693: Instagram | C693: 312384 | D693: 45 | F693: @biiittaa | G693: TikTok | H693: 10800 | I693: 50
A694: @mursyidzon | B694: Instagram | C694: 983917 | D694: 45 | F694: @bil.lasyabilla | G694: Instagram | H694: 21243 | I694: 50
A695: @nsf_82 | B695: Instagram | C695: 55947 | D695: 45 | F695: @bilalfadh | G695: TikTok | H695: 367400 | I695: 50
A696: @onyahero | B696: Instagram | C696: 225500 | D696: 45 | F696: @bilbawazier | G696: TikTok | H696: 23600 | I696: 50
A697: @putrypurwantika | B697: Instagram | C697: 211019 | D697: 45 | F697: @billaazz | G697: TikTok | H697: 1500000 | I697: 50
A698: @susijournal1509 | B698: Instagram | C698: 267982 | D698: 45 | F698: @binar_tika | G698: TikTok | H698: 70100 | I698: 50
A699: @theopasaribu_ | B699: Instagram | C699: 208540 | D699: 45 | F699: @bintangmaretta | G699: Instagram | H699: 10663 | I699: 50
A700: @uchiruhendi | B700: Instagram | C700: 97713 | D700: 45 | F700: @bitcj4lyf | G700: TikTok | H700: 95500 | I700: 50
A701: @_ameliatriani | B701: Instagram | C701: 14768 | D701: 44 | F701: @bitpply | G701: TikTok | H701: 107400 | I701: 50
A702: @_ifa.sl | B702: Instagram | C702: 10594 | D702: 44 | F702: @bixxy.chan | G702: Instagram | H702: 23077 | I702: 50
A703: @20.atim | B703: Instagram | C703: 13640 | D703: 44 | F703: @bizzlexo | G703: TikTok | H703: 314300 | I703: 50
A704: @a.nasrahma | B704: Instagram | C704: 31349 | D704: 44 | F704: @bloginnara | G704: TikTok | H704: 31200 | I704: 50
... A1248: @siresepbunda | B1248: Instagram | C1248: 907809 | D1248: 25 | F1248: @hufianafl | G1248: Instagram | H1248: 15077 | I1248: 50
F1249: @humairatushafa | G1249: TikTok | H1249: 10100 | I1249: 50
F1250: @humdyzyd | G1250: TikTok | H1250: 17400 | I1250: 50
F1251: @huningprastiwi | G1251: TikTok | H1251: 20200 | I1251: 50
F1252: @hxneybz | G1252: TikTok | H1252: 19800 | I1252: 50
F1253: @hyeiwn | G1253: TikTok | H1253: 91800 | I1253: 50
F1254: @hyemhyemla | G1254: TikTok | H1254: 21500 | I1254: 50
F1255: @hyly.angie | G1255: TikTok | H1255: 1100000 | I1255: 50
F1256: @hypee.boyy | G1256: TikTok | H1256: 26600 | I1256: 50
F1257: @hythyrr | G1257: TikTok | H1257: 306100 | I1257: 50
F1258: @iaamsyn | G1258: TikTok | H1258: 13900 | I1258: 50
...

Sheet Normalized_Scores
A1: NORMALIZED SCORES · Absolute ÷ population maximum × 100
A2: Every cell is a formula over Absolute_Scores, and the divisor is the MAX of THAT preference's own population — never a global maximum across the database. 100 therefore means "the highest relative match inside this comparison group", and it does NOT mean a perfect or 100% fit. The absolute score it came from is one sheet to the left.
A4: Preference A · LumiSkin · population maximum = | D4: =MAX(Absolute_Scores!$D$6:$D$1248) -> 80 | F4: Preference B · DailyBite · population maximum = | I4: =MAX(Absolute_Scores!$I$6:$I$5120) -> 80 | K4: Preference C · NovaTech · population maximum = | N4: =MAX(Absolute_Scores!$N$6:$N$692) -> 67
A5: KOL | B5: Platform | C5: Absolute Score | D5: Normalized Score | F5: KOL | G5: Platform | H5: Absolute Score | I5: Normalized Score | K5: KOL | L5: Platform | M5: Absolute Score | N5: Normalized Score
A6: =Absolute_Scores!A6 -> @almamestika | B6: =Absolute_Scores!B6 -> Instagram | C6: =Absolute_Scores!D6 -> 80 | D6: =ROUND(C6/$D$4*100,2) -> 100 | F6: =Absolute_Scores!F6 -> @nanakoot | G6: =Absolute_Scores!G6 -> TikTok | H6: =Absolute_Scores!I6 -> 80 | I6: =ROUND(H6/$I$4*100,2) -> 100 | K6: =Absolute_Scores!K6 -> @alyaaputri | L6: =Absolute_Scores!L6 -> Instagram | M6: =Absolute_Scores!N6 -> 67 | N6: =ROUND(M6/$N$4*100,2) -> 100
A7: =Absolute_Scores!A7 -> @desylasterina | B7: =Absolute_Scores!B7 -> Instagram | C7: =Absolute_Scores!D7 -> 72 | D7: =ROUND(C7/$D$4*100,2) -> 90 | F7: =Absolute_Scores!F7 -> @inul.d | G7: =Absolute_Scores!G7 -> Instagram | H7: =Absolute_Scores!I7 -> 69 | I7: =ROUND(H7/$I$4*100,2) -> 86.25 | K7: =Absolute_Scores!K7 -> @hipatrickreal | L7: =Absolute_Scores!L7 -> Instagram | M7: =Absolute_Scores!N7 -> 67 | N7: =ROUND(M7/$N$4*100,2) -> 100
A8: =Absolute_Scores!A8 -> @regina_nugroho | B8: =Absolute_Scores!B8 -> Instagram | C8: =Absolute_Scores!D8 -> 69 | D8: =ROUND(C8/$D$4*100,2) -> 86.25 | F8: =Absolute_Scores!F8 -> @cheekykiddo | G8: =Absolute_Scores!G8 -> TikTok | H8: =Absolute_Scores!I8 -> 68 | I8: =ROUND(H8/$I$4*100,2) -> 85 | K8: =Absolute_Scores!K8 -> @nfahdan | L8: =Absolute_Scores!L8 -> Instagram | M8: =Absolute_Scores!N8 -> 67 | N8: =ROUND(M8/$N$4*100,2) -> 100
A9: =Absolute_Scores!A9 -> @__ditamal | B9: =Absolute_Scores!B9 -> Instagram | C9: =Absolute_Scores!D9 -> 67 | D9: =ROUND(C9/$D$4*100,2) -> 83.75 | F9: =Absolute_Scores!F9 -> @dairyqueen | G9: =Absolute_Scores!G9 -> TikTok | H9: =Absolute_Scores!I9 -> 68 | I9: =ROUND(H9/$I$4*100,2) -> 85 | K9: =Absolute_Scores!K9 -> @suryainsomnia | L9: =Absolute_Scores!L9 -> Instagram | M9: =Absolute_Scores!N9 -> 62 | N9: =ROUND(M9/$N$4*100,2) -> 92.54
A10: =Absolute_Scores!A10 -> @angelaaudreyyy | B10: =Absolute_Scores!B10 -> Instagram | C10: =Absolute_Scores!D10 -> 67 | D10: =ROUND(C10/$D$4*100,2) -> 83.75 | F10: =Absolute_Scores!F10 -> @dimsthemeatguy | G10: =Absolute_Scores!G10 -> TikTok | H10: =Absolute_Scores!I10 -> 68 | I10: =ROUND(H10/$I$4*100,2) -> 85 | K10: =Absolute_Scores!K10 -> @indahnadapuspita | L10: =Absolute_Scores!L10 -> Instagram | M10: =Absolute_Scores!N10 -> 61 | N10: =ROUND(M10/$N$4*100,2) -> 91.04
A11: =Absolute_Scores!A11 -> @carlenedoraa | B11: =Absolute_Scores!B11 -> Instagram | C11: =Absolute_Scores!D11 -> 67 | D11: =ROUND(C11/$D$4*100,2) -> 83.75 | F11: =Absolute_Scores!F11 -> @mursid241 | G11: =Absolute_Scores!G11 -> TikTok | H11: =Absolute_Scores!I11 -> 68 | I11: =ROUND(H11/$I$4*100,2) -> 85 | K11: =Absolute_Scores!K11 -> @anggikabolsterli | L11: =Absolute_Scores!L11 -> Instagram | M11: =Absolute_Scores!N11 -> 59 | N11: =ROUND(M11/$N$4*100,2) -> 88.06
A12: =Absolute_Scores!A12 -> @cindercella | B12: =Absolute_Scores!B12 -> Instagram | C12: =Absolute_Scores!D12 -> 67 | D12: =ROUND(C12/$D$4*100,2) -> 83.75 | F12: =Absolute_Scores!F12 -> @ainiraaul | G12: =Absolute_Scores!G12 -> Instagram | H12: =Absolute_Scores!I12 -> 67 | I12: =ROUND(H12/$I$4*100,2) -> 83.75 | K12: =Absolute_Scores!K12 -> @bobbykertanegara | L12: =Absolute_Scores!L12 -> Instagram | M12: =Absolute_Scores!N12 -> 59 | N12: =ROUND(M12/$N$4*100,2) -> 88.06
A13: =Absolute_Scores!A13 -> @lindakayhz | B13: =Absolute_Scores!B13 -> Instagram | C13: =Absolute_Scores!D13 -> 67 | D13: =ROUND(C13/$D$4*100,2) -> 83.75 | F13: =Absolute_Scores!F13 -> @alyaaputri | G13: =Absolute_Scores!G13 -> Instagram | H13: =Absolute_Scores!I13 -> 67 | I13: =ROUND(H13/$I$4*100,2) -> 83.75 | K13: =Absolute_Scores!K13 -> @kayleemiracle | L13: =Absolute_Scores!L13 -> Instagram | M13: =Absolute_Scores!N13 -> 59 | N13: =ROUND(M13/$N$4*100,2) -> 88.06
A14: =Absolute_Scores!A14 -> @raniaayamin | B14: =Absolute_Scores!B14 -> Instagram | C14: =Absolute_Scores!D14 -> 67 | D14: =ROUND(C14/$D$4*100,2) -> 83.75 | F14: =Absolute_Scores!F14 -> @hipatrickreal | G14: =Absolute_Scores!G14 -> Instagram | H14: =Absolute_Scores!I14 -> 67 | I14: =ROUND(H14/$I$4*100,2) -> 83.75 | K14: =Absolute_Scores!K14 -> @laura_theux | L14: =Absolute_Scores!L14 -> Instagram | M14: =Absolute_Scores!N14 -> 59 | N14: =ROUND(M14/$N$4*100,2) -> 88.06
A15: =Absolute_Scores!A15 -> @theliztagram | B15: =Absolute_Scores!B15 -> Instagram | C15: =Absolute_Scores!D15 -> 67 | D15: =ROUND(C15/$D$4*100,2) -> 83.75 | F15: =Absolute_Scores!F15 -> @kokikutv | G15: =Absolute_Scores!G15 -> Instagram | H15: =Absolute_Scores!I15 -> 67 | I15: =ROUND(H15/$I$4*100,2) -> 83.75 | K15: =Absolute_Scores!K15 -> @ia_nita_lohiya | L15: =Absolute_Scores!L15 -> Instagram | M15: =Absolute_Scores!N15 -> 56 | N15: =ROUND(M15/$N$4*100,2) -> 83.58
A16: =Absolute_Scores!A16 -> @vaniafebrianne | B16: =Absolute_Scores!B16 -> Instagram | C16: =Absolute_Scores!D16 -> 67 | D16: =ROUND(C16/$D$4*100,2) -> 83.75 | F16: =Absolute_Scores!F16 -> @nfahdan | G16: =Absolute_Scores!G16 -> Instagram | H16: =Absolute_Scores!I16 -> 67 | I16: =ROUND(H16/$I$4*100,2) -> 83.75 | K16: =Absolute_Scores!K16 -> @karmalogy | L16: =Absolute_Scores!L16 -> TikTok | M16: =Absolute_Scores!N16 -> 56 | N16: =ROUND(M16/$N$4*100,2) -> 83.58
A17: =Absolute_Scores!A17 -> @yorikooangln_ | B17: =Absolute_Scores!B17 -> Instagram | C17: =Absolute_Scores!D17 -> 67 | D17: =ROUND(C17/$D$4*100,2) -> 83.75 | F17: =Absolute_Scores!F17 -> @aira_mishel_aurellia | G17: =Absolute_Scores!G17 -> Instagram | H17: =Absolute_Scores!I17 -> 64 | I17: =ROUND(H17/$I$4*100,2) -> 80 | K17: =Absolute_Scores!K17 -> @__ehan | L17: =Absolute_Scores!L17 -> TikTok | M17: =Absolute_Scores!N17 -> 55 | N17: =ROUND(M17/$N$4*100,2) -> 82.09
... A692: =Absolute_Scores!A692 -> @fenny_fennyyy | B692: =Absolute_Scores!B692 -> Instagram | C692: =Absolute_Scores!D692 -> 45 | D692: =ROUND(C692/$D$4*100,2) -> 56.25 | F692: =Absolute_Scores!F692 -> @bidarakirana | G692: =Absolute_Scores!G692 -> TikTok | H692: =Absolute_Scores!I692 -> 50 | I692: =ROUND(H692/$I$4*100,2) -> 62.5 | K692: =Absolute_Scores!K692 -> @rrghufrona | L692: =Absolute_Scores!L692 -> Instagram | M692: =Absolute_Scores!N692 -> 18 | N692: =ROUND(M692/$N$4*100,2) -> 26.87
A693: =Absolute_Scores!A693 -> @hairnerdsstudio | B693: =Absolute_Scores!B693 -> Instagram | C693: =Absolute_Scores!D693 -> 45 | D693: =ROUND(C693/$D$4*100,2) -> 56.25 | F693: =Absolute_Scores!F693 -> @biiittaa | G693: =Absolute_Scores!G693 -> TikTok | H693: =Absolute_Scores!I693 -> 50 | I693: =ROUND(H693/$I$4*100,2) -> 62.5
A694: =Absolute_Scores!A694 -> @mursyidzon | B694: =Absolute_Scores!B694 -> Instagram | C694: =Absolute_Scores!D694 -> 45 | D694: =ROUND(C694/$D$4*100,2) -> 56.25 | F694: =Absolute_Scores!F694 -> @bil.lasyabilla | G694: =Absolute_Scores!G694 -> Instagram | H694: =Absolute_Scores!I694 -> 50 | I694: =ROUND(H694/$I$4*100,2) -> 62.5
A695: =Absolute_Scores!A695 -> @nsf_82 | B695: =Absolute_Scores!B695 -> Instagram | C695: =Absolute_Scores!D695 -> 45 | D695: =ROUND(C695/$D$4*100,2) -> 56.25 | F695: =Absolute_Scores!F695 -> @bilalfadh | G695: =Absolute_Scores!G695 -> TikTok | H695: =Absolute_Scores!I695 -> 50 | I695: =ROUND(H695/$I$4*100,2) -> 62.5
A696: =Absolute_Scores!A696 -> @onyahero | B696: =Absolute_Scores!B696 -> Instagram | C696: =Absolute_Scores!D696 -> 45 | D696: =ROUND(C696/$D$4*100,2) -> 56.25 | F696: =Absolute_Scores!F696 -> @bilbawazier | G696: =Absolute_Scores!G696 -> TikTok | H696: =Absolute_Scores!I696 -> 50 | I696: =ROUND(H696/$I$4*100,2) -> 62.5
A697: =Absolute_Scores!A697 -> @putrypurwantika | B697: =Absolute_Scores!B697 -> Instagram | C697: =Absolute_Scores!D697 -> 45 | D697: =ROUND(C697/$D$4*100,2) -> 56.25 | F697: =Absolute_Scores!F697 -> @billaazz | G697: =Absolute_Scores!G697 -> TikTok | H697: =Absolute_Scores!I697 -> 50 | I697: =ROUND(H697/$I$4*100,2) -> 62.5
A698: =Absolute_Scores!A698 -> @susijournal1509 | B698: =Absolute_Scores!B698 -> Instagram | C698: =Absolute_Scores!D698 -> 45 | D698: =ROUND(C698/$D$4*100,2) -> 56.25 | F698: =Absolute_Scores!F698 -> @binar_tika | G698: =Absolute_Scores!G698 -> TikTok | H698: =Absolute_Scores!I698 -> 50 | I698: =ROUND(H698/$I$4*100,2) -> 62.5
A699: =Absolute_Scores!A699 -> @theopasaribu_ | B699: =Absolute_Scores!B699 -> Instagram | C699: =Absolute_Scores!D699 -> 45 | D699: =ROUND(C699/$D$4*100,2) -> 56.25 | F699: =Absolute_Scores!F699 -> @bintangmaretta | G699: =Absolute_Scores!G699 -> Instagram | H699: =Absolute_Scores!I699 -> 50 | I699: =ROUND(H699/$I$4*100,2) -> 62.5
A700: =Absolute_Scores!A700 -> @uchiruhendi | B700: =Absolute_Scores!B700 -> Instagram | C700: =Absolute_Scores!D700 -> 45 | D700: =ROUND(C700/$D$4*100,2) -> 56.25 | F700: =Absolute_Scores!F700 -> @bitcj4lyf | G700: =Absolute_Scores!G700 -> TikTok | H700: =Absolute_Scores!I700 -> 50 | I700: =ROUND(H700/$I$4*100,2) -> 62.5
A701: =Absolute_Scores!A701 -> @_ameliatriani | B701: =Absolute_Scores!B701 -> Instagram | C701: =Absolute_Scores!D701 -> 44 | D701: =ROUND(C701/$D$4*100,2) -> 55 | F701: =Absolute_Scores!F701 -> @bitpply | G701: =Absolute_Scores!G701 -> TikTok | H701: =Absolute_Scores!I701 -> 50 | I701: =ROUND(H701/$I$4*100,2) -> 62.5
A702: =Absolute_Scores!A702 -> @_ifa.sl | B702: =Absolute_Scores!B702 -> Instagram | C702: =Absolute_Scores!D702 -> 44 | D702: =ROUND(C702/$D$4*100,2) -> 55 | F702: =Absolute_Scores!F702 -> @bixxy.chan | G702: =Absolute_Scores!G702 -> Instagram | H702: =Absolute_Scores!I702 -> 50 | I702: =ROUND(H702/$I$4*100,2) -> 62.5
A703: =Absolute_Scores!A703 -> @20.atim | B703: =Absolute_Scores!B703 -> Instagram | C703: =Absolute_Scores!D703 -> 44 | D703: =ROUND(C703/$D$4*100,2) -> 55 | F703: =Absolute_Scores!F703 -> @bizzlexo | G703: =Absolute_Scores!G703 -> TikTok | H703: =Absolute_Scores!I703 -> 50 | I703: =ROUND(H703/$I$4*100,2) -> 62.5
A704: =Absolute_Scores!A704 -> @a.nasrahma | B704: =Absolute_Scores!B704 -> Instagram | C704: =Absolute_Scores!D704 -> 44 | D704: =ROUND(C704/$D$4*100,2) -> 55 | F704: =Absolute_Scores!F704 -> @bloginnara | G704: =Absolute_Scores!G704 -> TikTok | H704: =Absolute_Scores!I704 -> 50 | I704: =ROUND(H704/$I$4*100,2) -> 62.5
... A1248: =Absolute_Scores!A1248 -> @siresepbunda | B1248: =Absolute_Scores!B1248 -> Instagram | C1248: =Absolute_Scores!D1248 -> 25 | D1248: =ROUND(C1248/$D$4*100,2) -> 31.25 | F1248: =Absolute_Scores!F1248 -> @hufianafl | G1248: =Absolute_Scores!G1248 -> Instagram | H1248: =Absolute_Scores!I1248 -> 50 | I1248: =ROUND(H1248/$I$4*100,2) -> 62.5
F1249: =Absolute_Scores!F1249 -> @humairatushafa | G1249: =Absolute_Scores!G1249 -> TikTok | H1249: =Absolute_Scores!I1249 -> 50 | I1249: =ROUND(H1249/$I$4*100,2) -> 62.5
F1250: =Absolute_Scores!F1250 -> @humdyzyd | G1250: =Absolute_Scores!G1250 -> TikTok | H1250: =Absolute_Scores!I1250 -> 50 | I1250: =ROUND(H1250/$I$4*100,2) -> 62.5
F1251: =Absolute_Scores!F1251 -> @huningprastiwi | G1251: =Absolute_Scores!G1251 -> TikTok | H1251: =Absolute_Scores!I1251 -> 50 | I1251: =ROUND(H1251/$I$4*100,2) -> 62.5
F1252: =Absolute_Scores!F1252 -> @hxneybz | G1252: =Absolute_Scores!G1252 -> TikTok | H1252: =Absolute_Scores!I1252 -> 50 | I1252: =ROUND(H1252/$I$4*100,2) -> 62.5
F1253: =Absolute_Scores!F1253 -> @hyeiwn | G1253: =Absolute_Scores!G1253 -> TikTok | H1253: =Absolute_Scores!I1253 -> 50 | I1253: =ROUND(H1253/$I$4*100,2) -> 62.5
F1254: =Absolute_Scores!F1254 -> @hyemhyemla | G1254: =Absolute_Scores!G1254 -> TikTok | H1254: =Absolute_Scores!I1254 -> 50 | I1254: =ROUND(H1254/$I$4*100,2) -> 62.5
F1255: =Absolute_Scores!F1255 -> @hyly.angie | G1255: =Absolute_Scores!G1255 -> TikTok | H1255: =Absolute_Scores!I1255 -> 50 | I1255: =ROUND(H1255/$I$4*100,2) -> 62.5
F1256: =Absolute_Scores!F1256 -> @hypee.boyy | G1256: =Absolute_Scores!G1256 -> TikTok | H1256: =Absolute_Scores!I1256 -> 50 | I1256: =ROUND(H1256/$I$4*100,2) -> 62.5
F1257: =Absolute_Scores!F1257 -> @hythyrr | G1257: =Absolute_Scores!G1257 -> TikTok | H1257: =Absolute_Scores!I1257 -> 50 | I1257: =ROUND(H1257/$I$4*100,2) -> 62.5
F1258: =Absolute_Scores!F1258 -> @iaamsyn | G1258: =Absolute_Scores!G1258 -> TikTok | H1258: =Absolute_Scores!I1258 -> 50 | I1258: =ROUND(H1258/$I$4*100,2) -> 62.5
...

Sheet Distribution_Summary
A1: DISTRIBUTION SUMMARY · every statistic computed by Excel over the score ranges
A2: Nothing on this sheet is a pasted number. Each cell is a formula over the corresponding column of Absolute_Scores or Normalized_Scores, so the statistics cannot drift from the data and SKEW() is Excel's own.
A4: Preference | B4: Brand | C4: Score Type | D4: N | E4: Min | F4: Max | G4: Mean | H4: Median | I4: Std Dev | J4: P25 | K4: P75
A5: Preference A | B5: LumiSkin | C5: Absolute | D5: =COUNT(Absolute_Scores!$D$6:$D$1248) -> 1243 | E5: =MIN(Absolute_Scores!$D$6:$D$1248) -> 25 | F5: =MAX(Absolute_Scores!$D$6:$D$1248) -> 80 | G5: =AVERAGE(Absolute_Scores!$D$6:$D$1248) -> 47.185036 | H5: =MEDIAN(Absolute_Scores!$D$6:$D$1248) -> 50 | I5: =_xlfn.STDEV.S(Absolute_Scores!$D$6:$D$1248) -> 6.7542223 | J5: =_xlfn.PERCENTILE.INC(Absolute_Scores!$D$6:$D$1248,0.25) -> 44 | K5: =_xlfn.PERCENTILE.INC(Absolute_Scores!$D$6:$D$1248,0.75) -> 50
A6: Preference A | B6: LumiSkin | C6: Normalized | D6: =COUNT(Normalized_Scores!$D$6:$D$1248) -> 1243 | E6: =MIN(Normalized_Scores!$D$6:$D$1248) -> 31.25 | F6: =MAX(Normalized_Scores!$D$6:$D$1248) -> 100 | G6: =AVERAGE(Normalized_Scores!$D$6:$D$1248) -> 58.981295 | H6: =MEDIAN(Normalized_Scores!$D$6:$D$1248) -> 62.5 | I6: =_xlfn.STDEV.S(Normalized_Scores!$D$6:$D$1248) -> 8.4427778 | J6: =_xlfn.PERCENTILE.INC(Normalized_Scores!$D$6:$D$1248,0.25) -> 55 | K6: =_xlfn.PERCENTILE.INC(Normalized_Scores!$D$6:$D$1248,0.75) -> 62.5
A7: Preference B | B7: DailyBite | C7: Absolute | D7: =COUNT(Absolute_Scores!$I$6:$I$5120) -> 5115 | E7: =MIN(Absolute_Scores!$I$6:$I$5120) -> 18 | F7: =MAX(Absolute_Scores!$I$6:$I$5120) -> 80 | G7: =AVERAGE(Absolute_Scores!$I$6:$I$5120) -> 45.812903 | H7: =MEDIAN(Absolute_Scores!$I$6:$I$5120) -> 50 | I7: =_xlfn.STDEV.S(Absolute_Scores!$I$6:$I$5120) -> 6.3847128 | J7: =_xlfn.PERCENTILE.INC(Absolute_Scores!$I$6:$I$5120,0.25) -> 41 | K7: =_xlfn.PERCENTILE.INC(Absolute_Scores!$I$6:$I$5120,0.75) -> 50
A8: Preference B | B8: DailyBite | C8: Normalized | D8: =COUNT(Normalized_Scores!$I$6:$I$5120) -> 5115 | E8: =MIN(Normalized_Scores!$I$6:$I$5120) -> 22.5 | F8: =MAX(Normalized_Scores!$I$6:$I$5120) -> 100 | G8: =AVERAGE(Normalized_Scores!$I$6:$I$5120) -> 57.266129 | H8: =MEDIAN(Normalized_Scores!$I$6:$I$5120) -> 62.5 | I8: =_xlfn.STDEV.S(Normalized_Scores!$I$6:$I$5120) -> 7.980891 | J8: =_xlfn.PERCENTILE.INC(Normalized_Scores!$I$6:$I$5120,0.25) -> 51.25 | K8: =_xlfn.PERCENTILE.INC(Normalized_Scores!$I$6:$I$5120,0.75) -> 62.5
A9: Preference C | B9: NovaTech | C9: Absolute | D9: =COUNT(Absolute_Scores!$N$6:$N$692) -> 687 | E9: =MIN(Absolute_Scores!$N$6:$N$692) -> 18 | F9: =MAX(Absolute_Scores!$N$6:$N$692) -> 67 | G9: =AVERAGE(Absolute_Scores!$N$6:$N$692) -> 42.160116 | H9: =MEDIAN(Absolute_Scores!$N$6:$N$692) -> 42 | I9: =_xlfn.STDEV.S(Absolute_Scores!$N$6:$N$692) -> 8.3147264 | J9: =_xlfn.PERCENTILE.INC(Absolute_Scores!$N$6:$N$692,0.25) -> 36 | K9: =_xlfn.PERCENTILE.INC(Absolute_Scores!$N$6:$N$692,0.75) -> 48
A10: Preference C | B10: NovaTech | C10: Normalized | D10: =COUNT(Normalized_Scores!$N$6:$N$692) -> 687 | E10: =MIN(Normalized_Scores!$N$6:$N$692) -> 26.87 | F10: =MAX(Normalized_Scores!$N$6:$N$692) -> 100 | G10: =AVERAGE(Normalized_Scores!$N$6:$N$692) -> 62.925429 | H10: =MEDIAN(Normalized_Scores!$N$6:$N$692) -> 62.69 | I10: =_xlfn.STDEV.S(Normalized_Scores!$N$6:$N$692) -> 12.40984 | J10: =_xlfn.PERCENTILE.INC(Normalized_Scores!$N$6:$N$692,0.25) -> 53.73 | K10: =_xlfn.PERCENTILE.INC(Normalized_Scores!$N$6:$N$692,0.75) -> 71.64
A12: SKEWNESS AND TAIL · SKEW() is Excel's own sample skewness; the reading beside it is a description, not a verdict
A13: Preference | B13: Score Type | C13: Skewness =SKEW() | D13: Reading | E13: Spread (Max-Min) | F13: IQR (P75-P25) | G13: Modal value | H13: Modal share | I13: Tail Observation
A14: Preference A | B14: Absolute | C14: =SKEW(Absolute_Scores!$D$6:$D$1248) -> 0.13448674 | D14: =IF(ABS(C14)<0.25,"approximately symmetric",IF(C14>0,"right-skewed — a thin upper tail","left-skewed — a thin lower tail")) -> approximately symmetric | E14: =F5-E5 -> 55 | F14: =K5-J5 -> 6 | G14: =MODE(Absolute_Scores!$D$6:$D$1248) -> 50 | H14: =COUNTIF(Absolute_Scores!$D$6:$D$1248,G14)/COUNT(Absolute_Scores!$D$6:$D$1248) -> 0.33708769 | I14: ="P25 "&TEXT(J5,"0")&" · median "&TEXT(H5,"0")&" · P75 "&TEXT(K5,"0")&" — the middle half spans "&TEXT(K5-J5,"0")&" points of a "&TEXT(F5-E5,"0")&"-point range, "&"and "&TEXT(COUNTIF(Absolute_Scores!$D$6:$D$1248,G14)/COUNT(Absolute_Scores!$D$6:$D$1248),"0%")&" of the population sits on the single most common value." -> P25 44 · median 50 · P75 50 — the middle half spans 6 points of a 55-point range, and 34% of the population sits on the single most common value.
A15: Preference A | B15: Normalized | C15: =SKEW(Normalized_Scores!$D$6:$D$1248) -> 0.13448674 | D15: =IF(ABS(C15)<0.25,"approximately symmetric",IF(C15>0,"right-skewed — a thin upper tail","left-skewed — a thin lower tail")) -> approximately symmetric | E15: =F6-E6 -> 68.75 | F15: =K6-J6 -> 7.5 | G15: =MODE(Normalized_Scores!$D$6:$D$1248) -> 62.5 | H15: =COUNTIF(Normalized_Scores!$D$6:$D$1248,G15)/COUNT(Normalized_Scores!$D$6:$D$1248) -> 0.33708769 | I15: ="P25 "&TEXT(J6,"0")&" · median "&TEXT(H6,"0")&" · P75 "&TEXT(K6,"0")&" — the middle half spans "&TEXT(K6-J6,"0")&" points of a "&TEXT(F6-E6,"0")&"-point range, "&"and "&TEXT(COUNTIF(Normalized_Scores!$D$6:$D$1248,G15)/COUNT(Normalized_Scores!$D$6:$D$1248),"0%")&" of the population sits on the single most common value." -> P25 55 · median 63 · P75 63 — the middle half spans 8 points of a 69-point range, and 34% of the population sits on the single most common value.
A16: Preference B | B16: Absolute | C16: =SKEW(Absolute_Scores!$I$6:$I$5120) -> -0.31618432 | D16: =IF(ABS(C16)<0.25,"approximately symmetric",IF(C16>0,"right-skewed — a thin upper tail","left-skewed — a thin lower tail")) -> left-skewed — a thin lower tail | E16: =F7-E7 -> 62 | F16: =K7-J7 -> 9 | G16: =MODE(Absolute_Scores!$I$6:$I$5120) -> 50 | H16: =COUNTIF(Absolute_Scores!$I$6:$I$5120,G16)/COUNT(Absolute_Scores!$I$6:$I$5120) -> 0.44965787 | I16: ="P25 "&TEXT(J7,"0")&" · median "&TEXT(H7,"0")&" · P75 "&TEXT(K7,"0")&" — the middle half spans "&TEXT(K7-J7,"0")&" points of a "&TEXT(F7-E7,"0")&"-point range, "&"and "&TEXT(COUNTIF(Absolute_Scores!$I$6:$I$5120,G16)/COUNT(Absolute_Scores!$I$6:$I$5120),"0%")&" of the population sits on the single most common value." -> P25 41 · median 50 · P75 50 — the middle half spans 9 points of a 62-point range, and 45% of the population sits on the single most common value.
A17: Preference B | B17: Normalized | C17: =SKEW(Normalized_Scores!$I$6:$I$5120) -> -0.31618432 | D17: =IF(ABS(C17)<0.25,"approximately symmetric",IF(C17>0,"right-skewed — a thin upper tail","left-skewed — a thin lower tail")) -> left-skewed — a thin lower tail | E17: =F8-E8 -> 77.5 | F17: =K8-J8 -> 11.25 | G17: =MODE(Normalized_Scores!$I$6:$I$5120) -> 62.5 | H17: =COUNTIF(Normalized_Scores!$I$6:$I$5120,G17)/COUNT(Normalized_Scores!$I$6:$I$5120) -> 0.44965787 | I17: ="P25 "&TEXT(J8,"0")&" · median "&TEXT(H8,"0")&" · P75 "&TEXT(K8,"0")&" — the middle half spans "&TEXT(K8-J8,"0")&" points of a "&TEXT(F8-E8,"0")&"-point range, "&"and "&TEXT(COUNTIF(Normalized_Scores!$I$6:$I$5120,G17)/COUNT(Normalized_Scores!$I$6:$I$5120),"0%")&" of the population sits on the single most common value." -> P25 51 · median 63 · P75 63 — the middle half spans 11 points of a 78-point range, and 45% of the population sits on the single most common value.
A18: Preference C | B18: Absolute | C18: =SKEW(Absolute_Scores!$N$6:$N$692) -> 0.0054323583 | D18: =IF(ABS(C18)<0.25,"approximately symmetric",IF(C18>0,"right-skewed — a thin upper tail","left-skewed — a thin lower tail")) -> approximately symmetric | E18: =F9-E9 -> 49 | F18: =K9-J9 -> 12 | G18: =MODE(Absolute_Scores!$N$6:$N$692) -> 55 | H18: =COUNTIF(Absolute_Scores!$N$6:$N$692,G18)/COUNT(Absolute_Scores!$N$6:$N$692) -> 0.10043668 | I18: ="P25 "&TEXT(J9,"0")&" · median "&TEXT(H9,"0")&" · P75 "&TEXT(K9,"0")&" — the middle half spans "&TEXT(K9-J9,"0")&" points of a "&TEXT(F9-E9,"0")&"-point range, "&"and "&TEXT(COUNTIF(Absolute_Scores!$N$6:$N$692,G18)/COUNT(Absolute_Scores!$N$6:$N$692),"0%")&" of the population sits on the single most common value." -> P25 36 · median 42 · P75 48 — the middle half spans 12 points of a 49-point range, and 10% of the population sits on the single most common value.
A19: Preference C | B19: Normalized | C19: =SKEW(Normalized_Scores!$N$6:$N$692) -> 0.0055076916 | D19: =IF(ABS(C19)<0.25,"approximately symmetric",IF(C19>0,"right-skewed — a thin upper tail","left-skewed — a thin lower tail")) -> approximately symmetric | E19: =F10-E10 -> 73.13 | F19: =K10-J10 -> 17.91 | G19: =MODE(Normalized_Scores!$N$6:$N$692) -> 82.09 | H19: =COUNTIF(Normalized_Scores!$N$6:$N$692,G19)/COUNT(Normalized_Scores!$N$6:$N$692) -> 0.10043668 | I19: ="P25 "&TEXT(J10,"0")&" · median "&TEXT(H10,"0")&" · P75 "&TEXT(K10,"0")&" — the middle half spans "&TEXT(K10-J10,"0")&" points of a "&TEXT(F10-E10,"0")&"-point range, "&"and "&TEXT(COUNTIF(Normalized_Scores!$N$6:$N$692,G19)/COUNT(Normalized_Scores!$N$6:$N$692),"0%")&" of the population sits on the single most common value." -> P25 54 · median 63 · P75 72 — the middle half spans 18 points of a 73-point range, and 10% of the population sits on the single most common value.

Sheet Histogram_Data
A1: HISTOGRAM DATA · bin counts behind the six charts
A2: Twenty five-point bins spanning the whole 0-100 scale, not the observed range: a chart auto-scaled to the data would make a distribution occupying 18-80 look like it fills the scale, which is the impression this test exists to check. Every count is a COUNTIFS over the score column, so the charts move with the data.
A4: x-axis = score band · y-axis = number of KOL
A5: Bin (score) | B5: Preference A Absolute | C5: Preference A Normalized | D5: Preference B Absolute | E5: Preference B Normalized | F5: Preference C Absolute | G5: Preference C Normalized
A6: 0-5 | B6: =COUNTIFS(Absolute_Scores!$D$6:$D$1248,">=0",Absolute_Scores!$D$6:$D$1248,"<5") -> 0 | C6: =COUNTIFS(Normalized_Scores!$D$6:$D$1248,">=0",Normalized_Scores!$D$6:$D$1248,"<5") -> 0 | D6: =COUNTIFS(Absolute_Scores!$I$6:$I$5120,">=0",Absolute_Scores!$I$6:$I$5120,"<5") -> 0 | E6: =COUNTIFS(Normalized_Scores!$I$6:$I$5120,">=0",Normalized_Scores!$I$6:$I$5120,"<5") -> 0 | F6: =COUNTIFS(Absolute_Scores!$N$6:$N$692,">=0",Absolute_Scores!$N$6:$N$692,"<5") -> 0 | G6: =COUNTIFS(Normalized_Scores!$N$6:$N$692,">=0",Normalized_Scores!$N$6:$N$692,"<5") -> 0
A7: 5-10 | B7: =COUNTIFS(Absolute_Scores!$D$6:$D$1248,">=5",Absolute_Scores!$D$6:$D$1248,"<10") -> 0 | C7: =COUNTIFS(Normalized_Scores!$D$6:$D$1248,">=5",Normalized_Scores!$D$6:$D$1248,"<10") -> 0 | D7: =COUNTIFS(Absolute_Scores!$I$6:$I$5120,">=5",Absolute_Scores!$I$6:$I$5120,"<10") -> 0 | E7: =COUNTIFS(Normalized_Scores!$I$6:$I$5120,">=5",Normalized_Scores!$I$6:$I$5120,"<10") -> 0 | F7: =COUNTIFS(Absolute_Scores!$N$6:$N$692,">=5",Absolute_Scores!$N$6:$N$692,"<10") -> 0 | G7: =COUNTIFS(Normalized_Scores!$N$6:$N$692,">=5",Normalized_Scores!$N$6:$N$692,"<10") -> 0
A8: 10-15 | B8: =COUNTIFS(Absolute_Scores!$D$6:$D$1248,">=10",Absolute_Scores!$D$6:$D$1248,"<15") -> 0 | C8: =COUNTIFS(Normalized_Scores!$D$6:$D$1248,">=10",Normalized_Scores!$D$6:$D$1248,"<15") -> 0 | D8: =COUNTIFS(Absolute_Scores!$I$6:$I$5120,">=10",Absolute_Scores!$I$6:$I$5120,"<15") -> 0 | E8: =COUNTIFS(Normalized_Scores!$I$6:$I$5120,">=10",Normalized_Scores!$I$6:$I$5120,"<15") -> 0 | F8: =COUNTIFS(Absolute_Scores!$N$6:$N$692,">=10",Absolute_Scores!$N$6:$N$692,"<15") -> 0 | G8: =COUNTIFS(Normalized_Scores!$N$6:$N$692,">=10",Normalized_Scores!$N$6:$N$692,"<15") -> 0
A9: 15-20 | B9: =COUNTIFS(Absolute_Scores!$D$6:$D$1248,">=15",Absolute_Scores!$D$6:$D$1248,"<20") -> 0 | C9: =COUNTIFS(Normalized_Scores!$D$6:$D$1248,">=15",Normalized_Scores!$D$6:$D$1248,"<20") -> 0 | D9: =COUNTIFS(Absolute_Scores!$I$6:$I$5120,">=15",Absolute_Scores!$I$6:$I$5120,"<20") -> 1 | E9: =COUNTIFS(Normalized_Scores!$I$6:$I$5120,">=15",Normalized_Scores!$I$6:$I$5120,"<20") -> 0 | F9: =COUNTIFS(Absolute_Scores!$N$6:$N$692,">=15",Absolute_Scores!$N$6:$N$692,"<20") -> 1 | G9: =COUNTIFS(Normalized_Scores!$N$6:$N$692,">=15",Normalized_Scores!$N$6:$N$692,"<20") -> 0
A10: 20-25 | B10: =COUNTIFS(Absolute_Scores!$D$6:$D$1248,">=20",Absolute_Scores!$D$6:$D$1248,"<25") -> 0 | C10: =COUNTIFS(Normalized_Scores!$D$6:$D$1248,">=20",Normalized_Scores!$D$6:$D$1248,"<25") -> 0 | D10: =COUNTIFS(Absolute_Scores!$I$6:$I$5120,">=20",Absolute_Scores!$I$6:$I$5120,"<25") -> 3 | E10: =COUNTIFS(Normalized_Scores!$I$6:$I$5120,">=20",Normalized_Scores!$I$6:$I$5120,"<25") -> 1 | F10: =COUNTIFS(Absolute_Scores!$N$6:$N$692,">=20",Absolute_Scores!$N$6:$N$692,"<25") -> 9 | G10: =COUNTIFS(Normalized_Scores!$N$6:$N$692,">=20",Normalized_Scores!$N$6:$N$692,"<25") -> 0
A11: 25-30 | B11: =COUNTIFS(Absolute_Scores!$D$6:$D$1248,">=25",Absolute_Scores!$D$6:$D$1248,"<30") -> 5 | C11: =COUNTIFS(Normalized_Scores!$D$6:$D$1248,">=25",Normalized_Scores!$D$6:$D$1248,"<30") -> 0 | D11: =COUNTIFS(Absolute_Scores!$I$6:$I$5120,">=25",Absolute_Scores!$I$6:$I$5120,"<30") -> 6 | E11: =COUNTIFS(Normalized_Scores!$I$6:$I$5120,">=25",Normalized_Scores!$I$6:$I$5120,"<30") -> 2 | F11: =COUNTIFS(Absolute_Scores!$N$6:$N$692,">=25",Absolute_Scores!$N$6:$N$692,"<30") -> 24 | G11: =COUNTIFS(Normalized_Scores!$N$6:$N$692,">=25",Normalized_Scores!$N$6:$N$692,"<30") -> 3
A12: 30-35 | B12: =COUNTIFS(Absolute_Scores!$D$6:$D$1248,">=30",Absolute_Scores!$D$6:$D$1248,"<35") -> 34 | C12: =COUNTIFS(Normalized_Scores!$D$6:$D$1248,">=30",Normalized_Scores!$D$6:$D$1248,"<35") -> 4 | D12: =COUNTIFS(Absolute_Scores!$I$6:$I$5120,">=30",Absolute_Scores!$I$6:$I$5120,"<35") -> 229 | E12: =COUNTIFS(Normalized_Scores!$I$6:$I$5120,">=30",Normalized_Scores!$I$6:$I$5120,"<35") -> 4 | F12: =COUNTIFS(Absolute_Scores!$N$6:$N$692,">=30",Absolute_Scores!$N$6:$N$692,"<35") -> 108 | G12: =COUNTIFS(Normalized_Scores!$N$6:$N$692,">=30",Normalized_Scores!$N$6:$N$692,"<35") -> 2
A13: 35-40 | B13: =COUNTIFS(Absolute_Scores!$D$6:$D$1248,">=35",Absolute_Scores!$D$6:$D$1248,"<40") -> 120 | C13: =COUNTIFS(Normalized_Scores!$D$6:$D$1248,">=35",Normalized_Scores!$D$6:$D$1248,"<40") -> 12 | D13: =COUNTIFS(Absolute_Scores!$I$6:$I$5120,">=35",Absolute_Scores!$I$6:$I$5120,"<40") -> 936 | E13: =COUNTIFS(Normalized_Scores!$I$6:$I$5120,">=35",Normalized_Scores!$I$6:$I$5120,"<40") -> 75 | F13: =COUNTIFS(Absolute_Scores!$N$6:$N$692,">=35",Absolute_Scores!$N$6:$N$692,"<40") -> 106 | G13: =COUNTIFS(Normalized_Scores!$N$6:$N$692,">=35",Normalized_Scores!$N$6:$N$692,"<40") -> 11
A14: 40-45 | B14: =COUNTIFS(Absolute_Scores!$D$6:$D$1248,">=40",Absolute_Scores!$D$6:$D$1248,"<45") -> 389 | C14: =COUNTIFS(Normalized_Scores!$D$6:$D$1248,">=40",Normalized_Scores!$D$6:$D$1248,"<45") -> 45 | D14: =COUNTIFS(Absolute_Scores!$I$6:$I$5120,">=40",Absolute_Scores!$I$6:$I$5120,"<45") -> 1008 | E14: =COUNTIFS(Normalized_Scores!$I$6:$I$5120,">=40",Normalized_Scores!$I$6:$I$5120,"<45") -> 218 | F14: =COUNTIFS(Absolute_Scores!$N$6:$N$692,">=40",Absolute_Scores!$N$6:$N$692,"<45") -> 177 | G14: =COUNTIFS(Normalized_Scores!$N$6:$N$692,">=40",Normalized_Scores!$N$6:$N$692,"<45") -> 33
A15: 45-50 | B15: =COUNTIFS(Absolute_Scores!$D$6:$D$1248,">=45",Absolute_Scores!$D$6:$D$1248,"<50") -> 66 | C15: =COUNTIFS(Normalized_Scores!$D$6:$D$1248,">=45",Normalized_Scores!$D$6:$D$1248,"<50") -> 98 | D15: =COUNTIFS(Absolute_Scores!$I$6:$I$5120,">=45",Absolute_Scores!$I$6:$I$5120,"<50") -> 276 | E15: =COUNTIFS(Normalized_Scores!$I$6:$I$5120,">=45",Normalized_Scores!$I$6:$I$5120,"<50") -> 875 | F15: =COUNTIFS(Absolute_Scores!$N$6:$N$692,">=45",Absolute_Scores!$N$6:$N$692,"<50") -> 133 | G15: =COUNTIFS(Normalized_Scores!$N$6:$N$692,">=45",Normalized_Scores!$N$6:$N$692,"<50") -> 74
A16: 50-55 | B16: =COUNTIFS(Absolute_Scores!$D$6:$D$1248,">=50",Absolute_Scores!$D$6:$D$1248,"<55") -> 481 | C16: =COUNTIFS(Normalized_Scores!$D$6:$D$1248,">=50",Normalized_Scores!$D$6:$D$1248,"<55") -> 94 | D16: =COUNTIFS(Absolute_Scores!$I$6:$I$5120,">=50",Absolute_Scores!$I$6:$I$5120,"<55") -> 2378 | E16: =COUNTIFS(Normalized_Scores!$I$6:$I$5120,">=50",Normalized_Scores!$I$6:$I$5120,"<55") -> 519 | F16: =COUNTIFS(Absolute_Scores!$N$6:$N$692,">=50",Absolute_Scores!$N$6:$N$692,"<55") -> 49 | G16: =COUNTIFS(Normalized_Scores!$N$6:$N$692,">=50",Normalized_Scores!$N$6:$N$692,"<55") -> 60
A17: 55-60 | B17: =COUNTIFS(Absolute_Scores!$D$6:$D$1248,">=55",Absolute_Scores!$D$6:$D$1248,"<60") -> 112 | C17: =COUNTIFS(Normalized_Scores!$D$6:$D$1248,">=55",Normalized_Scores!$D$6:$D$1248,"<60") -> 341 | D17: =COUNTIFS(Absolute_Scores!$I$6:$I$5120,">=55",Absolute_Scores!$I$6:$I$5120,"<60") -> 188 | E17: =COUNTIFS(Normalized_Scores!$I$6:$I$5120,">=55",Normalized_Scores!$I$6:$I$5120,"<60") -> 708 | F17: =COUNTIFS(Absolute_Scores!$N$6:$N$692,">=55",Absolute_Scores!$N$6:$N$692,"<60") -> 75 | G17: =COUNTIFS(Normalized_Scores!$N$6:$N$692,">=55",Normalized_Scores!$N$6:$N$692,"<60") -> 102
A18: 60-65 | B18: =COUNTIFS(Absolute_Scores!$D$6:$D$1248,">=60",Absolute_Scores!$D$6:$D$1248,"<65") -> 21 | C18: =COUNTIFS(Normalized_Scores!$D$6:$D$1248,">=60",Normalized_Scores!$D$6:$D$1248,"<65") -> 463 | D18: =COUNTIFS(Absolute_Scores!$I$6:$I$5120,">=60",Absolute_Scores!$I$6:$I$5120,"<65") -> 79 | E18: =COUNTIFS(Normalized_Scores!$I$6:$I$5120,">=60",Normalized_Scores!$I$6:$I$5120,"<65") -> 2387 | F18: =COUNTIFS(Absolute_Scores!$N$6:$N$692,">=60",Absolute_Scores!$N$6:$N$692,"<65") -> 2 | G18: =COUNTIFS(Normalized_Scores!$N$6:$N$692,">=60",Normalized_Scores!$N$6:$N$692,"<65") -> 99
A19: 65-70 | B19: =COUNTIFS(Absolute_Scores!$D$6:$D$1248,">=65",Absolute_Scores!$D$6:$D$1248,"<70") -> 13 | C19: =COUNTIFS(Normalized_Scores!$D$6:$D$1248,">=65",Normalized_Scores!$D$6:$D$1248,"<70") -> 46 | D19: =COUNTIFS(Absolute_Scores!$I$6:$I$5120,">=65",Absolute_Scores!$I$6:$I$5120,"<70") -> 10 | E19: =COUNTIFS(Normalized_Scores!$I$6:$I$5120,">=65",Normalized_Scores!$I$6:$I$5120,"<70") -> 139 | F19: =COUNTIFS(Absolute_Scores!$N$6:$N$692,">=65",Absolute_Scores!$N$6:$N$692,"<70") -> 3 | G19: =COUNTIFS(Normalized_Scores!$N$6:$N$692,">=65",Normalized_Scores!$N$6:$N$692,"<70") -> 82
A20: 70-75 | B20: =COUNTIFS(Absolute_Scores!$D$6:$D$1248,">=70",Absolute_Scores!$D$6:$D$1248,"<75") -> 1 | C20: =COUNTIFS(Normalized_Scores!$D$6:$D$1248,">=70",Normalized_Scores!$D$6:$D$1248,"<75") -> 104 | D20: =COUNTIFS(Absolute_Scores!$I$6:$I$5120,">=70",Absolute_Scores!$I$6:$I$5120,"<75") -> 0 | E20: =COUNTIFS(Normalized_Scores!$I$6:$I$5120,">=70",Normalized_Scores!$I$6:$I$5120,"<75") -> 97 | F20: =COUNTIFS(Absolute_Scores!$N$6:$N$692,">=70",Absolute_Scores!$N$6:$N$692,"<75") -> 0 | G20: =COUNTIFS(Normalized_Scores!$N$6:$N$692,">=70",Normalized_Scores!$N$6:$N$692,"<75") -> 101
A21: 75-80 | B21: =COUNTIFS(Absolute_Scores!$D$6:$D$1248,">=75",Absolute_Scores!$D$6:$D$1248,"<80") -> 0 | C21: =COUNTIFS(Normalized_Scores!$D$6:$D$1248,">=75",Normalized_Scores!$D$6:$D$1248,"<80") -> 19 | D21: =COUNTIFS(Absolute_Scores!$I$6:$I$5120,">=75",Absolute_Scores!$I$6:$I$5120,"<80") -> 0 | E21: =COUNTIFS(Normalized_Scores!$I$6:$I$5120,">=75",Normalized_Scores!$I$6:$I$5120,"<80") -> 75 | F21: =COUNTIFS(Absolute_Scores!$N$6:$N$692,">=75",Absolute_Scores!$N$6:$N$692,"<80") -> 0 | G21: =COUNTIFS(Normalized_Scores!$N$6:$N$692,">=75",Normalized_Scores!$N$6:$N$692,"<80") -> 32
A22: 80-85 | B22: =COUNTIFS(Absolute_Scores!$D$6:$D$1248,">=80",Absolute_Scores!$D$6:$D$1248,"<85") -> 1 | C22: =COUNTIFS(Normalized_Scores!$D$6:$D$1248,">=80",Normalized_Scores!$D$6:$D$1248,"<85") -> 14 | D22: =COUNTIFS(Absolute_Scores!$I$6:$I$5120,">=80",Absolute_Scores!$I$6:$I$5120,"<85") -> 1 | E22: =COUNTIFS(Normalized_Scores!$I$6:$I$5120,">=80",Normalized_Scores!$I$6:$I$5120,"<85") -> 9 | F22: =COUNTIFS(Absolute_Scores!$N$6:$N$692,">=80",Absolute_Scores!$N$6:$N$692,"<85") -> 0 | G22: =COUNTIFS(Normalized_Scores!$N$6:$N$692,">=80",Normalized_Scores!$N$6:$N$692,"<85") -> 79
A23: 85-90 | B23: =COUNTIFS(Absolute_Scores!$D$6:$D$1248,">=85",Absolute_Scores!$D$6:$D$1248,"<90") -> 0 | C23: =COUNTIFS(Normalized_Scores!$D$6:$D$1248,">=85",Normalized_Scores!$D$6:$D$1248,"<90") -> 1 | D23: =COUNTIFS(Absolute_Scores!$I$6:$I$5120,">=85",Absolute_Scores!$I$6:$I$5120,"<90") -> 0 | E23: =COUNTIFS(Normalized_Scores!$I$6:$I$5120,">=85",Normalized_Scores!$I$6:$I$5120,"<90") -> 5 | F23: =COUNTIFS(Absolute_Scores!$N$6:$N$692,">=85",Absolute_Scores!$N$6:$N$692,"<90") -> 0 | G23: =COUNTIFS(Normalized_Scores!$N$6:$N$692,">=85",Normalized_Scores!$N$6:$N$692,"<90") -> 4
A24: 90-95 | B24: =COUNTIFS(Absolute_Scores!$D$6:$D$1248,">=90",Absolute_Scores!$D$6:$D$1248,"<95") -> 0 | C24: =COUNTIFS(Normalized_Scores!$D$6:$D$1248,">=90",Normalized_Scores!$D$6:$D$1248,"<95") -> 1 | D24: =COUNTIFS(Absolute_Scores!$I$6:$I$5120,">=90",Absolute_Scores!$I$6:$I$5120,"<95") -> 0 | E24: =COUNTIFS(Normalized_Scores!$I$6:$I$5120,">=90",Normalized_Scores!$I$6:$I$5120,"<95") -> 0 | F24: =COUNTIFS(Absolute_Scores!$N$6:$N$692,">=90",Absolute_Scores!$N$6:$N$692,"<95") -> 0 | G24: =COUNTIFS(Normalized_Scores!$N$6:$N$692,">=90",Normalized_Scores!$N$6:$N$692,"<95") -> 2
A25: 95-100 | B25: =COUNTIFS(Absolute_Scores!$D$6:$D$1248,">=95",Absolute_Scores!$D$6:$D$1248,"<=100") -> 0 | C25: =COUNTIFS(Normalized_Scores!$D$6:$D$1248,">=95",Normalized_Scores!$D$6:$D$1248,"<=100") -> 1 | D25: =COUNTIFS(Absolute_Scores!$I$6:$I$5120,">=95",Absolute_Scores!$I$6:$I$5120,"<=100") -> 0 | E25: =COUNTIFS(Normalized_Scores!$I$6:$I$5120,">=95",Normalized_Scores!$I$6:$I$5120,"<=100") -> 1 | F25: =COUNTIFS(Absolute_Scores!$N$6:$N$692,">=95",Absolute_Scores!$N$6:$N$692,"<=100") -> 0 | G25: =COUNTIFS(Normalized_Scores!$N$6:$N$692,">=95",Normalized_Scores!$N$6:$N$692,"<=100") -> 3
A26: TOTAL | B26: =SUM(B6:B25) -> 1243 | C26: =SUM(C6:C25) -> 1243 | D26: =SUM(D6:D25) -> 5115 | E26: =SUM(E6:E25) -> 5115 | F26: =SUM(F6:F25) -> 687 | G26: =SUM(G6:G25) -> 687

Sheet Preference_Comparison
A1: PREFERENCE COMPARISON · the same creators scored under all three profiles
A2: Only creators eligible for ALL THREE populations appear here — that is what makes the six numbers on a row comparable. Absolute and Normalized travel together, and the rank columns are what answer whether changing the brand changes the order rather than just the numbers.
A4: 194 creators are eligible under all three preferences
A5: KOL | B5: Category | C5: Pref A Abs | D5: Pref A Norm | E5: Pref A Rank | F5: Pref B Abs | G5: Pref B Norm | H5: Pref B Rank | I5: Pref C Abs | J5: Pref C Norm | K5: Pref C Rank | L5: Rank spread (max-min)
A6: @ainiraaul | B6: Food | C6: 50 | D6: 62.5 | E6: 220 | F6: 67 | G6: 83.75 | H6: 7 | I6: 48 | J6: 71.64 | K6: 147 | L6: 213
A7: @kokikutv | B7: Food | C7: 50 | D7: 62.5 | E7: 420 | F7: 67 | G7: 83.75 | H7: 10 | I7: 48 | J7: 71.64 | K7: 161 | L7: 410
A8: @dimasramadhan | B8: Lifestyle | C8: 64 | D8: 80 | E8: 17 | F8: 64 | G8: 80 | H8: 13 | I8: 51 | J8: 76.12 | K8: 112 | L8: 99
A9: @lilisbadriyahh | B9: Lifestyle | C9: 60 | D9: 75 | E9: 32 | F9: 64 | G9: 80 | H9: 14 | I9: 53 | J9: 79.1 | K9: 95 | L9: 81
A10: @ia_nita_lohiya | B10: Lifestyle | C10: 63 | D10: 78.75 | E10: 18 | F10: 63 | G10: 78.75 | H10: 16 | I10: 56 | J10: 83.58 | K10: 10 | L10: 8
A11: @baksorusukjoss | B11: Food | C11: 43 | D11: 53.75 | E11: 993 | F11: 62 | G11: 77.5 | H11: 18 | I11: 41 | J11: 61.19 | K11: 381 | L11: 975
A12: @dellyclarissa | B12: Lifestyle | C12: 62 | D12: 77.5 | E12: 23 | F12: 62 | G12: 77.5 | H12: 19 | I12: 49 | J12: 73.13 | K12: 137 | L12: 118
A13: @mursyidzon | B13: Food | C13: 45 | D13: 56.25 | E13: 689 | F13: 61 | G13: 76.25 | H13: 24 | I13: 42 | J13: 62.69 | K13: 362 | L13: 665
A14: @a.ci.pa | B14: Lifestyle | C14: 60 | D14: 75 | E14: 26 | F14: 60 | G14: 75 | H14: 25 | I14: 53 | J14: 79.1 | K14: 89 | L14: 64
A15: @ahquote | B15: Lifestyle | C15: 60 | D15: 75 | E15: 28 | F15: 60 | G15: 75 | H15: 27 | I15: 53 | J15: 79.1 | K15: 90 | L15: 63
A16: @avy_vhie | B16: Lifestyle | C16: 60 | D16: 75 | E16: 29 | F16: 60 | G16: 75 | H16: 34 | I16: 53 | J16: 79.1 | K16: 92 | L16: 63
A17: @faniaputriutami | B17: Lifestyle | C17: 60 | D17: 75 | E17: 30 | F17: 60 | G17: 75 | H17: 49 | I17: 53 | J17: 79.1 | K17: 93 | L17: 63
... A199: @tellaaa09 | B199: Beauty | C199: 43 | D199: 53.75 | E199: 1020 | F199: 27 | G199: 33.75 | H199: 5110 | I199: 24 | J199: 35.82 | K199: 682 | L199: 4428

Sheet Validation
A1: VALIDATION · the checks this test has to pass before its conclusions mean anything
A2: Formula checks recompute in the workbook. Process checks record what was done outside it and where the evidence lives.
A4: # | B4: Check | C4: Result | D4: Detail
A5: 1 | B5: No dummy KOL | C5: PASS | D5: Every creator comes from public.kol_directory where directory_status='active'. Population read 2026-09-10 06:25 UTC from 10.100.14.216/kol.
A6: 2 | B6: No duplicate KOL within a population | C6: PASS | D6: Each preference population is a filter over one reading, and each directory row appears once in it.
A7: 3 | B7: No fabricated metrics | C7: PASS | D7: Every input is read or null. Where the server has nothing the sub-score is N/A and its weight renormalises; nothing is defaulted to zero. See the coverage table on Population.
A8: 4 | B8: Population size recorded | C8: 6991 | D8: Active creators read: 6991. Eligible per preference: Preference A N=1243 · Preference B N=5115 · Preference C N=687
A9: 5 | B9: Three preference profiles recorded | C9: 3 | D9: Preference A = LumiSkin (Beauty) · Preference B = DailyBite (Food) · Preference C = NovaTech (Tech)
A10: 6 | B10: Absolute Score unchanged | C10: PASS | D10: No weight, sub-weight, normalisation target, band or matrix cell was altered for this test. npm run brandmatch:port:verify recalculates the 24x5 comparison workbook in Excel and asserts the JavaScript scorer reproduces all 120 rows across 26 score columns — 3.120 values, exact match.
A11: 7 | B11: One bug fixed, and named | C11: NOTED | D11: The haystack emptiness guard tested LEN(TRIM(haystack))=0, but the haystack is four fields joined with " | ", so a creator with none of them still produced " | | | " and the guard never fired. Three creators with no bio and no captions were scoring Keyword and Topic Match 0 instead of N/A. Now stripped of separators before the test. This is the only change to scoring behaviour.
A12: 8 | B12: Normalized uses the max of its OWN population | C12: =IF(AND(MAX(Normalized_Scores!$D$6:$D$1248)=100,MAX(Normalized_Scores!$I$6:$I$5120)=100,MAX(Normalized_Scores!$N$6:$N$692)=100),"PASS","FAIL") -> PASS | D12: Each Normalized column divides by MAX of that preference's own Absolute column, shown on Normalized_Scores row 4. A correct normalisation puts exactly 100 at the top of every population. No global database maximum is used anywhere.
A13: 9 | B13: Normalized Score inside 0-100 | C13: =IF(AND(MIN(Normalized_Scores!$D$6:$D$1248)>=0,MAX(Normalized_Scores!$D$6:$D$1248)<=100,MIN(Normalized_Scores!$I$6:$I$5120)>=0,MAX(Normalized_Scores!$I$6:$I$5120)<=100,MIN(Normalized_Scores!$N$6:$N$692)>=0,MAX(Normalized_Scores!$N$6:$N$692)<=100),"PASS","FAIL") -> PASS
A14: 10 | B14: Absolute Score still present beside it | C14: PASS | D14: Absolute_Scores is a full sheet, and Normalized_Scores repeats the absolute value in the column immediately left of each normalised one. Neither replaces the other.
A15: 11 | B15: Histogram bin counts reconcile with N | C15: =IF(AND(Histogram_Data!B26=COUNT(Absolute_Scores!$D$6:$D$1248),Histogram_Data!C26=COUNT(Normalized_Scores!$D$6:$D$1248),Histogram_Data!D26=COUNT(Absolute_Scores!$I$6:$I$5120),Histogram_Data!E26=COUNT(Normalized_Scores!$I$6:$I$5120),Histogram_Data!F26=COUNT(Absolute_Scores!$N$6:$N$692),Histogram_Data!G26=COUNT(Normalized_Scores!$N$6:$N$692)),"PASS","FAIL") -> PASS | D15: Every scored creator lands in exactly one bin: the six bin totals equal the six population counts.
A16: 12 | B16: Distribution summary present | C16: PASS | D16: Count, Min, Max, Mean, Median, Std Dev, P25 and P75 for all six series, each an Excel formula over the score range.
A17: 13 | B17: Skewness present | C17: PASS | D17: Excel =SKEW() over each of the six ranges, on Distribution_Summary.
A18: 14 | B18: Tail observation present | C18: PASS | D18: Per series on Distribution_Summary, assembled from that series' own P25, median, P75, range and modal share.
A19: 15 | B19: Creators comparable across all three preferences | C19: 194 | D19: Populations differ by design, so only creators eligible under all three can have their ranks compared. Preference_Comparison holds them.

Sheet Histograms
A1: HISTOGRAMS - x-axis = score band, y-axis = number of KOL
A2: Bins are five points wide and span the full 0-100 scale, so empty space at either end is part of the finding. Counts come from Histogram_Data.
