Workbook

Sheet README
A1: AUTOMETRIC — BRAND MATCH COMPARISON
A2: 24 creators read from the KOL server, scored against 5 brands, 120 matching records. Roster measured 2026-09-10 04:48 UTC from 10.100.14.216/kol.
A4: 1. WHAT THIS WORKBOOK IS
A5: Purpose | B5: To show that Brand Match is a contextual score — a function of (brand, creator) — rather than a permanent rating attached to a creator. The same 24 creators are scored against 5 deliberately different brands, and the resulting orders differ. Brand_Comparison is where that is easiest to see: one row per creator, one column per brand, and a Spread column that would read 0 if the model were secretly ranking creators rather than pairs.
A6: Source of data | B6: Every creator field comes from the KOL server (10.100.14.216/kol) via scripts/brand-match/roster-fetch.mjs, read-only. Nothing on KOL_Source_Data is invented, estimated to fill a gap, or carried over from the engine workbook's sample roster. Tables read: public.kol_directory, public.kol_social_account, public.kol_categories, feature.ig/tt_audience_analysis, feature.ig_engagement_analysis, l2_gold.kol_profile_card, l2_gold.audience_interest_daily, l2_gold.audience_geo_daily, l2_gold.audience_demographics_daily, l1_silver.unified_post.
A7: Relationship to the engine workbook | B7: Autometric_Brand_Match_Engine.xlsx is the specification of the logic and runs on a hand-built sample roster. This workbook runs the same logic on real rows: the same six components, the same weights, the same relevance matrices, all read from the same Lookup_Lists code (scripts/brand-match/build.mjs) and the same taxonomy (taxonomy.mjs). There is one model, not two.
A8: 2. THE 24 CREATORS
A9: Selection | B9: The 24 handles were given. They were not chosen by the model, and no creator outside the list appears anywhere in this workbook. 24 resolved to an active row in public.kol_directory. None had to be reported NOT FOUND.
A10: Two spellings were corrected | B10: Two requested handles do not exist on the server and each has a neighbour one transposition away that does: @erickapinedao9 → @erickapineda09, @shabiraaluaadnan → @shabiraalulaadnan. Both spellings are printed on KOL_Source_Data and on Validation. This is the only place a requested handle and a scored handle differ.
A11: Four handles existed twice | B11: Four creators hold a row on both Instagram and TikTok. The brief asks for 24 accounts, so one row per handle survives — the row carrying the most measured signal, not the most followers. Every dropped row is listed on Validation with the follower count it had, because a dropped row nobody can see is indistinguishable from a row that was never there.
A12: 3. THE FIVE BRANDS · every category taken from the database
A13: The categories are the database’s, not the workbook’s | B13: public.kol_categories holds 28 category names, and its taxonomy_key column already says which of them are the same thing — Foodies, Food and Cooking all carry Food; Sports, Gym Enthusiast, Cyclist and Fitness all carry Fitness. That column yields nine canonical values: Beauty · Entertainment · Fashion · Fitness · Food · Gen Z · Lifestyle · Moms · Tech. Lookup_Lists section 11a prints all 28 rows with their counts and their key. Both halves of every comparison resolve through that one column, so neither half authored the vocabulary it is scored on.
A14: The five brands | B14: NovaTech → Tech · LumiSkin → Beauty · DailyBite → Food · MoveFit → Fitness · UrbanMuse → Fashion. Five different canonical categories, different audience genders, different interest sets — five brands wanting the same creator profile would rank identically and demonstrate nothing. Brand_Profile carries a Source column naming the database column behind every field, and the record shape follows public.brand: name, category, brand_keywords, brand_hashtags.
A15: Audience interests are the database’s keys too | B15: The interest rows on Brand_Profile hold l2_gold.audience_interest_daily.interest_key values, spelled exactly as the server spells them — lower case, and 'sports' kept separate from 'fitness' because the database keeps them separate, which is why MoveFit targets both. A brand cannot target an interest the database does not have: the build asserts it and stops.
A16: There is no Industry field, because there is no industry column | B16: An earlier draft of this workbook carried brand Industry, Product Category, Sub Category, Brand Niche, Brand Personality, Tone, Communication Style and Positioning, scored against a 14-label taxonomy written for the engine workbook. None of those exist as creator columns on this server, and the taxonomy was a second vocabulary that disagreed with the database in two places — it filed Moms under Parenting and dropped Gen Z, when kol_categories assigns both a key of their own. They are gone. What remains either maps to a database column or is marked on Brand_Profile as scoring nothing.
A17: Hard filters left permissive | B17: The brief asks how 24 named creators compare across 5 brands. A minimum-follower or minimum-ER gate would answer a different question by deleting rows from the comparison. Sheet Hard_vs_Soft_Filter documents every gate that exists and counts what each would remove from this roster if it were switched on.
A18: 4. THE MODEL
A19: Final Match Score | B19: Final = (Business x 20 + Audience x 30 + Content x 20 + Personality x 10 + Performance x 10 + Safety x 10) / 100, on a 0-100 scale. The six weights live in editable cells on Lookup_Lists section 4 and CHECK_WEIGHT_TOTAL asserts they sum to 100. No score anywhere in this workbook is a typed number: every one is a formula over KOL_Source_Data and Brand_Profile.
A20: Sub-weights | B20: Target Audience = Age 25 / Gender 15 / Location 30 / Interest 30 (the brief’s own split). Brand & Business = Category 60 / Keyword 25 / Hashtag 15. Content & Category = Content Category 60 / Topic 40. Performance = ER 35 / Audience Quality 20 / Consistency 20 / Community 10 / Average Views 10 / Recent Growth 5. Brand Safety = Authenticity 40 / Follower Quality 30 / Verification 15 / Paid Ratio 15. The first two are not even splits, and Lookup_Lists section 11 says why: measured on this roster, Category Match takes 8 distinct values across the 120 pairs while Keyword Match takes 3 and Hashtag Match 2. Letting the two sparse signals carry 60% of a component would make it mostly measure whether a celebrity writes marketing copy in their captions, which none of them does.
A21: Missing inputs renormalise; they never become zero | B21: This is the one mechanism this workbook adds to the engine's. Where the server has no reading, the cell reads N/A and drops out of its weighted mean, so the remaining weights renormalise to 100 by themselves. A component with no inputs at all is N/A and drops out of the Final Match Score; the Available Weight column reports how much of the nominal 100 each row could be scored on. Zero is a measurement — "we looked, and there was none". Using it for "nobody looked" would rank an unmeasured creator below a bad one.
A22: Score interpretation | B22: Excellent Match 90-100 · Strong Match 80-89 · Good Match 70-79 · Moderate Match 60-69 · Low Match below 60. The bands are the brief's and live in editable cells (BAND_EXCELLENT and below). Scores on this roster sit low relative to those bands, and that is a finding rather than a bug: see section 6.
A23: 5. HARD FILTER vs SOFT MATCH
A24: The distinction | B24: A hard filter answers yes or no and removes creators from the result set: platform, minimum followers, mandatory location, tier, minimum ER, category requirement, connected-only. A soft match returns 0-100 and reorders them: brand match, audience relevance, content relevance, personality, performance, brand safety. Confusing the two is how a filter can be marked DONE while returning zero creators for every value.
A25: 6. LIMITATIONS · read this before quoting a number
A26: Six inputs do not exist on this server | B26: Audience age (no rows anywhere), sub category (no column), creator personality/tone/values/content style (no column — this empties Brand Personality Fit entirely), community (no column), comment sentiment and toxicity (0 rows), rate card (0 rows). Validation lists each one with where it would live, how it was verified and what it does to the score.
A27: Absolute scores are low against the bands — read them as a ranking, not a percentage | B27: Final scores on this roster run roughly 20 to 71, so almost every row lands in Low Match and a handful reach Moderate or Good. That is a property of the data, not of the creators. Brand Personality Fit contributes nothing at all (10 points of the 100 gone); audience interest and geography are known for only 10-20% of each sampled audience; and Keyword and Topic Match are near-empty for the reasons below. The bands are the brief's and they assume a complete creator record. USE THIS WORKBOOK TO COMPARE — creators within one brand, and one creator across the five brands. Do not read 52/100 as "52% fit".
A28: Engagement rate is scored against the creator's own tier | B28: Section 11b of Lookup_Lists sets the ER that scores 100 per tier, from 8% at Nano down to 2% at Mega. All 24 of these accounts are Mega. The shared CAL_ER_TARGET of 6% is calibrated for micro creators and would have scored @cristiano's 2.21% — the best engagement on the roster by some distance — as 37 out of 100. Engagement rate falls with reach as a matter of arithmetic, so the question the tier targets ask is "well engaged for an account this size", which is the only version a brand can act on.
A29: Audience shares are shares of the KNOWN portion | B29: l2_gold.audience_interest_daily is dominated by the key 'unknown' — often 80-89% of a creator's sample. Interest and country shares here are computed over the known remainder, and Interest Known % / Country Known % on KOL_Source_Data report how large that remainder was. A 100 on Interest Score off a 12% known sample is a much weaker claim than the same 100 off a 60% one.
A30: Categories are three different kinds of thing | B30: 12 creators carry a category from public.kol_categories (basis: live). 3 were classified from their own captions and hashtags by the taxonomy's keyword rules (basis: calculated or estimated), and the evidence that produced each one is printed beside it on KOL_Source_Data so it can be overruled. 9 carry none at all. A classified category ranks; it never gates.
A31: 9 creators have no category, and it moves their score | B31: Category Match and Content Category Match fall back to CAL_NEUTRAL for them — not to N/A, and not to CAL_UNRELATED. This has a consequence worth stating plainly: a creator nobody has categorised can outscore one who is known to be a poor fit. That is correct. Knowing @cristiano makes fitness content is real evidence against a SaaS brief; knowing nothing about @leomessi is not evidence either way. Category Basis and Confidence are the columns that tell the two apart, and their ranking says more about their audience than about their content.
A32: Keyword Match and Topic Match are close to empty, and honestly so | B32: Across all 120 pairs, Keyword Match averages under 2 and Topic Match under 4. Three reasons, none of them a bug: kol_directory.bio is ~12% filled; the brand keyword lists are Indonesian while several of these creators caption in English or Spanish, so @leomessi and @cristiano can never hit an Indonesian term whatever they post about; and these are celebrity and entertainment accounts that genuinely do not write about SaaS, skincare formulation or sportswear. The consequence is that Brand & Business Relevance rests mostly on Industry and Category (70% of it) and Content Relevance rests mostly on category, since Topic is half of what is left after sub-category and style drop out. A per-language keyword set would fix the second reason; nothing in the data fixes the third.
A33: 7. SHEETS
A34: Sheet | B34: What it holds
A35: README | B35: This sheet.
A36: KOL_Source_Data | B36: The 24 accounts as the server has them, with a Data Note per row saying what was missing.
A37: Brand_Profile | B37: The 5 brands, one column each, keyed for the engine.
A38: Matching_Engine | B38: 120 rows. Every score a formula. The only sheet that computes anything.
A39: Score_Breakdown | B39: The same rows, sub-scores first. A pure view.
A40: Match_Explanation | B40: 120 written reasons, each assembled from its own row's scores.
A41: Brand_Comparison | B41: One row per creator, one column per brand, plus Best Brand and Spread.
...

Sheet KOL_Source_Data
A1: KOL SOURCE DATA · the 24 requested accounts, read from the KOL server
A2: Nothing on this sheet is invented, estimated to fill a gap, or carried over from the engine workbook's sample roster. A cell reading N/A means the column exists and is empty, or the column does not exist at all — the Data Note says which. Every one of the five age columns is N/A for every creator: there is no age signal anywhere on this server.
A4: IDENTITY | J4: CATEGORY & CONTENT | V4: AUDIENCE | BG4: PERFORMANCE | BS4: INTEGRITY | BW4: COVERAGE
A5: KOL ID | B5: Requested Handle | C5: Handle | D5: Creator Name | E5: Platform | F5: Found In Database | G5: Followers | H5: Tier | I5: Verified | J5: Directory Category (raw) | K5: Category | L5: Category Basis | M5: Category From Captions | N5: Content Topics | O5: Classification Evidence | P5: Sub Category | Q5: Content Style | R5: Creator City | S5: Bio | T5: Caption Digest | U5: Hashtag Digest | V5: Audience Age 13-17 % | W5: Audience Age 18-24 % | X5: Audience Age 25-34 % | Y5: Audience Age 35-44 % | Z5: Audience Age 45+ % | AA5: Female % | AB5: Male % | AC5: Gender Known % | AD5: Audience Country | AE5: Country Share % | AF5: Country Known % | AG5: Audience City 1 | AH5: City 1 Share % | AI5: Audience City 2 | AJ5: City 2 Share % | AK5: Audience City 3 | AL5: City 3 Share % | AM5: City Known % | AN5: Interest Known % | AO5: Interest: art % | AP5: Interest: automotive % | AQ5: Interest: beauty % | AR5: Interest: business % | AS5: Interest: education % | AT5: Interest: entertainment % | AU5: Interest: fashion % | AV5: Interest: fitness % | AW5: Interest: food % | AX5: Interest: gaming % | AY5: Interest: music % | AZ5: Interest: parenting % | BA5: Interest: pets % | BB5: Interest: photography % | BC5: Interest: religion % | BD5: Interest: sports % | BE5: Interest: technology % | BF5: Interest: travel % | BG5: Engagement Rate (%) | BH5: Engagement Rate Source | BI5: Average Views | BJ5: Median Views | BK5: View-to-Follower Ratio | BL5: Posts Analyzed | BM5: Posts / Month | BN5: Observation Days | BO5: Cadence Usable | BP5: Followers Growth % | BQ5: Paid Ratio % | BR5: Community Score | BS5: Audience Quality | BT5: Authenticity | BU5: Follower Quality | BV5: Content Risk | BW5: Data Completeness % | BX5: Confidence | BY5: Data Note
A6: KOL-01 | B6: @instagram | C6: @instagram | D6: instagram | E6: Instagram | F6: FOUND | G6: 685896635 | H6: =IFERROR(INDEX(Lookup_Lists!$A$96:$A$100,MATCH(KOL_Source_Data!$G$6,Lookup_Lists!$B$96:$B$100,1)),"N/A") | I6: Yes | J6: Lifestyle | Moms | K6: Lifestyle | L6: live | M6: N/A | N6: Music | O6: Entertainment 2pt [music (caption)] | P6: N/A | Q6: N/A | R6: N/A | S6: Discover what's new on Instagram 🔎✨ | T6: The precision in this trick 🤯 @leonmbz is a freestyle footballer who collabs with athletes across different sports. Here, he’s teaming up with spinning top world champion @jun_spintop_s. “I’ve always been trying to push the boundaries of what’s possible.” Video by @leonmbz and @jun_spintop_s Music by @_zynyx | U6: N/A | V6: N/A | W6: N/A | X6: N/A | Y6: N/A | Z6: N/A | AA6: N/A | AB6: N/A | AC6: N/A | AD6: N/A | AE6: N/A | AF6: N/A | AG6: N/A | AH6: N/A | AI6: N/A | AJ6: N/A | AK6: N/A | AL6: N/A | AM6: N/A | AN6: N/A | AO6: N/A | AP6: N/A | AQ6: N/A | AR6: N/A | AS6: N/A | AT6: N/A | AU6: N/A | AV6: N/A | AW6: N/A | AX6: N/A | AY6: N/A | AZ6: N/A | BA6: N/A | BB6: N/A | BC6: N/A | BD6: N/A | BE6: N/A | BF6: N/A | BG6: 0.07 | BH6: kol_directory.engagement_rate | BI6: 136309208 | BJ6: 136309208 | BK6: 19.8731 | BL6: 1 | BM6: N/A | BN6: 0 | BO6: N/A | BP6: N/A | BQ6: 0 | BR6: N/A | BS6: N/A | BT6: N/A | BU6: N/A | BV6: N/A | BW6: =ROUND((IF(ISNUMBER(KOL_Source_Data!$K$6),1,IF(AND(ISTEXT(KOL_Source_Data!$K$6),KOL_Source_Data!$K$6<>"N/A"),1,0))+IF(ISNUMBER(KOL_Source_Data!$BG$6),1,IF(AND(ISTEXT(KOL_Source_Data!$BG$6),KOL_Source_Data!$BG$6<>"N/A"),1,0))+IF(ISNUMBER(KOL_Source_Data!$BI$6),1,IF(AND(ISTEXT(KOL_Source_Data!$BI$6),KOL_Source_Data!$BI$6<>"N/A"),1,0))+IF(ISNUMBER(KOL_Source_Data!$BK$6),1,IF(AND(ISTEXT(KOL_Source_Data!$BK$6),KOL_Source_Data!$BK$6<>"N/A"),1,0))+IF(ISNUMBER(KOL_Source_Data!$AA$6),1,IF(AND(ISTEXT(KOL_Source_Data!$AA$6),KOL_Source_Data!$AA$6<>"N/A"),1,0))+IF(ISNUMBER(KOL_Source_Data!$AE$6),1,IF(AND(ISTEXT(KOL_Source_Data!$AE$6),KOL_Source_Data!$AE$6<>"N/A"),1,0))+IF(ISNUMBER(KOL_Source_Data!$AH$6),1,IF(AND(ISTEXT(KOL_Source_Data!$AH$6),KOL_Source_Data!$AH$6<>"N/A"),1,0))+IF(ISNUMBER(KOL_Source_Data!$AN$6),1,IF(AND(ISTEXT(KOL_Source_Data!$AN$6),KOL_Source_Data!$AN$6<>"N/A"),1,0))+IF(ISNUMBER(KOL_Source_Data!$BS$6),1,IF(AND(ISTEXT(KOL_Source_Data!$BS$6),KOL_Source_Data!$BS$6<>"N/A"),1,0))+IF(ISNUMBER(KOL_Source_Data!$BT$6),1,IF(AND(ISTEXT(KOL_Source_Data!$BT$6),KOL_Source_Data!$BT$6<>"N/A"),1,0))+IF(ISNUMBER(KOL_Source_Data!$BU$6),1,IF(AND(ISTEXT(KOL_Source_Data!$BU$6),KOL_Source_Data!$BU$6<>"N/A"),1,0))+IF(ISNUMBER(KOL_Source_Data!$BM$6),1,IF(AND(ISTEXT(KOL_Source_Data!$BM$6),KOL_Source_Data!$BM$6<>"N/A"),1,0)))/12*100,0) | BX6: =IF(KOL_Source_Data!$BW$6>=Lookup_Lists!$D$159,"High",IF(KOL_Source_Data!$BW$6>=Lookup_Lists!$D$160,"Medium","Limited Data")) | BY6: no audience analysis row · no audience interest rows · cadence unusable: null/month extrapolated from 0 observed day(s)
A7: KOL-02 | B7: @cristiano | C7: @cristiano | D7: cristiano | E7: Instagram | F7: FOUND | G7: 679264838 | H7: =IFERROR(INDEX(Lookup_Lists!$A$96:$A$100,MATCH(KOL_Source_Data!$G$7,Lookup_Lists!$B$96:$B$100,1)),"N/A") | I7: Yes | J7: Fitness | K7: Fitness | L7: live | M7: Tech | N7: Esports, Makeup | O7: Gaming 3pt [game (caption); esports (caption)] · Beauty 2pt [makeup (caption)] | P7: N/A | Q7: N/A | R7: N/A | S7: N/A | T7: @Cristiano Ronaldo and Georgina Rodríguez (@georginagio) are married! For weeks, the internet was awash with speculation—about the date, the location, the guest list. (The rumored celebrity attendees included everyone from Rio Ferdinand to Rihanna.) In the end, the couple’s wedding took place on a symbolic date: August 11, the 10th anniversary of the day they first met at a Gucci store in Madrid. Instead of a blowout celebration, the couple, who have over 750 million Instagram followers between them, got married in their living room, wearing @gucci by Demna. “It was exactly as I’d imagined it,” says Georgina. For Vogue’s Summer digital cover, Gaby Wood spoke to Cris y Gio, as they are known to friends and family, about their intimate wedding day in Portugal. Tap the link in our bio for an exclusive look inside the ceremony. Photographed by @juergentellerstudio, makeup by @fermartinezlab, hair by @torrentfernando, with special thanks to @angelsproject, Vogue, Summer Digital Cover 2026. · Back 🟡🔵 · C❤️G · My toys 🚀 · Not yet 🤷🏽‍♂️😅 · Cuando te vuelves hacia la luz del sol, las sombras caen detrás de ti. 🌅 · Try my Game Day Blast recipe. Stay sharp. Stay ready. #FuelLikeRonaldo · Pai feliz ❤️ · Greatness takes many forms 💪 Esports World Cup is live in Paris with over 2000 players putting in the work to be the champion. @ewc_en · Football, art and passion. Proud to be part of Knight of Najd – Chapter II with @alnassr and @vhils. 100 moments from my journey, carved into on | U7: #fuellikeronaldo #alnassr #vhils #cr7 #knightofnajd | V7: N/A | W7: N/A | X7: N/A | Y7: N/A | Z7: N/A | AA7: 18.18 | AB7: 81.82 | AC7: 22 | AD7: N/A | AE7: N/A | AF7: 6 | AG7: N/A | AH7: N/A | AI7: N/A | AJ7: N/A | AK7: N/A | AL7: N/A | AM7: N/A | AN7: 16.7 | AO7: N/A | AP7: N/A | AQ7: N/A | AR7: 5.9 | AS7: 5.9 | AT7: 11.8 | AU7: N/A | AV7: N/A | AW7: 5.9 | AX7: 5.9 | AY7: N/A | AZ7: N/A | BA7: N/A | BB7: N/A | BC7: 29.4 | BD7: 29.4 | BE7: 5.9 | BF7: N/A | BG7: 2.21 | BH7: kol_directory.engagement_rate | BI7: 80305356 | BJ7: 80305356 | BK7: N/A | BL7: 8 | BM7: 10 | BN7: 24 | BO7: Yes | BP7: 0.0637 | BQ7: 12.5 | BR7: N/A | BS7: 68 | BT7: 69 | BU7: 68 | BV7: N/A | BW7: =ROUND((IF(ISNUMBER(KOL_Source_Data!$K$7),1,IF(AND(ISTEXT(KOL_Source_Data!$K$7),KOL_Source_Data!$K$7<>"N/A"),1,0))+IF(ISNUMBER(KOL_Source_Data!$BG$7),1,IF(AND(ISTEXT(KOL_Source_Data!$BG$7),KOL_Source_Data!$BG$7<>"N/A"),1,0))+IF(ISNUMBER(KOL_Source_Data!$BI$7),1,IF(AND(ISTEXT(KOL_Source_Data!$BI$7),KOL_Source_Data!$BI$7<>"N/A"),1,0))+IF(ISNUMBER(KOL_Source_Data!$BK$7),1,IF(AND(ISTEXT(KOL_Source_Data!$BK$7),KOL_Source_Data!$BK$7<>"N/A"),1,0))+IF(ISNUMBER(KOL_Source_Data!$AA$7),1,IF(AND(ISTEXT(KOL_Source_Data!$AA$7),KOL_Source_Data!$AA$7<>"N/A"),1,0))+IF(ISNUMBER(KOL_Source_Data!$AE$7),1,IF(AND(ISTEXT(KOL_Source_Data!$AE$7),KOL_Source_Data!$AE$7<>"N/A"),1,0))+IF(ISNUMBER(KOL_Source_Data!$AH$7),1,IF(AND(ISTEXT(KOL_Source_Data!$AH$7),KOL_Source_Data!$AH$7<>"N/A"),1,0))+IF(ISNUMBER(KOL_Source_Data!$AN$7),1,IF(AND(ISTEXT(KOL_Source_Data!$AN$7),KOL_Source_Data!$AN$7<>"N/A"),1,0))+IF(ISNUMBER(KOL_Source_Data!$BS$7),1,IF(AND(ISTEXT(KOL_Source_Data!$BS$7),KOL_Source_Data!$BS$7<>"N/A"),1,0))+IF(ISNUMBER(KOL_Source_Data!$BT$7),1,IF(AND(ISTEXT(KOL_Source_Data!$BT$7),KOL_Source_Data!$BT$7<>"N/A"),1,0))+IF(ISNUMBER(KOL_Source_Data!$BU$7),1,IF(AND(ISTEXT(KOL_Source_Data!$BU$7),KOL_Source_Data!$BU$7<>"N/A"),1,0))+IF(ISNUMBER(KOL_Source_Data!$BM$7),1,IF(AND(ISTEXT(KOL_Source_Data!$BM$7),KOL_Source_Data!$BM$7<>"N/A"),1,0)))/12*100,0) | BX7: =IF(KOL_Source_Data!$BW$7>=Lookup_Lists!$D$159,"High",IF(KOL_Source_Data!$BW$7>=Lookup_Lists!$D$160,"Medium","Limited Data")) | BY7: complete on every tracked field
A8: KOL-03 | B8: @leomessi | C8: @leomessi | D8: leomessi | E8: Instagram | F8: FOUND | G8: 516185245 | H8: =IFERROR(INDEX(Lookup_Lists!$A$96:$A$100,MATCH(KOL_Source_Data!$G$8,Lookup_Lists!$B$96:$B$100,1)),"N/A") | I8: Yes | J8: Animal Lovers | K8: N/A | L8: N/A | M8: N/A | N8: N/A | O8: N/A | P8: N/A | Q8: N/A | R8: N/A | S8: Bienvenidos a la cuenta oficial de Instagram de Leo Messi / Welcome to the official Leo Messi Instagram account | T8: Te amo, pa. ❤️ · Germany 2006. South Africa 2010. Brazil 2014. Russia 2018. Qatar 2022. Canada, Mexico and United States 2026. Six FIFA World Cups. Relive the journey with my official FIFA World Cup™ signed collection - available only at Icons.com Alemania 2006. Sudáfrica 2010. Brasil 2014. Rusia 2018. Qatar 2022. Canadá, México y Estados Unidos 2026. Seis Copas del Mundo. Reviví todo el camino con mi colección oficial firmada de la Copa Mundial de la FIFA™. Disponible exclusivamente en Icons.com · Thanks world, we’ll take it from here. 🌎 MLS & Leagues Cup are back in a big way. · golden memories. ✨ the new Leo Messi x Originals collection, available tomorrow. · Introducing the new Leo Messi x Originals collection, available tomorrow. Certified gold. 🏅 Descubrí la nueva colección Leo Messi x Originals. Disponible desde mañana. Puro oro. 🏅 · El dolor es muy grande y va a costar que cierre esta herida. Pero también me quedo con todo lo bueno… Con los partidos que dimos vuelta dejando todo y que quedarán para siempre en la memoria, con el apoyo de un país entero que junto con el trabajo y el esfuerzo de este grupo nos llevó a volver a estar, una vez más, entre los mejores del mundo. Hoy cuesta valorar lo que hicimos, pero este grupo llegó a dos finales consecutivas de la Copa del Mundo. Muchas gracias de corazón por cada saludo y por cada mensaje. Una vez más logramos unirnos como país y estar todos juntos, compartiendo el inmenso orgullo de ser argentinos. También quiero fel | U8: N/A | V8: N/A | W8: N/A | X8: N/A | Y8: N/A | Z8: N/A | AA8: 20 | AB8: 80 | AC8: 25 | AD8: N/A | AE8: N/A | AF8: 3 | AG8: N/A | AH8: N/A | AI8: N/A | AJ8: N/A | AK8: N/A | AL8: N/A | AM8: N/A | AN8: 18.3 | AO8: 5.3 | AP8: 5.3 | AQ8: N/A | AR8: 10.5 | AS8: N/A | AT8: 5.3 | AU8: N/A | AV8: 5.3 | AW8: N/A | AX8: 10.5 | AY8: 10.5 | AZ8: 10.5 | BA8: N/A | BB8: N/A | BC8: 21.1 | BD8: 15.8 | BE8: N/A | BF8: N/A | BG8: 2.66 | BH8: kol_directory.engagement_rate | BI8: 44938781 | BJ8: 44938781 | BK8: N/A | BL8: 8 | BM8: 0.87 | BN8: 275 | BO8: Yes | BP8: 0.0191 | BQ8: 25 | BR8: N/A | BS8: 65 | BT8: 67 | BU8: 63 | BV8: N/A | BW8: =ROUND((IF(ISNUMBER(KOL_Source_Data!$K$8),1,IF(AND(ISTEXT(KOL_Source_Data!$K$8),KOL_Source_Data!$K$8<>"N/A"),1,0))+IF(ISNUMBER(KOL_Source_Data!$BG$8),1,IF(AND(ISTEXT(KOL_Source_Data!$BG$8),KOL_Source_Data!$BG$8<>"N/A"),1,0))+IF(ISNUMBER(KOL_Source_Data!$BI$8),1,IF(AND(ISTEXT(KOL_Source_Data!$BI$8),KOL_Source_Data!$BI$8<>"N/A"),1,0))+IF(ISNUMBER(KOL_Source_Data!$BK$8),1,IF(AND(ISTEXT(KOL_Source_Data!$BK$8),KOL_Source_Data!$BK$8<>"N/A"),1,0))+IF(ISNUMBER(KOL_Source_Data!$AA$8),1,IF(AND(ISTEXT(KOL_Source_Data!$AA$8),KOL_Source_Data!$AA$8<>"N/A"),1,0))+IF(ISNUMBER(KOL_Source_Data!$AE$8),1,IF(AND(ISTEXT(KOL_Source_Data!$AE$8),KOL_Source_Data!$AE$8<>"N/A"),1,0))+IF(ISNUMBER(KOL_Source_Data!$AH$8),1,IF(AND(ISTEXT(KOL_Source_Data!$AH$8),KOL_Source_Data!$AH$8<>"N/A"),1,0))+IF(ISNUMBER(KOL_Source_Data!$AN$8),1,IF(AND(ISTEXT(KOL_Source_Data!$AN$8),KOL_Source_Data!$AN$8<>"N/A"),1,0))+IF(ISNUMBER(KOL_Source_Data!$BS$8),1,IF(AND(ISTEXT(KOL_Source_Data!$BS$8),KOL_Source_Data!$BS$8<>"N/A"),1,0))+IF(ISNUMBER(KOL_Source_Data!$BT$8),1,IF(AND(ISTEXT(KOL_Source_Data!$BT$8),KOL_Source_Data!$BT$8<>"N/A"),1,0))+IF(ISNUMBER(KOL_Source_Data!$BU$8),1,IF(AND(ISTEXT(KOL_Source_Data!$BU$8),KOL_Source_Data!$BU$8<>"N/A"),1,0))+IF(ISNUMBER(KOL_Source_Data!$BM$8),1,IF(AND(ISTEXT(KOL_Source_Data!$BM$8),KOL_Source_Data!$BM$8<>"N/A"),1,0)))/12*100,0) | BX8: =IF(KOL_Source_Data!$BW$8>=Lookup_Lists!$D$159,"High",IF(KOL_Source_Data!$BW$8>=Lookup_Lists!$D$160,"Medium","Limited Data")) | BY8: no category: kol_categories carries none and caption evidence did not reach the threshold
A9: KOL-04 | B9: @raffinagita1717 | C9: @raffinagita1717 | D9: raffinagita1717 | E9: Instagram | F9: FOUND | G9: 75052814 | H9: =IFERROR(INDEX(Lookup_Lists!$A$96:$A$100,MATCH(KOL_Source_Data!$G$9,Lookup_Lists!$B$96:$B$100,1)),"N/A") | I9: Yes | J9: N/A | K9: Lifestyle | L9: calculated | M9: Lifestyle | N9: Domestic Travel, Business, City & Culture | O9: Travel 9pt [jalan-jalan (caption); wisata (caption); wisata lokal (caption)] · Finance 5pt [umkm (caption)] | P9: N/A | Q9: N/A | R9: N/A | S9: Single terbaru "Bersyukurlah" ⬇️⬇️ | T9: Dari Indonesia, menuju lebih dekat ke Asia. 🌏🏠 Di press conference D’MASIV Asia Home Run, Nagita Slavina berbagi harapannya untuk membawa pengalaman D’MASIV lebih dekat dengan para pendengar di berbagai negara Asia—dengan skala yang lebih besar dan tentunya pengalaman yang nggak terlupakan. Siap ikut merasakan perjalanan D’MASIV Asia Home Run? 🏃‍♂️💨 🎟️ Dapatkan tiketmu: dmasivtour.com · Perjalanan The Duda’s-1 belum selesai. Setelah berkeliling Indonesia dan sempat membawa cerita sampai ke Amerika, kali ini rasa penasaran itu membawa kita menjelajahi Asia. Bukan cuma datang ke tempat baru, tapi mengenal lebih dekat budaya, kebiasaan, makanan, musik, dan cerita orang-orangnya. Melihat apa yang membuat setiap negara berbeda, sekaligus menemukan banyak hal yang ternyata terasa dekat dengan Indonesia. The Duda’s-1 Goes to Asia. Satu benua, banyak cerita. Kira-kira negara mana yang bakal mereka datangi pertama? · The Dudas-1, yang beranggotakan Raffi Ahmad, Ariel NOAH, Gading Marten, dan Desta, bersiap melebarkan sayap mereka ke kancah internasional lewat tur Asia. Setelah hampir tiga tahun aktif berkeliling Indonesia untuk mempromosikan destinasi wisata lokal serta mendongkrak UMKM, keempat sahabat ini memutuskan untuk menjajal tantangan baru di luar negeri. Ariel NOAH menjelaskan bahwa pemilihan kawasan Asia bertujuan untuk mempelajari cara negara-negara tetangga mempromosikan pariwisata mereka ke tingkat dunia, sehingga hasilnya dapat menjadi bahan pembelajaran yang berman | U9: #thedudasminusone #ransentertainment #dmasiv #nagitaslavina #utusankhususpresiden #pembinaangenerasimuda #pekerjaseni | V9: N/A | W9: N/A | X9: N/A | Y9: N/A | Z9: N/A | AA9: 50 | AB9: 50 | AC9: 30 | AD9: Indonesia | AE9: 60 | AF9: 5 | AG9: N/A | AH9: N/A | AI9: N/A | AJ9: N/A | AK9: N/A | AL9: N/A | AM9: N/A | AN9: 8.7 | AO9: N/A | AP9: N/A | AQ9: 11.1 | AR9: 22.2 | AS9: 22.2 | AT9: 11.1 | AU9: N/A | AV9: N/A | AW9: N/A | AX9: N/A | AY9: 11.1 | AZ9: 11.1 | BA9: N/A | BB9: N/A | BC9: N/A | BD9: N/A | BE9: 11.1 | BF9: N/A | BG9: 0.52 | BH9: kol_directory.engagement_rate | BI9: 1148129 | BJ9: 1148129 | BK9: 1.5298 | BL9: 6 | BM9: 0.27 | BN9: 666 | BO9: Yes | BP9: -0.0261 | BQ9: 0 | BR9: N/A | BS9: 58 | BT9: 29 | BU9: 86 | BV9: N/A | BW9: =ROUND((IF(ISNUMBER(KOL_Source_Data!$K$9),1,IF(AND(ISTEXT(KOL_Source_Data!$K$9),KOL_Source_Data!$K$9<>"N/A"),1,0))+IF(ISNUMBER(KOL_Source_Data!$BG$9),1,IF(AND(ISTEXT(KOL_Source_Data!$BG$9),KOL_Source_Data!$BG$9<>"N/A"),1,0))+IF(ISNUMBER(KOL_Source_Data!$BI$9),1,IF(AND(ISTEXT(KOL_Source_Data!$BI$9),KOL_Source_Data!$BI$9<>"N/A"),1,0))+IF(ISNUMBER(KOL_Source_Data!$BK$9),1,IF(AND(ISTEXT(KOL_Source_Data!$BK$9),KOL_Source_Data!$BK$9<>"N/A"),1,0))+IF(ISNUMBER(KOL_Source_Data!$AA$9),1,IF(AND(ISTEXT(KOL_Source_Data!$AA$9),KOL_Source_Data!$AA$9<>"N/A"),1,0))+IF(ISNUMBER(KOL_Source_Data!$AE$9),1,IF(AND(ISTEXT(KOL_Source_Data!$AE$9),KOL_Source_Data!$AE$9<>"N/A"),1,0))+IF(ISNUMBER(KOL_Source_Data!$AH$9),1,IF(AND(ISTEXT(KOL_Source_Data!$AH$9),KOL_Source_Data!$AH$9<>"N/A"),1,0))+IF(ISNUMBER(KOL_Source_Data!$AN$9),1,IF(AND(ISTEXT(KOL_Source_Data!$AN$9),KOL_Source_Data!$AN$9<>"N/A"),1,0))+IF(ISNUMBER(KOL_Source_Data!$BS$9),1,IF(AND(ISTEXT(KOL_Source_Data!$BS$9),KOL_Source_Data!$BS$9<>"N/A"),1,0))+IF(ISNUMBER(KOL_Source_Data!$BT$9),1,IF(AND(ISTEXT(KOL_Source_Data!$BT$9),KOL_Source_Data!$BT$9<>"N/A"),1,0))+IF(ISNUMBER(KOL_Source_Data!$BU$9),1,IF(AND(ISTEXT(KOL_Source_Data!$BU$9),KOL_Source_Data!$BU$9<>"N/A"),1,0))+IF(ISNUMBER(KOL_Source_Data!$BM$9),1,IF(AND(ISTEXT(KOL_Source_Data!$BM$9),KOL_Source_Data!$BM$9<>"N/A"),1,0)))/12*100,0) | BX9: =IF(KOL_Source_Data!$BW$9>=Lookup_Lists!$D$159,"High",IF(KOL_Source_Data!$BW$9>=Lookup_Lists!$D$160,"Medium","Limited Data")) | BY9: category calculated from captions, not from kol_categories
A10: KOL-05 | B10: @lunamaya | C10: @lunamaya | D10: lunamaya | E10: Instagram | F10: FOUND | G10: 37961844 | H10: =IFERROR(INDEX(Lookup_Lists!$A$96:$A$100,MATCH(KOL_Source_Data!$G$10,Lookup_Lists!$B$96:$B$100,1)),"N/A") | I10: Yes | J10: Beauty | K10: Beauty | L10: live | M10: N/A | N10: Career, Job Hunting & CV, Domestic Travel | O10: Education 5pt [interview (caption)] · Fashion 4pt [fashion (caption); gaya (caption); outfit (caption)] | P10: N/A | Q10: N/A | R10: N/A | S10: @namabeauty.co @tsmediaid @roleentertainment @yayasan_lunamayanawasena lunamaya@role-entertainment.com BA @zappremiere @rrfx.indonesia | T10: POV: the jewels changed everything! @bvlgari✨️ More from this special cover story over at @bazaarindonesia 🫶 · A glimpse behind the sparkle✨️ @bvlgari · Dalam gerak, kilau, dan siluet yang tegas, @lunamaya mewarnai Harper’s Bazaar Indonesia edisi Agustus 2026. Dipotret di Singapura dalam balutan @bvlgari High Jewelry, kamera menangkap sisi Luna yang modern, powerful, dan penuh karakter. ✨ Portofolio ini: Keseluruhan Perhiasan & Jam tangan: @bvlgari High Jewelry Director: @hilariusjason Video Editor: @fajrids Editor Fashion: @yudithnk Busana: @blancstudio.official @dibbaofficial, Didit Hediprasetyo, @heaven_tanudiredja @_peau @yosafat_k Makeup: @zhouaiyimua Hair: @tressandcurvy (@colinyeohair @dorenelowhair @sitosthair @janebokhair) Asst. Stylist: @nau.kamillaa Lokasi: The Clifford Pier Alfresco Deck and La Brasserie’s Private Dining Room at @fullertonbayhotelsg · A very Cinta birthday! @claurakiehl 🥳🫶 · Here’s to a brighter Indonesia🇮🇩🫶 · Dressed up for a day that means so much✨️🇮🇩 Dirgahayu ke-81, Indonesiaku. Semoga negeri ini selalu menjadi rumah yang kita banggakan❤️🤍 -- Outfit: @saptodjojokartiko | Stylist: @hagaipakan | Bag: @bvlgari | Make Up: @kunsoomakeupartist | Hair Do: @iwanetaufik_hair | Broch: @epajewel | Suntiang: @hummingbirdroad · Didn’t expect anything to survive HYROX hahaha but my makeup did tho. complexion, bibir, semuanya masih cakeppp💋 · Untuk edisi Agustus 2026, @lunamaya kembali menghiasi cover Harper’s Bazaar Indonesia. Dipotret di Singapur | U10: #withgalaxy #teamgalaxy #galaxys26ultra #circletosearchwithgoogle #circleitthatsall #mexico66golf #onitsukatiger #onitsukatigerid | V10: N/A | W10: N/A | X10: N/A | Y10: N/A | Z10: N/A | AA10: 51.52 | AB10: 48.48 | AC10: 33 | AD10: Indonesia | AE10: 85 | AF10: 20 | AG10: Bali | AH10: 25 | AI10: Bandung | AJ10: 25 | AK10: Jakarta | AL10: 16.7 | AM10: 100 | AN10: 25.2 | AO10: N/A | AP10: 3.6 | AQ10: 3.6 | AR10: 28.6 | AS10: 7.1 | AT10: 7.1 | AU10: 10.7 | AV10: N/A | AW10: 3.6 | AX10: N/A | AY10: N/A | AZ10: 3.6 | BA10: N/A | BB10: 3.6 | BC10: 10.7 | BD10: 3.6 | BE10: 10.7 | BF10: 3.6 | BG10: 0.03 | BH10: kol_directory.engagement_rate | BI10: 383646 | BJ10: 205306 | BK10: 1.0106 | BL10: 6 | BM10: 45 | BN10: 4 | BO10: No | BP10: -0.0301 | BQ10: 0 | BR10: N/A | BS10: 72 | BT10: 73 | BU10: 71 | BV10: N/A | BW10: =ROUND((IF(ISNUMBER(KOL_Source_Data!$K$10),1,IF(AND(ISTEXT(KOL_Source_Data!$K$10),KOL_Source_Data!$K$10<>"N/A"),1,0))+IF(ISNUMBER(KOL_Source_Data!$BG$10),1,IF(AND(ISTEXT(KOL_Source_Data!$BG$10),KOL_Source_Data!$BG$10<>"N/A"),1,0))+IF(ISNUMBER(KOL_Source_Data!$BI$10),1,IF(AND(ISTEXT(KOL_Source_Data!$BI$10),KOL_Source_Data!$BI$10<>"N/A"),1,0))+IF(ISNUMBER(KOL_Source_Data!$BK$10),1,IF(AND(ISTEXT(KOL_Source_Data!$BK$10),KOL_Source_Data!$BK$10<>"N/A"),1,0))+IF(ISNUMBER(KOL_Source_Data!$AA$10),1,IF(AND(ISTEXT(KOL_Source_Data!$AA$10),KOL_Source_Data!$AA$10<>"N/A"),1,0))+IF(ISNUMBER(KOL_Source_Data!$AE$10),1,IF(AND(ISTEXT(KOL_Source_Data!$AE$10),KOL_Source_Data!$AE$10<>"N/A"),1,0))+IF(ISNUMBER(KOL_Source_Data!$AH$10),1,IF(AND(ISTEXT(KOL_Source_Data!$AH$10),KOL_Source_Data!$AH$10<>"N/A"),1,0))+IF(ISNUMBER(KOL_Source_Data!$AN$10),1,IF(AND(ISTEXT(KOL_Source_Data!$AN$10),KOL_Source_Data!$AN$10<>"N/A"),1,0))+IF(ISNUMBER(KOL_Source_Data!$BS$10),1,IF(AND(ISTEXT(KOL_Source_Data!$BS$10),KOL_Source_Data!$BS$10<>"N/A"),1,0))+IF(ISNUMBER(KOL_Source_Data!$BT$10),1,IF(AND(ISTEXT(KOL_Source_Data!$BT$10),KOL_Source_Data!$BT$10<>"N/A"),1,0))+IF(ISNUMBER(KOL_Source_Data!$BU$10),1,IF(AND(ISTEXT(KOL_Source_Data!$BU$10),KOL_Source_Data!$BU$10<>"N/A"),1,0))+IF(ISNUMBER(KOL_Source_Data!$BM$10),1,IF(AND(ISTEXT(KOL_Source_Data!$BM$10),KOL_Source_Data!$BM$10<>"N/A"),1,0)))/12*100,0) | BX10: =IF(KOL_Source_Data!$BW$10>=Lookup_Lists!$D$159,"High",IF(KOL_Source_Data!$BW$10>=Lookup_Lists!$D$160,"Medium","Limited Data")) | BY10: cadence unusable: 45/month extrapolated from 4 observed day(s)
A11: KOL-06 | B11: @ibnuwardani | C11: @ibnuwardani | D11: ibnuwardani | E11: TikTok | F11: FOUND | G11: 26200000 | H11: =IFERROR(INDEX(Lookup_Lists!$A$96:$A$100,MATCH(KOL_Source_Data!$G$11,Lookup_Lists!$B$96:$B$100,1)),"N/A") | I11: Yes | J11: N/A | K11: N/A | L11: N/A | M11: N/A | N11: N/A | O11: Home & Living 1pt [rumah (caption)] | P11: N/A | Q11: N/A | R11: N/A | S11: N/A | T11: Setuju ga kalau kita keliling Indonesia? @Lita🐣 @Alvarazka Antarsukha Wardani · 🙏🏻🤣🙏🏻 @Lita🐣 @Alvarazka Antarsukha Wardani · Spiderman😍 @Lita🐣 @Alvarazka Antarsukha Wardani · STICH VIDEO INI‼️ Ultah Agustus mana JJ-nya🤣‼️ @Lita🐣 @Alvarazka Antarsukha Wardani · Kok malah rebahan😭🙏🏻 @Lita🐣 @Alvarazka Antarsukha Wardani · ULANGTAHUN AGUSTUS?! @Lita🐣 @Alvarazka Antarsukha Wardani · BIKIN NGILER! Sekali di TF 1 video jutaan, inimah puluhan ratusan juta gampang bgt🙏🏻😭 @tokoclippers · 🙏🏻🤣 @Lita🐣 @Alvarazka Antarsukha Wardani · BTS konten🤣 @Lita🐣 @Alvarazka Antarsukha Wardani · Rumah Impian ini untukmu, dan hanya untukmu, selamanya kamu akan jadi orang yang paling aku sayang🩵 @Lita🐣 @Alvarazka Antarsukha Wardani @Sibambo Studio @Satrio Ananda #rumahibnulita · #rumahibnulita | U11: #rumahibnulita | V11: N/A | W11: N/A | X11: N/A | Y11: N/A | Z11: N/A | AA11: 51.72 | AB11: 48.28 | AC11: 29 | AD11: Indonesia | AE11: 66.7 | AF11: 9 | AG11: N/A | AH11: N/A | AI11: N/A | AJ11: N/A | AK11: N/A | AL11: N/A | AM11: N/A | AN11: 11.8 | AO11: N/A | AP11: N/A | AQ11: 16.7 | AR11: 16.7 | AS11: N/A | AT11: 8.3 | AU11: N/A | AV11: N/A | AW11: 8.3 | AX11: N/A | AY11: 16.7 | AZ11: 16.7 | BA11: N/A | BB11: N/A | BC11: 8.3 | BD11: 8.3 | BE11: N/A | BF11: N/A | BG11: 0.33 | BH11: l2_gold.kol_profile_card.monitoring_er_pct | BI11: 2762680 | BJ11: 308650 | BK11: 5.5438 | BL11: N/A | BM11: 1.65 | BN11: 182 | BO11: Yes | BP11: 0.2857 | BQ11: 10 | BR11: N/A | BS11: 76 | BT11: 61 | BU11: 92 | BV11: N/A | BW11: =ROUND((IF(ISNUMBER(KOL_Source_Data!$K$11),1,IF(AND(ISTEXT(KOL_Source_Data!$K$11),KOL_Source_Data!$K$11<>"N/A"),1,0))+IF(ISNUMBER(KOL_Source_Data!$BG$11),1,IF(AND(ISTEXT(KOL_Source_Data!$BG$11),KOL_Source_Data!$BG$11<>"N/A"),1,0))+IF(ISNUMBER(KOL_Source_Data!$BI$11),1,IF(AND(ISTEXT(KOL_Source_Data!$BI$11),KOL_Source_Data!$BI$11<>"N/A"),1,0))+IF(ISNUMBER(KOL_Source_Data!$BK$11),1,IF(AND(ISTEXT(KOL_Source_Data!$BK$11),KOL_Source_Data!$BK$11<>"N/A"),1,0))+IF(ISNUMBER(KOL_Source_Data!$AA$11),1,IF(AND(ISTEXT(KOL_Source_Data!$AA$11),KOL_Source_Data!$AA$11<>"N/A"),1,0))+IF(ISNUMBER(KOL_Source_Data!$AE$11),1,IF(AND(ISTEXT(KOL_Source_Data!$AE$11),KOL_Source_Data!$AE$11<>"N/A"),1,0))+IF(ISNUMBER(KOL_Source_Data!$AH$11),1,IF(AND(ISTEXT(KOL_Source_Data!$AH$11),KOL_Source_Data!$AH$11<>"N/A"),1,0))+IF(ISNUMBER(KOL_Source_Data!$AN$11),1,IF(AND(ISTEXT(KOL_Source_Data!$AN$11),KOL_Source_Data!$AN$11<>"N/A"),1,0))+IF(ISNUMBER(KOL_Source_Data!$BS$11),1,IF(AND(ISTEXT(KOL_Source_Data!$BS$11),KOL_Source_Data!$BS$11<>"N/A"),1,0))+IF(ISNUMBER(KOL_Source_Data!$BT$11),1,IF(AND(ISTEXT(KOL_Source_Data!$BT$11),KOL_Source_Data!$BT$11<>"N/A"),1,0))+IF(ISNUMBER(KOL_Source_Data!$BU$11),1,IF(AND(ISTEXT(KOL_Source_Data!$BU$11),KOL_Source_Data!$BU$11<>"N/A"),1,0))+IF(ISNUMBER(KOL_Source_Data!$BM$11),1,IF(AND(ISTEXT(KOL_Source_Data!$BM$11),KOL_Source_Data!$BM$11<>"N/A"),1,0)))/12*100,0) | BX11: =IF(KOL_Source_Data!$BW$11>=Lookup_Lists!$D$159,"High",IF(KOL_Source_Data!$BW$11>=Lookup_Lists!$D$160,"Medium","Limited Data")) | BY11: no category: kol_categories carries none and caption evidence did not reach the threshold
A12: KOL-07 | B12: @iben_ma | C12: @iben_ma | D12: iben_ma | E12: Instagram | F12: FOUND | G12: 3997609 | H12: =IFERROR(INDEX(Lookup_Lists!$A$96:$A$100,MATCH(KOL_Source_Data!$G$12,Lookup_Lists!$B$96:$B$100,1)),"N/A") | I12: Yes | J12: Entertainment | K12: Entertainment | L12: live | M12: N/A | N12: N/A | O12: N/A | P12: N/A | Q12: N/A | R12: N/A | S12: living life to the fullest of capacity 💯🚀 #LLTTFOC @sambalbakar 🔥 @jualemasidn 🥇 @fuelworld_ 💨 CP: 0811-1479-279 (Nonie) | T12: Awas lu Habibi, harus gantian lah!! · Jujur! Kalau lu bakal bawain nya apa?? 😁🙏🏻 · The real ngebut Pak Vincent, merdeka! 🇮🇩😁 · Maaf, tapi semua tindakan harus ada balasannya. 🙏🏻 · finallyyyyyy joining this trend, lots of prewedding content coming soon❤️ pre-wedding content creator @momentsmatter.id · Kadang semuanya udah masuk akal, masuk logika. Tapi tetep aja, perlu that final push of “I trust u” buat ngejalaninnya bener-bener maksimal dan pede. Thank you baby @natashabigeyl sudah percaya dengan decision-decision aku yang kadang terlalu roller coaster 😁❤️ Penghargaan ini ditujukan untuk kalian semua pecinta Eatsambel, dan yang pasti untuk team yang udah selalu support Eatsambel 24/7. LET’S GO KITA BAWA SAMBEL MENDUNIA!!!! 🔥🔥🔥🤤🤤🤤 · Wah harus JELAS nih. @sambalbakar · A one minute teaser of our pre-wedding session in our favorite city of all time. You know I’m the happiest when the gummy smile is out🤪❤️ baru teaser aja jujur udh mellow nontonnya hahaha gak sabar next week for the full video, tungguin yaaa!!!🥹❤️ video by @retromagis · Kita tunggu bareng nih di akunnya…😁🤩 📍Jual Emas Indonesia Cipinang · Astaga Habibi, udah gua bilang kan.. 🤣😁 | U12: N/A | V12: N/A | W12: N/A | X12: N/A | Y12: N/A | Z12: N/A | AA12: 39.47 | AB12: 60.53 | AC12: 38 | AD12: Indonesia | AE12: 85.7 | AF12: 14 | AG12: Bali | AH12: 33.3 | AI12: Kediri | AJ12: 16.7 | AK12: Lampung | AL12: 16.7 | AM12: 100 | AN12: 15.2 | AO12: N/A | AP12: 6.3 | AQ12: 6.3 | AR12: 6.3 | AS12: 12.5 | AT12: 6.3 | AU12: N/A | AV12: N/A | AW12: 6.3 | AX12: N/A | AY12: 12.5 | AZ12: 12.5 | BA12: N/A | BB12: N/A | BC12: 18.8 | BD12: 12.5 | BE12: N/A | BF12: N/A | BG12: 1.46 | BH12: kol_directory.engagement_rate | BI12: 1608002.1 | BJ12: 1110744 | BK12: 50.0887 | BL12: 8 | BM12: 34.29 | BN12: 7 | BO12: No | BP12: 0.2351 | BQ12: 0 | BR12: N/A | BS12: 63 | BT12: 77 | BU12: 49 | BV12: N/A | BW12: =ROUND((IF(ISNUMBER(KOL_Source_Data!$K$12),1,IF(AND(ISTEXT(KOL_Source_Data!$K$12),KOL_Source_Data!$K$12<>"N/A"),1,0))+IF(ISNUMBER(KOL_Source_Data!$BG$12),1,IF(AND(ISTEXT(KOL_Source_Data!$BG$12),KOL_Source_Data!$BG$12<>"N/A"),1,0))+IF(ISNUMBER(KOL_Source_Data!$BI$12),1,IF(AND(ISTEXT(KOL_Source_Data!$BI$12),KOL_Source_Data!$BI$12<>"N/A"),1,0))+IF(ISNUMBER(KOL_Source_Data!$BK$12),1,IF(AND(ISTEXT(KOL_Source_Data!$BK$12),KOL_Source_Data!$BK$12<>"N/A"),1,0))+IF(ISNUMBER(KOL_Source_Data!$AA$12),1,IF(AND(ISTEXT(KOL_Source_Data!$AA$12),KOL_Source_Data!$AA$12<>"N/A"),1,0))+IF(ISNUMBER(KOL_Source_Data!$AE$12),1,IF(AND(ISTEXT(KOL_Source_Data!$AE$12),KOL_Source_Data!$AE$12<>"N/A"),1,0))+IF(ISNUMBER(KOL_Source_Data!$AH$12),1,IF(AND(ISTEXT(KOL_Source_Data!$AH$12),KOL_Source_Data!$AH$12<>"N/A"),1,0))+IF(ISNUMBER(KOL_Source_Data!$AN$12),1,IF(AND(ISTEXT(KOL_Source_Data!$AN$12),KOL_Source_Data!$AN$12<>"N/A"),1,0))+IF(ISNUMBER(KOL_Source_Data!$BS$12),1,IF(AND(ISTEXT(KOL_Source_Data!$BS$12),KOL_Source_Data!$BS$12<>"N/A"),1,0))+IF(ISNUMBER(KOL_Source_Data!$BT$12),1,IF(AND(ISTEXT(KOL_Source_Data!$BT$12),KOL_Source_Data!$BT$12<>"N/A"),1,0))+IF(ISNUMBER(KOL_Source_Data!$BU$12),1,IF(AND(ISTEXT(KOL_Source_Data!$BU$12),KOL_Source_Data!$BU$12<>"N/A"),1,0))+IF(ISNUMBER(KOL_Source_Data!$BM$12),1,IF(AND(ISTEXT(KOL_Source_Data!$BM$12),KOL_Source_Data!$BM$12<>"N/A"),1,0)))/12*100,0) | BX12: =IF(KOL_Source_Data!$BW$12>=Lookup_Lists!$D$159,"High",IF(KOL_Source_Data!$BW$12>=Lookup_Lists!$D$160,"Medium","Limited Data")) | BY12: cadence unusable: 34.29/month extrapolated from 7 observed day(s)
A13: KOL-08 | B13: @inul.d | C13: @inul.d | D13: inul.d | E13: Instagram | F13: FOUND | G13: 20046665 | H13: =IFERROR(INDEX(Lookup_Lists!$A$96:$A$100,MATCH(KOL_Source_Data!$G$13,Lookup_Lists!$B$96:$B$100,1)),"N/A") | I13: Yes | J13: N/A | K13: Food | L13: calculated | M13: Food | N13: Coffee & Beverage, Baking & Dessert, Budget Travel | O13: Food 10pt [dessert (caption); minuman (caption); cafe (caption)] · Travel 4pt [travel (caption); promo (caption)] | P13: N/A | Q13: N/A | R13: N/A | S13: ✨BA @sunco_id @brightgas @miburungdara @purinaindonesia INUL INFO 👇 | T13: sexy 💋 designer 👉 @jaka_raja @jaka_raja2 💋 shoes Bali 👉 @niluhdjelantik 💋 DMD Panggung Rezeki @officialmnctv · REVEAL! ✨ Scent Your Song — Paket Karaoke + Parfum Favoritmu! 🎤✨ Yang kemarin masih coming soon, sekarang waktunya di-reveal! 👀 Nikmati serunya karaoke sambil bawa pulang parfum pilihanmu dalam Scent Your Song dari Inul Vizta. 🎶💐 MEDIUM PACKAGE — Rp315.000 2 Jam Room + 1 Appetizer + 1 Dessert + 1 Pitcher Minuman + 1 Parfum LARGE PACKAGE — Rp510.000 2 Jam Room + 2 Appetizer + 2 Dessert + 2 Pitcher Minuman + 1 Parfum DELUXE PACKAGE — Rp750.000 2 Jam Room + 3 Appetizer + 3 Dessert + 3 Pitcher Minuman + 1 Parfum 🍴 Appetizer: Cheese Sticks / Mac N’ Cheese / Tteokbokki Cheese 🍰 Dessert: Double Choux 🥤 Beverage: Lychee Tea / Lemon Tea / Orange Juice / Coca-Cola / Fanta 🎁 BONUS PROMO PARFUM Tebus parfum hanya Rp75.000 dengan minimal belanja Rp1.000.000. Harga paket sudah termasuk tax & service. Harga tebus parfum Rp75.000 belum termasuk tax & service. 📍 Tersedia di outlet: DKI Jakarta • Inul Vizta Buaran • Inul Vizta Kramat Jati • Inul Vizta Kota Kasablanka • Inul Vizta Melawai • Inul Vizta Pejaten Jawa Barat • Inul Vizta Summarecon Bekasi • Inul Vizta Harapan Indah • Inul Vizta Blu Plaza • Inul Vizta TSM Cibubur • Inul Vizta Cileungsi • Inul Rumah Bernyanyi • Inul Vizta Festive Walk • Inul Vizta Sukabumi • Inul Vizta Paskal Bandung Banten • Inul Vizta Tangerang City • Inul Vizta Balekota Jambi • Inul Vizta Jambi 🎤 Sing your song, complete your scent! Saatnya | U13: #inulvizta #daraparfum #promokaraoke #scentyoursong #keinvizaja #inulviztakaraoke #karaokekeluarga #17agustus #dmdpanggungrezeki #mnctvrumahnyadangdut #hutri81 | V13: N/A | W13: N/A | X13: N/A | Y13: N/A | Z13: N/A | AA13: 57.5 | AB13: 42.5 | AC13: 40 | AD13: Indonesia | AE13: 86.7 | AF13: 15 | AG13: Bandung | AH13: 18.2 | AI13: Bali | AJ13: 9.1 | AK13: Jakarta | AL13: 9.1 | AM13: 100 | AN13: 17.1 | AO13: 5.6 | AP13: N/A | AQ13: N/A | AR13: 27.8 | AS13: 5.6 | AT13: 5.6 | AU13: N/A | AV13: 5.6 | AW13: 11.1 | AX13: N/A | AY13: N/A | AZ13: 22.2 | BA13: N/A | BB13: N/A | BC13: 16.7 | BD13: N/A | BE13: N/A | BF13: N/A | BG13: 0.01 | BH13: kol_directory.engagement_rate | BI13: 226692.67 | BJ13: 80192 | BK13: 1.1308 | BL13: 7 | BM13: 105 | BN13: 2 | BO13: No | BP13: -0.0202 | BQ13: 0 | BR13: N/A | BS13: 62 | BT13: 55 | BU13: 70 | BV13: N/A | BW13: =ROUND((IF(ISNUMBER(KOL_Source_Data!$K$13),1,IF(AND(ISTEXT(KOL_Source_Data!$K$13),KOL_Source_Data!$K$13<>"N/A"),1,0))+IF(ISNUMBER(KOL_Source_Data!$BG$13),1,IF(AND(ISTEXT(KOL_Source_Data!$BG$13),KOL_Source_Data!$BG$13<>"N/A"),1,0))+IF(ISNUMBER(KOL_Source_Data!$BI$13),1,IF(AND(ISTEXT(KOL_Source_Data!$BI$13),KOL_Source_Data!$BI$13<>"N/A"),1,0))+IF(ISNUMBER(KOL_Source_Data!$BK$13),1,IF(AND(ISTEXT(KOL_Source_Data!$BK$13),KOL_Source_Data!$BK$13<>"N/A"),1,0))+IF(ISNUMBER(KOL_Source_Data!$AA$13),1,IF(AND(ISTEXT(KOL_Source_Data!$AA$13),KOL_Source_Data!$AA$13<>"N/A"),1,0))+IF(ISNUMBER(KOL_Source_Data!$AE$13),1,IF(AND(ISTEXT(KOL_Source_Data!$AE$13),KOL_Source_Data!$AE$13<>"N/A"),1,0))+IF(ISNUMBER(KOL_Source_Data!$AH$13),1,IF(AND(ISTEXT(KOL_Source_Data!$AH$13),KOL_Source_Data!$AH$13<>"N/A"),1,0))+IF(ISNUMBER(KOL_Source_Data!$AN$13),1,IF(AND(ISTEXT(KOL_Source_Data!$AN$13),KOL_Source_Data!$AN$13<>"N/A"),1,0))+IF(ISNUMBER(KOL_Source_Data!$BS$13),1,IF(AND(ISTEXT(KOL_Source_Data!$BS$13),KOL_Source_Data!$BS$13<>"N/A"),1,0))+IF(ISNUMBER(KOL_Source_Data!$BT$13),1,IF(AND(ISTEXT(KOL_Source_Data!$BT$13),KOL_Source_Data!$BT$13<>"N/A"),1,0))+IF(ISNUMBER(KOL_Source_Data!$BU$13),1,IF(AND(ISTEXT(KOL_Source_Data!$BU$13),KOL_Source_Data!$BU$13<>"N/A"),1,0))+IF(ISNUMBER(KOL_Source_Data!$BM$13),1,IF(AND(ISTEXT(KOL_Source_Data!$BM$13),KOL_Source_Data!$BM$13<>"N/A"),1,0)))/12*100,0) | BX13: =IF(KOL_Source_Data!$BW$13>=Lookup_Lists!$D$159,"High",IF(KOL_Source_Data!$BW$13>=Lookup_Lists!$D$160,"Medium","Limited Data")) | BY13: category calculated from captions, not from kol_categories · cadence unusable: 105/month extrapolated from 2 observed day(s)
A14: KOL-09 | B14: @bbrightvc | C14: @bbrightvc | D14: bbrightvc | E14: Instagram | F14: FOUND | G14: 18018065 | H14: =IFERROR(INDEX(Lookup_Lists!$A$96:$A$100,MATCH(KOL_Source_Data!$G$14,Lookup_Lists!$B$96:$B$100,1)),"N/A") | I14: No | J14: Fashion | K14: Fashion | L14: live | M14: N/A | N14: N/A | O14: N/A | P14: N/A | Q14: N/A | R14: N/A | S14: N/A | T14: N/A | U14: N/A | V14: N/A | W14: N/A | X14: N/A | Y14: N/A | Z14: N/A | AA14: N/A | AB14: N/A | AC14: N/A | AD14: N/A | AE14: N/A | AF14: N/A | AG14: N/A | AH14: N/A | AI14: N/A | AJ14: N/A | AK14: N/A | AL14: N/A | AM14: N/A | AN14: N/A | AO14: N/A | AP14: N/A | AQ14: N/A | AR14: N/A | AS14: N/A | AT14: N/A | AU14: N/A | AV14: N/A | AW14: N/A | AX14: N/A | AY14: N/A | AZ14: N/A | BA14: N/A | BB14: N/A | BC14: N/A | BD14: N/A | BE14: N/A | BF14: N/A | BG14: N/A | BH14: N/A | BI14: N/A | BJ14: N/A | BK14: N/A | BL14: N/A | BM14: N/A | BN14: N/A | BO14: N/A | BP14: N/A | BQ14: N/A | BR14: N/A | BS14: N/A | BT14: N/A | BU14: N/A | BV14: N/A | BW14: =ROUND((IF(ISNUMBER(KOL_Source_Data!$K$14),1,IF(AND(ISTEXT(KOL_Source_Data!$K$14),KOL_Source_Data!$K$14<>"N/A"),1,0))+IF(ISNUMBER(KOL_Source_Data!$BG$14),1,IF(AND(ISTEXT(KOL_Source_Data!$BG$14),KOL_Source_Data!$BG$14<>"N/A"),1,0))+IF(ISNUMBER(KOL_Source_Data!$BI$14),1,IF(AND(ISTEXT(KOL_Source_Data!$BI$14),KOL_Source_Data!$BI$14<>"N/A"),1,0))+IF(ISNUMBER(KOL_Source_Data!$BK$14),1,IF(AND(ISTEXT(KOL_Source_Data!$BK$14),KOL_Source_Data!$BK$14<>"N/A"),1,0))+IF(ISNUMBER(KOL_Source_Data!$AA$14),1,IF(AND(ISTEXT(KOL_Source_Data!$AA$14),KOL_Source_Data!$AA$14<>"N/A"),1,0))+IF(ISNUMBER(KOL_Source_Data!$AE$14),1,IF(AND(ISTEXT(KOL_Source_Data!$AE$14),KOL_Source_Data!$AE$14<>"N/A"),1,0))+IF(ISNUMBER(KOL_Source_Data!$AH$14),1,IF(AND(ISTEXT(KOL_Source_Data!$AH$14),KOL_Source_Data!$AH$14<>"N/A"),1,0))+IF(ISNUMBER(KOL_Source_Data!$AN$14),1,IF(AND(ISTEXT(KOL_Source_Data!$AN$14),KOL_Source_Data!$AN$14<>"N/A"),1,0))+IF(ISNUMBER(KOL_Source_Data!$BS$14),1,IF(AND(ISTEXT(KOL_Source_Data!$BS$14),KOL_Source_Data!$BS$14<>"N/A"),1,0))+IF(ISNUMBER(KOL_Source_Data!$BT$14),1,IF(AND(ISTEXT(KOL_Source_Data!$BT$14),KOL_Source_Data!$BT$14<>"N/A"),1,0))+IF(ISNUMBER(KOL_Source_Data!$BU$14),1,IF(AND(ISTEXT(KOL_Source_Data!$BU$14),KOL_Source_Data!$BU$14<>"N/A"),1,0))+IF(ISNUMBER(KOL_Source_Data!$BM$14),1,IF(AND(ISTEXT(KOL_Source_Data!$BM$14),KOL_Source_Data!$BM$14<>"N/A"),1,0)))/12*100,0) | BX14: =IF(KOL_Source_Data!$BW$14>=Lookup_Lists!$D$159,"High",IF(KOL_Source_Data!$BW$14>=Lookup_Lists!$D$160,"Medium","Limited Data")) | BY14: no engagement rate on any of the three sources · no audience analysis row · no audience interest rows
A15: KOL-10 | B15: @pevpearce | C15: @pevpearce | D15: pevpearce | E15: Instagram | F15: FOUND | G15: 17452714 | H15: =IFERROR(INDEX(Lookup_Lists!$A$96:$A$100,MATCH(KOL_Source_Data!$G$15,Lookup_Lists!$B$96:$B$100,1)),"N/A") | I15: Yes | J15: Lifestyle | K15: Lifestyle | L15: live | M15: N/A | N15: Race & Event, Running, Investing | O15: Fitness 3pt [race (caption)] · Beauty 2pt [makeup (caption)] | P15: N/A | Q15: N/A | R15: N/A | S15: N/A | T15: A reminder, dreams do come true ✨🏎️ · Monza, we finally meet and even more 🏁 Nggak ada yang ngalahin feeling balik ke race week setelah summer break apalagi ngerasainnya langsung dari salah satu circuit paling legendaris di dunia. Plus, sempat shooting bareng Lewis & Charles juga… kebayang kan serunya kaya apa ✨ Can't wait to show you more... stay tuned! 🏎️ · Next coba apa lagi ya? Spill ✨️ · Date night · Once upon a time di 2019 pas lagi medical check up di Kuala Lumpur dikenalin ke Mirzan dan fast forward sekarang ngerayain hari ulang tahunnya as husband & wife. Life is so funny. They say the best stories are the ones you don’t see coming. Meeting you was mine. Thank you for being you, My Love. Happy birthday to my fave person. · Off the grid for a few days · My July cover for Harper's Bazaar Indonesia is out! Sharing stories of dedication and my creative path, all while in beautiful @louisvuitton. So much love for this feature Fotografi: @mr_hendra Fashion Editor: @sophisticadit Makeup: @evalovira Hair: @picaleva Asisten Stylist: @nau.kamillaa Wardrobe & Accessories: @louisvuitton Teks: sadini Layout Cover: @somadvladislav · Bagi @pevpearce, apa yang terwujud hari ini mungkin pernah bermula dari sesuatu yang sederhana, yakni sebuah bayangan tentang apa yang ingin ia ciptakan. Membuka edisi Juli 2026 Harper’s Bazaar Indonesia, Pevita Pearce hadir dalam balutan @louisvuitton dan berbagi cerita tentang karya, manifestasi, serta dedikasi yang membawanya sampai pada titik in | U15: N/A | V15: N/A | W15: N/A | X15: N/A | Y15: N/A | Z15: N/A | AA15: 28.21 | AB15: 71.79 | AC15: 39 | AD15: Indonesia | AE15: 56.3 | AF15: 16 | AG15: Jakarta | AH15: 25 | AI15: Bandung | AJ15: 12.5 | AK15: Jawa | AL15: 12.5 | AM15: 100 | AN15: 22.2 | AO15: N/A | AP15: N/A | AQ15: N/A | AR15: 16.7 | AS15: N/A | AT15: 4.2 | AU15: N/A | AV15: 4.2 | AW15: 12.5 | AX15: 4.2 | AY15: 8.3 | AZ15: 4.2 | BA15: N/A | BB15: 12.5 | BC15: 20.8 | BD15: 4.2 | BE15: 4.2 | BF15: 4.2 | BG15: 0.28 | BH15: kol_directory.engagement_rate | BI15: 577655.67 | BJ15: 557850 | BK15: 0.996 | BL15: 9 | BM15: 5.74 | BN15: 47 | BO15: Yes | BP15: -0.022 | BQ15: 0 | BR15: N/A | BS15: 54 | BT15: 51 | BU15: 56 | BV15: N/A | BW15: =ROUND((IF(ISNUMBER(KOL_Source_Data!$K$15),1,IF(AND(ISTEXT(KOL_Source_Data!$K$15),KOL_Source_Data!$K$15<>"N/A"),1,0))+IF(ISNUMBER(KOL_Source_Data!$BG$15),1,IF(AND(ISTEXT(KOL_Source_Data!$BG$15),KOL_Source_Data!$BG$15<>"N/A"),1,0))+IF(ISNUMBER(KOL_Source_Data!$BI$15),1,IF(AND(ISTEXT(KOL_Source_Data!$BI$15),KOL_Source_Data!$BI$15<>"N/A"),1,0))+IF(ISNUMBER(KOL_Source_Data!$BK$15),1,IF(AND(ISTEXT(KOL_Source_Data!$BK$15),KOL_Source_Data!$BK$15<>"N/A"),1,0))+IF(ISNUMBER(KOL_Source_Data!$AA$15),1,IF(AND(ISTEXT(KOL_Source_Data!$AA$15),KOL_Source_Data!$AA$15<>"N/A"),1,0))+IF(ISNUMBER(KOL_Source_Data!$AE$15),1,IF(AND(ISTEXT(KOL_Source_Data!$AE$15),KOL_Source_Data!$AE$15<>"N/A"),1,0))+IF(ISNUMBER(KOL_Source_Data!$AH$15),1,IF(AND(ISTEXT(KOL_Source_Data!$AH$15),KOL_Source_Data!$AH$15<>"N/A"),1,0))+IF(ISNUMBER(KOL_Source_Data!$AN$15),1,IF(AND(ISTEXT(KOL_Source_Data!$AN$15),KOL_Source_Data!$AN$15<>"N/A"),1,0))+IF(ISNUMBER(KOL_Source_Data!$BS$15),1,IF(AND(ISTEXT(KOL_Source_Data!$BS$15),KOL_Source_Data!$BS$15<>"N/A"),1,0))+IF(ISNUMBER(KOL_Source_Data!$BT$15),1,IF(AND(ISTEXT(KOL_Source_Data!$BT$15),KOL_Source_Data!$BT$15<>"N/A"),1,0))+IF(ISNUMBER(KOL_Source_Data!$BU$15),1,IF(AND(ISTEXT(KOL_Source_Data!$BU$15),KOL_Source_Data!$BU$15<>"N/A"),1,0))+IF(ISNUMBER(KOL_Source_Data!$BM$15),1,IF(AND(ISTEXT(KOL_Source_Data!$BM$15),KOL_Source_Data!$BM$15<>"N/A"),1,0)))/12*100,0) | BX15: =IF(KOL_Source_Data!$BW$15>=Lookup_Lists!$D$159,"High",IF(KOL_Source_Data!$BW$15>=Lookup_Lists!$D$160,"Medium","Limited Data")) | BY15: complete on every tracked field
A16: KOL-11 | B16: @irwansyah_15 | C16: @irwansyah_15 | D16: irwansyah_15 | E16: Instagram | F16: FOUND | G16: 14916540 | H16: =IFERROR(INDEX(Lookup_Lists!$A$96:$A$100,MATCH(KOL_Source_Data!$G$16,Lookup_Lists!$B$96:$B$100,1)),"N/A") | I16: Yes | J16: N/A | K16: N/A | L16: N/A | M16: N/A | N16: Coffee & Beverage, Kids & Family | O16: Parenting 3pt [keluarga (caption)] · Food 2pt [kopi (caption)] | P16: N/A | Q16: N/A | R16: N/A | S16: Indonesian • @15interior_official • @jannahtravel • @umroqutravel • @swizgroup Cp +6285176781115 Ov (work only) | T16: Dirgahayu Indonesiaku! 81 tahun Indonesia merdeka, Indonesia berdaulat adil dan makmur 🇮🇩 · Semoga kelak Anak2 bisa lebih baik dari kami , semoga Allah jaga mereka آمِيْن اللّهُمَّ آمِيْن Barakallahufiikum anak2 shaleh dan shalehah ku syg · Gawat Ada King @mister.aloy di hari Minggu ❤️ Sehat" semuanyaa guys 🙏 · MasyaAllah Tabarakallah ❤️ semoga Allah jaga anak2ku syg · Ternyata ini isi tasnya @irwansyah_15 ❤️👀 ide challenge apa ya berikutnya? #pakaiautannyamukpamitan · kirain ada maling nggak taunya...🤣🦟 #PakaiAutanNyamukPamitan · caption nya apa ya? 😎 · Kamu team roma + kopi ? Atau roma + teh ? #Pastiromakelapa 🤤😍 @roma.biskuitkelapa · Alhamdulillah Senangnya bisa bergabung di keluarga @barakat_id 😍 siapa yang udah coba @barakat_id ? Ada yang mau dikirimin parcel barakat? Cungg👆🏻 · Satu lagi dari @mayoraofficial , @le_mineraleid 😉 · #pakaiautannyamukpamitan · #PakaiAutanNyamukPamitan · #Pastiromakelapa | U16: #pakaiautannyamukpamitan #pastiromakelapa | V16: N/A | W16: N/A | X16: N/A | Y16: N/A | Z16: N/A | AA16: 71.79 | AB16: 28.21 | AC16: 39 | AD16: Indonesia | AE16: 70 | AF16: 10 | AG16: Lampung | AH16: 16.7 | AI16: Madiun | AJ16: 16.7 | AK16: Palu | AL16: 16.7 | AM16: 100 | AN16: 21.7 | AO16: 4.3 | AP16: 4.3 | AQ16: 4.3 | AR16: 21.7 | AS16: 4.3 | AT16: 4.3 | AU16: N/A | AV16: 4.3 | AW16: 4.3 | AX16: N/A | AY16: 4.3 | AZ16: 8.7 | BA16: N/A | BB16: 4.3 | BC16: 17.4 | BD16: 4.3 | BE16: 8.7 | BF16: N/A | BG16: 0.25 | BH16: kol_directory.engagement_rate | BI16: N/A | BJ16: N/A | BK16: N/A | BL16: 0 | BM16: N/A | BN16: N/A | BO16: N/A | BP16: -0.0281 | BQ16: N/A | BR16: N/A | BS16: 62 | BT16: 42 | BU16: 81 | BV16: N/A | BW16: =ROUND((IF(ISNUMBER(KOL_Source_Data!$K$16),1,IF(AND(ISTEXT(KOL_Source_Data!$K$16),KOL_Source_Data!$K$16<>"N/A"),1,0))+IF(ISNUMBER(KOL_Source_Data!$BG$16),1,IF(AND(ISTEXT(KOL_Source_Data!$BG$16),KOL_Source_Data!$BG$16<>"N/A"),1,0))+IF(ISNUMBER(KOL_Source_Data!$BI$16),1,IF(AND(ISTEXT(KOL_Source_Data!$BI$16),KOL_Source_Data!$BI$16<>"N/A"),1,0))+IF(ISNUMBER(KOL_Source_Data!$BK$16),1,IF(AND(ISTEXT(KOL_Source_Data!$BK$16),KOL_Source_Data!$BK$16<>"N/A"),1,0))+IF(ISNUMBER(KOL_Source_Data!$AA$16),1,IF(AND(ISTEXT(KOL_Source_Data!$AA$16),KOL_Source_Data!$AA$16<>"N/A"),1,0))+IF(ISNUMBER(KOL_Source_Data!$AE$16),1,IF(AND(ISTEXT(KOL_Source_Data!$AE$16),KOL_Source_Data!$AE$16<>"N/A"),1,0))+IF(ISNUMBER(KOL_Source_Data!$AH$16),1,IF(AND(ISTEXT(KOL_Source_Data!$AH$16),KOL_Source_Data!$AH$16<>"N/A"),1,0))+IF(ISNUMBER(KOL_Source_Data!$AN$16),1,IF(AND(ISTEXT(KOL_Source_Data!$AN$16),KOL_Source_Data!$AN$16<>"N/A"),1,0))+IF(ISNUMBER(KOL_Source_Data!$BS$16),1,IF(AND(ISTEXT(KOL_Source_Data!$BS$16),KOL_Source_Data!$BS$16<>"N/A"),1,0))+IF(ISNUMBER(KOL_Source_Data!$BT$16),1,IF(AND(ISTEXT(KOL_Source_Data!$BT$16),KOL_Source_Data!$BT$16<>"N/A"),1,0))+IF(ISNUMBER(KOL_Source_Data!$BU$16),1,IF(AND(ISTEXT(KOL_Source_Data!$BU$16),KOL_Source_Data!$BU$16<>"N/A"),1,0))+IF(ISNUMBER(KOL_Source_Data!$BM$16),1,IF(AND(ISTEXT(KOL_Source_Data!$BM$16),KOL_Source_Data!$BM$16<>"N/A"),1,0)))/12*100,0) | BX16: =IF(KOL_Source_Data!$BW$16>=Lookup_Lists!$D$159,"High",IF(KOL_Source_Data!$BW$16>=Lookup_Lists!$D$160,"Medium","Limited Data")) | BY16: no category: kol_categories carries none and caption evidence did not reach the threshold
